Workbook

Sheet ACCUEIL
C1: Bienvenue dans l'extraction de vos données d'effectifs ! | H1: #! END_ROW
C2: Ce fichier Excel a été extrait automatiquement de votre application A-JUST. Retrouvez ci-dessous quelques indications pour y naviguer en toute fluidité. | H2: #! END_ROW
H3: #! END_ROW
B4: Nom de l'onglet | C4: Description rapide | D4: Usage | E4: Pour une présentation complète | H4: #! END_ROW
B5: ETPT A-JUST | C5: Retrouvez le détail des ventilations individuelles de chaque agent, agrégées sur la période pour laquelle vous avez extrait les données, à l'identique de ce que vous avez renseigné dans A-JUST. | D5: Tout au long de l'année, consultez le détail des affectations de chaque agent, calculées en ETPT, pour la période choisie. | E5: #! HYPERLINK firstLink.label firstLink.url | H5: #! END_ROW
B6: ETPT Format DDG | C6: Vous y trouverez les données individuelles, retraitées conformément aux règles de calcul de la Chancellerie, en procédant à la réintégration de certaines indisponibilités considérées comme de l'absentéisme, ne déduisant pas d'ETPT. | D6: Afin de préparer la collecte de vos ETPT dans les matrices de la DSJ certaines précisions doivent être apportées dans cet onglet. | E6: #! HYPERLINK secondLink.label secondLink.url | H6: #! END_ROW
B7: Agrégats DDG | C7: Pour chaque juridiction de l'arrondissement judiciaire, cette synthèse présente les ETPT affectés, par catégorie d'agent, à chaque contentieux ou sous-contentieux, l'absentéisme étant réintégré comme dans l'onglet "ETPT Format DDG". | D7: N'hésitez pas à la consulter toute l'année, pour les périodes de votre choix. | E7: #! HYPERLINK firstLink.label firstLink.url | H7: #! END_ROW
B8: ETPT_TJ_DDG | C8: Les tableaux de la Chancellerie, préremplis grâce aux informations saisies dans A-JUST et aux précisions apportées dans l'onglet ETPT Format DDG. Pour les Tribunaux de proximité et CPH, sélectionnez la juridiction dans la cellule D5 et vos tableaux seront prêts ! | D8: Ces données sont prérenseignées dans les tableaux de collecte des ETPT de la Chancellerie mais restent soumises à votre contrôle et éventuels ajustements avant transmission. | E8: #! HYPERLINK thirdLink.label thirdLink.url | H8: #! END_ROW
B9: ETPT_TPRX-DDG | H9: #! END_ROW
B10: ETPT_CPH_DDG | H10: #! END_ROW
H11: #! END_ROW
C12: Ce fichier, permettant de remplir automatiquement les tableaux de collecte d'ETPT de la Chancellerie à partir des données A-JUST, résulte de la collaboration de l'équipe de la start-up d'Etat A-JUST avec Mme Nathalie DE JONG, statisticienne du SAIR de la Cour d'Appel de LYON. Qu'elle soit ici vivement remerciée, ainsi que sa hiérarchie qui l'a autorisée à consacrer un temps aussi précieux qu'irremplaçable à écrire les formules de calcul permettant d'automatiser l'alimentation des tableaux DDG et faire ainsi gagner à nos utilisateurs un temps considérable chaque année. | H12: #! END_ROW
H13: #! END_ROW
A14: Pour toute question, n'hésitez pas à contacter l'équipe A-JUST : support-utilisateurs@a-just.fr | H14: #! END_ROW
H15: #! FINISH

Sheet ETPT A-JUST
A1: Extracteur de données d'effectifs | G1: #! DUMP_COLS subtitles | H1: #! END_ROW
A2: #! DUMP_COLS days | B2: #! FOR_EACH w stats
A3: #! DUMP_COLS w.actions | B3: #! CONTINUE w
A4: #! DUMP_COLS w.actions | B4: #! END_LOOP w
B5: #! FINISH

Sheet ETPT Format DDG
A1: Extracteur de données d'effectifs - Format DDG (avec réintégration de l'absentéisme) | G1: #! DUMP_COLS subtitles | EA1: RECAPITULATIF | EG1: #! END_ROW
A2: #! DUMP_COLS days1 | B2: #! FOR_EACH x stats1 | EA2: Fonction recodée | EB2: Temps ventilés sur la période (contentieux sociaux civils et commerciaux) | EC2: Temps ventilés sur la période (service pénal) | ED2: Temps ventilés sur la période (hors indisponibilité) | EE2: Soutien (Hors accueil du justiciable) | EF2: Temps ventilés sur la période (y.c. indisponibilité)
A3: #! DUMP_COLS x.actions | B3: #! END_LOOP x
B4: #! FINISH
EH5: Temps ventilés sur la période (contentieux sociaux civils et commerciaux) = somme des postes 1. Contentieux social, 2. Contentieux commercial, 3. Contentieux de la famille, 4. Contentieux de la protection, 5. Contentieux civil non spécialisé, Contentieux des mineurs/7.1 Activité civile, 12. Attributions du PP, de la nomenclature A-JUST.
EH6: Temps ventilés sur la période (service pénal) = somme des postes Contentieux des mineurs/7.2 Activité pénale, 8. Correctionnel, 9. Instruction et entraide, 10. Application des peines, 11. Contentieux criminel, de la nomenclature A-JUST.
EH7: Temps ventilés sur la période (hors indisponibilité) = somme de Temps ventilés sur la période (contentieux sociaux civils et commerciaux), Temps ventilés sur la période (service pénal), 13. Autres activités, de la nomenclature A-JUST.
EH8: Temps ventilés sur la période (y.c. indisponibilité) = somme de Temps ventilés sur la période (contentieux sociaux civils et commerciaux), Temps ventilés sur la période (service pénal), 13. Autres activités, 14. Indisponibilité de la nomenclature A-JUST.
EH9: Fonction recodée (créer en parallèle une table de correspondance pour chaque fonction) avec les modalités recodées suivantes : Magistrats SIEGE ; Magistrats placés ADD ; Magistrats placés SUB ; Fonctionnaires CTECH ; Fonctionnaire CTECH placé ADD ; Fonctionnaire CTECH placé SUB ; Fonctionnaires A-B-CBUR ; Fonctionnaire A-B-CBUR placé ADD ; Fonctionnaire A-B-CBUR placé SUB ; JURISTE AS chambres sociales ; JURISTE AS siège Autres ; JURISTE AS parquet général ; JURISTE AS chambres sociales placé ADD ; JURISTE AS siège Autres placé ADD ; JURISTE AS parquet général placé ADD ; JURISTE AS chambres sociales placé SUB ; JURISTE AS siège Autres placé SUB ; JURISTE AS parquet général placé SUB.
EH10: Soutien (Hors accueil du justiciable) = somme des postes 13.11 Activités extérieures et partenariats, 13.12 Equipement, 13.13 Communication, 13.14 Politique associative et aide aux victimes, 13.1 Soutien (autres), 13.2 Formations suivies, 13.5 Expertises (suivi et listes), 13.6 Médiation / conciliation (suivi et listes).

Sheet Agrégats DDG
C1: Agrégats DDG | J1: #! DUMP_COLS subtitles | K1: #! END_ROW
A2: Selectionner une juridiction | B2: Code | C2: #! END_ROW
A3: #` ${arrondissement} | B3: =VLOOKUP(A3,'codage tribunal'!A:B,2,FALSE) -> #N/A | C3: #! END_ROW
G4: SIEGE | N4: GREFFE | U4: EQUIPE AUTOUR DU MAGISTRAT | X4: #! END_ROW
G5: Magistrats hors placés | H5: %age de l'ETPT | I5: Magistrats placés additionnels | J5: Magistrats placés de substitution | K5: Contractuels et vacataires | L5: TOTAL SIEGE | M5: %age de l'ETPT | N5: Fonctionnaires hors placés | O5: %age de l'ETPT | P5: Fonctionnaires placés additionnels | Q5: Fonctionnaires placés de substitution | R5: Contractuels et vacataires | S5: TOTAL GREFFE | T5: %age de l'ETPT | U5: Contractuels et vacataires | V5: %age de l'ETPT | W5: #! FOR_EACH y agregat
C6: ## y.global | D6: ## y.global1 | E6: ## y.sub | F6: ## y.sub1 | G6: =SUMIFS(INDEX('ETPT Format DDG'!$A:$DU,,IFERROR(MATCH(E6,'ETPT Format DDG'!$2:$2,0),MATCH(C6,'ETPT Format DDG'!$2:$2,0))),'ETPT Format DDG'!$I:$I,"M-TIT",'ETPT Format DDG'!$C:$C,$A$3) -> #N/A | H6: =IF(AND(OR(LEFT(C6,3)="12.",LEFT(E6,3)="12.",LEFT(E6,5)="CET >",IFERROR(G6/$G$6,"")=0),NOT(AND(LEFT(E6,5)="12.31",IFERROR(G6/$G$6,"")<>0)),NOT(AND(LEFT(E6,5)="12.32",IFERROR(G6/$G$6,"")<>0))),"", IFERROR(G6/$G$6,"")) | I6: =SUMIFS(INDEX('ETPT Format DDG'!$A:$DU,,IFERROR(MATCH(E6,'ETPT Format DDG'!$2:$2,0),MATCH(C6,'ETPT Format DDG'!$2:$2,0))),'ETPT Format DDG'!$I:$I,"M-PLAC-ADD",'ETPT Format DDG'!$C:$C,$A$3) -> #N/A | J6: =SUMIFS(INDEX('ETPT Format DDG'!$A:$DU,,IFERROR(MATCH(E6,'ETPT Format DDG'!$2:$2,0),MATCH(C6,'ETPT Format DDG'!$2:$2,0))),'ETPT Format DDG'!$I:$I,"M-PLAC-SUB",'ETPT Format DDG'!$C:$C,$A$3) -> #N/A | K6: =SUMIFS( INDEX('ETPT Format DDG'!$A:$DU, , IFERROR(MATCH(E6,'ETPT Format DDG'!$2:$2,0),MATCH(C6,'ETPT Format DDG'!$2:$2,0)) ),'ETPT Format DDG'!$I:$I,"C", 'ETPT Format DDG'!$C:$C,$A$3, 'ETPT Format DDG'!$G:$G,"Magistrat") -> #N/A | L6: =SUMIFS( INDEX('ETPT Format DDG'!$A:$DU, , IFERROR(MATCH(E6,'ETPT Format DDG'!$2:$2,0),MATCH(C6,'ETPT Format DDG'!$2:$2,0)) ), 'ETPT Format DDG'!$C:$C,$A$3, 'ETPT Format DDG'!$G:$G,"Magistrat") -> #N/A | M6: =IF(AND(OR(LEFT(C6,3)="12.",LEFT(E6,3)="12.",LEFT(E6,5)="CET >", IFERROR(L6/$L$6,"")=0),NOT(AND(LEFT(E6,5)="12.31",IFERROR(L6/$G$6,"")<>0)),NOT(AND(LEFT(E6,5)="12.32",IFERROR(L6/$G$6,"")<>0))),"", IFERROR(L6/$L$6,"")) | N6: =SUMIFS(INDEX('ETPT Format DDG'!$A:$DU,,IFERROR(MATCH(E6,'ETPT Format DDG'!$2:$2,0),MATCH(C6,'ETPT Format DDG'!$2:$2,0))),'ETPT Format DDG'!$I:$I,"F-TIT",'ETPT Format DDG'!$C:$C,$A$3) -> #N/A | O6: =IF(AND(OR(LEFT(C6,3)="12.",LEFT(E6,3)="12.",LEFT(E6,5)="CET >",IFERROR(N6/$N$6,"")=0),NOT(AND(LEFT(E6,5)="12.31",IFERROR(N6/$G$6,"")<>0)),NOT(AND(LEFT(E6,5)="12.32",IFERROR(N6/$G$6,"")<>0))),"",IFERROR(N6/$N$6,"")) | P6: =SUMIFS(INDEX('ETPT Format DDG'!$A:$DU,,IFERROR(MATCH(E6,'ETPT Format DDG'!$2:$2,0),MATCH(C6,'ETPT Format DDG'!$2:$2,0))),'ETPT Format DDG'!$I:$I,"F-PLAC-ADD",'ETPT Format DDG'!$C:$C,$A$3) -> #N/A | Q6: =SUMIFS(INDEX('ETPT Format DDG'!$A:$DU,,IFERROR(MATCH(E6,'ETPT Format DDG'!$2:$2,0),MATCH(C6,'ETPT Format DDG'!$2:$2,0))),'ETPT Format DDG'!$I:$I,"F-PLAC-SUB",'ETPT Format DDG'!$C:$C,$A$3) -> #N/A | R6: =SUMIFS(INDEX('ETPT Format DDG'!$A:$DU,,IFERROR(MATCH(E6,'ETPT Format DDG'!$2:$2,0),MATCH(C6,'ETPT Format DDG'!$2:$2,0))),'ETPT Format DDG'!$I:$I,"C",'ETPT Format DDG'!$C:$C,$A$3,'ETPT Format DDG'!$G:$G,"Greffe") -> #N/A | S6: =SUMIFS( INDEX('ETPT Format DDG'!$A:$DU, , IFERROR(MATCH(E6,'ETPT Format DDG'!$2:$2,0),MATCH(C6,'ETPT Format DDG'!$2:$2,0)) ), 'ETPT Format DDG'!$C:$C,$A$3, 'ETPT Format DDG'!$G:$G,"Greffe") -> #N/A | T6: =IF(AND(OR(LEFT(C6,3)="12.",LEFT(E6,3)="12.",LEFT(E6,5)="CET >",IFERROR(S6/$S$6,"")=0),NOT(AND(LEFT(E6,5)="12.31",IFERROR(S6/$G$6,"")<>0)),NOT(AND(LEFT(E6,5)="12.32",IFERROR(S6/$G$6,"")<>0))),"", IFERROR(S6/$S$6,"")) | U6: =SUMIFS( INDEX('ETPT Format DDG'!$A:$DU, , IFERROR(MATCH(E6,'ETPT Format DDG'!$2:$2,0),MATCH(C6,'ETPT Format DDG'!$2:$2,0)) ),'ETPT Format DDG'!$I:$I,"C", 'ETPT Format DDG'!$C:$C,$A$3, 'ETPT Format DDG'!$G:$G,"Autour du magistrat") -> #N/A | V6: =IF(AND(OR(LEFT(C6,3)="12.",LEFT(E6,3)="12.",LEFT(E6,5)="CET >",IFERROR(U6/$U$6,"")=0),NOT(AND(LEFT(E6,5)="12.31",IFERROR(U6/$G$6,"")<>0)),NOT(AND(LEFT(E6,5)="12.32",IFERROR(U6/$G$6,"")<>0))),"", IFERROR(U6/$U$6,"")) | W6: #! END_LOOP y
W7: #! FINISH

Sheet codage tribunal

Sheet Juridictions
A1: TJ | D1: TPROX | G1: CPH | I1: CPH détachés

Sheet Table_Fonctions
A1: Catégorie(s) | B1: Fonction | C1: Raccourci | D1: Titulaire / Placé / Contractuel | E1: CODE EXTRACTEUR | F1: Fonction recodée
A2: Magistrat | B2: PRÉSIDENT | C2: P | D2: Titulaire | E2: M-TIT | F2: Magistrat SIEGE NS
A3: Magistrat | B3: PREMIER VICE-PRÉSIDENT | C3: 1VP | D3: Titulaire | E3: M-TIT | F3: Magistrat SIEGE NS
A4: Magistrat | B4: PREMIER VICE-PRÉSIDENT ADJOINT | C4: 1VPA | D4: Titulaire | E4: M-TIT | F4: Magistrat SIEGE NS
A5: Magistrat | B5: PREMIER VICE-PRÉSIDENT CHARGÉ DES FONCTIONS DE JUGE DES CONTENTIEUX DE LA PROTECTION | C5: 1VPCP | D5: Titulaire | E5: M-TIT | F5: Magistrat SIEGE S
A6: Magistrat | B6: PREMIER VICE-PRÉSIDENT CHARGÉ DES FONCTIONS DE JUGE DES ENFANTS | C6: 1VPE | D6: Titulaire | E6: M-TIT | F6: Magistrat SIEGE S
A7: Magistrat | B7: PREMIER VICE-PRÉSIDENT CHARGÉ DES FONCTIONS DE JUGE D'INSTRUCTION | C7: 1VPI | D7: Titulaire | E7: M-TIT | F7: Magistrat SIEGE S
A8: Magistrat | B8: VICE-PRÉSIDENT CHARGÉ D'UN SECRÉTARIAT GÉNÉRAL | C8: VPSG | D8: Titulaire | E8: M-TIT | F8: Magistrat SIEGE NS
A9: Magistrat | B9: PREMIER VICE-PRÉSIDENT CHARGÉ DES FONCTIONS DE JUGE DE L'APPLICATION DES PEINES | C9: 1VPAP | D9: Titulaire | E9: M-TIT | F9: Magistrat SIEGE S
A10: Magistrat | B10: PREMIER VICE-PRÉSIDENT CHARGÉ DES FONCTIONS DE JUGE DES LIBERTÉS ET DE LA DÉTENTION | C10: 1VPLD | D10: Titulaire | E10: M-TIT | F10: Magistrat SIEGE S
A11: Magistrat | B11: VICE-PRÉSIDENT | C11: VP | D11: Titulaire | E11: M-TIT | F11: Magistrat SIEGE NS
A12: Magistrat | B12: VICE-PRÉSIDENT CHARGÉ DES FONCTIONS DE JUGE DES CONTENTIEUX DE LA PROTECTION | C12: VPCP | D12: Titulaire | E12: M-TIT | F12: Magistrat SIEGE S
... A55: Greffe | B55: CONTRACTUEL C JUSTICE DE PROXIMITE | C55: CONT C JP | D55: Contractuel | E55: C | F55: Fonctionnaire A-B-CBUR
A56: Autour du Juge | B56: ASSISTANT SPECIALISE | C56: AS | D56: Contractuel | E56: C | G56: Hors périmètre ventilation ETPT
A57: Autour du Juge | B57: ASSISTANT DE JUSTICE | C57: ADJ | D57: Contractuel | E57: C | F57: ASSIST_JUST
A58: Autour du Juge | B58: ATTACHÉ DE JUSTICE | D58: Contractuel | E58: C | F58: JURISTE AS
A59: Autour du Juge | B59: JURISTE ASSISTANT siège Autres | C59: JA Siège autres | D59: Contractuel | E59: C | F59: JURISTE AS siège Autres
A60: Autour du Juge | B60: JURISTE ASSISTANT Pôle social | C60: JA Pôle social | D60: Contractuel | E60: C | F60: JURISTE AS Pôle social
A61: Autour du Juge | B61: JURISTE ASSISTANT Parquet | C61: JA Parquet | D61: Contractuel | E61: C | F61: JURISTE AS Parquet
A62: Autour du Juge | B62: JURISTE ASSISTANT Vif | C62: JA VIF | D62: Contractuel | E62: C | F62: CONT A JP Autour du Juge
A63: Autour du Juge | B63: ELEVE AVOCAT | C63: PPI | D63: Contractuel | E63: C | G63: Hors périmètre ventilation ETPT
A64: Autour du Juge | B64: CONTRACTUEL A JUSTICE DE PROXIMITE | C64: JA JP | D64: Contractuel | E64: C | F64: CONT A JP Autour du Juge
A65: Autour du Juge | B65: CONTRACTUEL A JUSTICE DE PROXIMITE | C65: CONT A JP Autour du magistrat | D65: Contractuel | E65: C | F65: CONT A JP Autour du Juge
A66: Autour du Juge | B66: CONTRACTUEL B JUSTICE DE PROXIMITE | C66: CONT B JP Autour du magistrat | D66: Contractuel | E66: C | G66: Il me semble que cela n'existe pas (seulement sur Catégorie Greffe)
A67: Autour du Juge | B67: CONTRACTUEL C JUSTICE DE PROXIMITE | C67: CONT C JP Autour du magistrat | D67: Contractuel | E67: C | G67: Il me semble que cela n'existe pas (seulement sur Catégorie Greffe)
A71: Magistrat | B71: Premier Président | C71: PP | D71: Titulaire | E71: M-TIT
A72: Magistrat | B72: Premier Président de Chambre | C72: 1PC | D72: Titulaire | E72: M-TIT
A73: Magistrat | B73: Président de Chambre | C73: PC | D73: Titulaire | E73: M-TIT
A74: Magistrat | B74: Président de la Chambre de l'Instruction | C74: PCINS | D74: Titulaire | E74: M-TIT
A75: Magistrat | B75: Conseiller chargé d'un Secrétariat Général | C75: CSG | D75: Titulaire | E75: M-TIT
A76: Magistrat | B76: Conseiller | C76: C | D76: Titulaire | E76: M-TIT
A77: Magistrat | B77: Vice-Président placé | C77: VPP | D77: Placé | E77: M-PLAC-ADD
A78: Magistrat | B78: Juge placé | C78: JP | D78: Placé | E78: M-PLAC-ADD
A79: Magistrat | B79: Magistrat honoraire à fonctions juridictionnelles | C79: MHFJ | D79: Contractuel | E79: M-CONT
A80: Magistrat | B80: Magistrat honoraire à fonctions non juridictionnelles | C80: MHFNJ | D80: Contractuel | E80: M-CONT
A81: Magistrat | B81: Magistrat réserviste | C81: MRES | D81: Contractuel | E81: M-CONT
A82: Magistrat | B82: Magistrat à titre temporaire | C82: MTT | D82: Contractuel | E82: M-CONT
... A114: Autour du Juge | B114: Élève avocat | C114: PPI | D114: Titulaire | E114: C
B117: Fonction recodée (créer en parallèle une table de correspondance pour chaque fonction) avec les modalités recodées suivantes : Magistrats SIEGE ; Magistrats placés ADD ; Magistrats placés SUB ; Fonctionnaires CTECH ; Fonctionnaire CTECH placé ADD ; Fonctionnaire CTECH placé SUB ; Fonctionnaires A-B-CBUR ; Fonctionnaire A-B-CBUR placé ADD ; Fonctionnaire A-B-CBUR placé SUB ; JURISTE AS chambres sociales ; JURISTE AS siège Autres ; JURISTE AS parquet général ; JURISTE AS chambres sociales placé ADD ; JURISTE AS siège Autres placé ADD ; JURISTE AS parquet général placé ADD ; JURISTE AS chambres sociales placé SUB ; JURISTE AS siège Autres placé SUB ; JURISTE AS parquet général placé SUB.

Sheet ETPT_TJ
B1: DÉCLARATION ETPT TJ
G2: CTECH | H2: Total fonctionnaires techniques | I2: A-B-CBUR | J2: A-B-CBUR | K2: A-B-CBUR | L2: A-B-CBUR | M2: A-B-CBUR | N2: A-B-CBUR | O2: A-B-CBUR | P2: A-B-CBUR | Q2: A-B-CBUR | R2: A-B-CBUR | S2: A-B-CBUR | T2: A-B-CBUR | U2: A-B-CBUR | V2: A-B-CBUR | W2: Total fonctionnaires administratifs | X2: JURISTE AS | Y2: JURISTE AS | Z2: JURISTE AS | AA2: JURISTE AS | AB2: Total juristes assistants | AC2: SIEGE S | AD2: SIEGE S | AE2: SIEGE S | AF2: SIEGE S | AG2: SIEGE S | AH2: SIEGE S | AI2: SIEGE S | AJ2: SIEGE S | AK2: SIEGE S | AL2: Total magistrats du siège spécialisés | AM2: SIEGE NS | AN2: SIEGE NS | AO2: SIEGE NS | AP2: SIEGE NS | AQ2: SIEGE NS | AR2: SIEGE NS | AS2: SIEGE NS | AT2: SIEGE NS | AU2: SIEGE NS | AV2: SIEGE NS | AW2: SIEGE NS | AX2: SIEGE NS | AY2: SIEGE NS | AZ2: Total magistrats du siège non spécialisés | BA2: PRQT | BB2: PRQT | BC2: PRQT | BD2: PRQT | BE2: PRQT | BF2: PRQT | BG2: PRQT | BH2: PRQT | BI2: PRQT | BJ2: Total magistrats du parquet
G3: FONCTIONNAIRES_C_TECHNIQUES_SPEC | I3: FONCTIONNAIRES_ACTIVITE_CIV_PRQT | J3: FONCTIONNAIRES_BEX_APP | K3: FONCTIONNAIRES_ASSISES | L3: FONC_COUR_CRIM | M3: FONCTIONNAIRES_JIRS_ECOFI | N3: FONCTIONNAIRES_JIRS_CRIMO | O3: FONCTIONNAIRES_JIRS_SS | P3: FONC_TJ_TUT_MAJ | Q3: FONC_TJ_SURENDETTEMENT | S3: FONC_TJ_IP_SR | T3: FONC_CTX_GEN_INF_DIX_MIL | U3: FONC_P_SOC | V3: FONCTIONNAIRES_HORS_FONCT_SPEC | Y3: JUR_ASS_PARQUET | Z3: JUR_ASS_TASS | AA3: JUR_ASS_SIEGE | AC3: JCP_TJ_TUT_MAJ | AD3: JCP_TJ_SURENDETTEMENT | AE3: J_INSTRUCTION | AF3: J_INSTRUCTION_JIRS_ECOFI | AG3: J_INSTRUCTION_JIRS_CRIMO | AH3: J_INSTRUCTION_JIRS_SS | AI3: JAP | AJ3: JE | AK3: JLD_JNS | AM3: MAG_SIEGE_ASSISES | AN3: JNS_COUR_CRIM | AO3: MAG_SIEGE_JIRS_ECOFI | AP3: MAG_SIEGE_JIRS_CRIMO | AQ3: MAG_SIEGE_JIRS_SS | AR3: MAG_SIEGE_CONTRAV | AS3: TI_ACT_J_DEPARTITEUR | AT3: JUGE_CTX_GEN_INF_DIX_MIL | AU3: JUGE_TJ_IP_SR | AV3: JUGE_TASS_JNS | AW3: JAF_JNS | AX3: J_SPEC_ACT_NON_SPEC | AY3: AUTRES_JNS | BA3: PARQUET_ACTIVITE_CIV_COM | BB3: PARQUET_EXE_APP_PEINES | BC3: PARQUET_JIRS_ECOFI | BD3: PARQUET_JIRS_CRIMO | BE3: PARQUET_JIRS_SS | BF3: PARQUET_ASSISES | BG3: PQT_COUR_CRIM | BH3: PARQUET_TI | BI3: AUTRES_PARQUET
B4: UO | C4: Code de la juridiction | D4: Juridiction | E4: Code sous action | F4: Action | G4: Fonctionnaires Catégorie C Technique spécialisés | I4: Fonctionnaires activité civile et commerciale du parquet | J4: Fonctionnaires exécution des peines | K4: Fonctionnaires Assises | L4: Fonctionnaires Cour criminelle | M4: Fonctionnaires JIRS éco-fi | N4: Fonctionnaires JIRS crim-org | O4: Fonctionnaires sections spécialisées | P4: Fonctionnaires TJ Tutelles majeurs | Q4: Fonctionnaires TJ au surendettement et au hors surendettement | R4: Fonctionnaires affectés aux fonctions JI, JE, JAP, JLD | S4: Fonctionnaires TJ IP_Saisies Rém | T4: Fonctionnaires TJ Contentieux général < 10 000 EUR | U4: Fonctionnaires affectés aux pôles sociaux | V4: Fonctionnaires hors fonctions spécifiques | X4: de Contractuels A J Prox et A VIF | Y4: Juristes assistants au parquet | Z4: Juristes assistants Pôle social | AA4: Juristes assistants siège Autres | AC4: JCP TJ Tutelles majeurs | AD4: JCP TJ surendettement et hors surendettement | AE4: Juges Instruction - service général | AF4: Juges Instruction JIRS éco-fi | AG4: Juges Instruction JIRS crim-org | AH4: Juges Instruction sections spécialisées | AI4: JAP | AJ4: Juges des Enfants | AK4: JLD | AM4: Magistrats du Siège assises | AN4: Magistrats du siège Cour criminelle | AO4: Magistrat du siège JIRS éco-fi | AP4: Magistrat du siège JIRS crim-org | AQ4: Magistrat du siège sections spécialisées | AR4: Magistrats du Siège activité contraventionnelle | AS4: Magistrats activité juge départiteur | AT4: Juges TJ Contentieux général < 10 000 EUR | AU4: Juges TJ IP et Saisies Rém | AV4: Juges du Pôle social | AW4: JAF | AX4: Activités non spécialisés des juges spécialisés | AY4: Autres Magistrats du Siège non spécialisés | BA4: Magistrats du Parquet - activité civile et commerciale | BB4: Magistrats du Parquet - exécution et appl. des peines | BC4: Magistrats du Parquet JIRS éco-fi | BD4: Magistrats du Parquet JIRS crim-org | BE4: Magistrats du Parquet JIRS sections spécialisées | BF4: Magistrats du Parquet assises | BG4: Magistrats du Parquet Cour criminelle | BH4: Magistrats du Parquet - activité contraventionnelle | BI4: Autres Magistrats du Parquet
A5: ETPT_TJ | D5: =IF(ETPT_TJ_DDG!$D$5="","",ETPT_TJ_DDG!$D$5) | E5: 166-01-NC | F5: Action 1 - Traitement et jugement des contentieux civils | G5: =SUMIFS( INDEX( 'ETPT Format DDG'!$A:$EF,,MATCH("Temps ventilés sur la période (contentieux civils et sociaux)",'ETPT Format DDG'!2:2,0)),'ETPT Format DDG'!$C:$C,$D$5,'ETPT Format DDG'!$EA:$EA,"Fonctionnaire CTECH") -> #N/A | H5: =SUM(G5) -> #N/A | I5: =SUMIFS( INDEX( 'ETPT Format DDG'!$A:$EF,,MATCH("11.8. FONCTIONNAIRES AFFECTÉS AUX ACTIVITÉS CIVILES ET COMMERCIALES DU PARQUET",'ETPT Format DDG'!2:2,0)),'ETPT Format DDG'!$C:$C,$D$5,'ETPT Format DDG'!$EA:$EA,"Fonctionnaire A-B-CBUR") -> #N/A | P5: =SUMIFS( INDEX( 'ETPT Format DDG'!$A:$EF,,MATCH("3.2. PROTECTION DES MAJEURS",'ETPT Format DDG'!2:2,0)),'ETPT Format DDG'!$C:$C,$D$5,'ETPT Format DDG'!$EA:$EA,"Fonctionnaire A-B-CBUR") -> #N/A | Q5: =SUMIFS( INDEX( 'ETPT Format DDG'!$A:$EF,,MATCH("3. TOTAL CONTENTIEUX DE LA PROTECTION",'ETPT Format DDG'!2:2,0)),'ETPT Format DDG'!$C:$C,$D$5,'ETPT Format DDG'!$EA:$EA,"Fonctionnaire A-B-CBUR")- SUMIFS( INDEX( 'ETPT Format DDG'!$A:$EF,,MATCH("3.2. PROTECTION DES MAJEURS",'ETPT Format DDG'!2:2,0)),'ETPT Format DDG'!$C:$C,$D$5,'ETPT Format DDG'!$EA:$EA,"Fonctionnaire A-B-CBUR")- SUMIFS( INDEX( 'ETPT Format DDG'!$A:$EF,,MATCH("3.43. INJONCTIONS DE PAYER",'ETPT Format DDG'!2:2,0)),'ETPT Format DDG'!$C:$C,$D$5,'ETPT Format DDG'!$EA:$EA,"Fonctionnaire A-B-CBUR")- SUMIFS( INDEX( 'ETPT Format DDG'!$A:$EF,,MATCH("3.44. SAISIE DES RÉMUNÉRATIONS",'ETPT Format DDG'!2:2,0)),'ETPT Format DDG'!$C:$C,$D$5,'ETPT Format DDG'!$EA:$EA,"Fonctionnaire A-B-CBUR") -> #N/A | R5: =SUMIFS( INDEX( 'ETPT Format DDG'!$A:$EF,,MATCH("5. TOTAL JLD CIVIL",'ETPT Format DDG'!2:2,0)),'ETPT Format DDG'!$C:$C,$D$5,'ETPT Format DDG'!$EA:$EA,"Fonctionnaire A-B-CBUR") +SUMIFS( INDEX( 'ETPT Format DDG'!$A:$EF,,MATCH("6.1. ACTIVITÉ CIVILE",'ETPT Format DDG'!2:2,0)),'ETPT Format DDG'!$C:$C,$D$5,'ETPT Format DDG'!$EA:$EA,"Fonctionnaire A-B-CBUR") -> #N/A | S5: =SUMIFS( INDEX( 'ETPT Format DDG'!$A:$EF,,MATCH("3.43. INJONCTIONS DE PAYER",'ETPT Format DDG'!2:2,0)),'ETPT Format DDG'!$C:$C,$D$5,'ETPT Format DDG'!$EA:$EA,"Fonctionnaire A-B-CBUR")+ SUMIFS( INDEX( 'ETPT Format DDG'!$A:$EF,,MATCH("3.44. SAISIE DES RÉMUNÉRATIONS",'ETPT Format DDG'!2:2,0)),'ETPT Format DDG'!$C:$C,$D$5,'ETPT Format DDG'!$EA:$EA,"Fonctionnaire A-B-CBUR") -> #N/A | T5: =SUMIFS( INDEX( 'ETPT Format DDG'!$A:$EF,,MATCH("4.0. CONTENTIEUX GÉNÉRAL <10.000€",'ETPT Format DDG'!2:2,0)),'ETPT Format DDG'!$C:$C,$D$5,'ETPT Format DDG'!$EA:$EA,"Fonctionnaire A-B-CBUR") -> #N/A | U5: =SUMIFS( INDEX( 'ETPT Format DDG'!$A:$EF,,MATCH("1. TOTAL CONTENTIEUX SOCIAL",'ETPT Format DDG'!2:2,0)),'ETPT Format DDG'!$C:$C,$D$5,'ETPT Format DDG'!$EA:$EA,"Fonctionnaire A-B-CBUR") -> #N/A | V5: =SUMIFS( INDEX( 'ETPT Format DDG'!$A:$EF,,MATCH("Temps ventilés sur la période (contentieux civils et sociaux)",'ETPT Format DDG'!2:2,0)),'ETPT Format DDG'!$C:$C,$D$5,'ETPT Format DDG'!$EA:$EA,"Fonctionnaire A-B-CBUR")-SUM(K5:U5) -> #N/A | W5: =SUM(I5:V5) -> #N/A | X5: =SUMIFS( INDEX( 'ETPT Format DDG'!$A:$EF,,MATCH("Temps ventilés sur la période (contentieux civils et sociaux)",'ETPT Format DDG'!2:2,0)),'ETPT Format DDG'!$C:$C,$D$5,'ETPT Format DDG'!$EA:$EA,"CONT A JP Autour du Juge") -> #N/A | Y5: =SUMIFS( INDEX( 'ETPT Format DDG'!$A:$EF,,MATCH("Temps ventilés sur la période (contentieux civils et sociaux)",'ETPT Format DDG'!2:2,0)),'ETPT Format DDG'!$C:$C,$D$5,'ETPT Format DDG'!$EA:$EA,"JURISTE AS Parquet") -> #N/A | Z5: =SUMIFS( INDEX( 'ETPT Format DDG'!$A:$EF,,MATCH("Temps ventilés sur la période (contentieux civils et sociaux)",'ETPT Format DDG'!2:2,0)),'ETPT Format DDG'!$C:$C,$D$5,'ETPT Format DDG'!$EA:$EA,"JURISTE AS Pôle social") -> #N/A | AA5: =SUMIFS( INDEX( 'ETPT Format DDG'!$A:$EF,,MATCH("Temps ventilés sur la période (contentieux civils et sociaux)",'ETPT Format DDG'!2:2,0)),'ETPT Format DDG'!$C:$C,$D$5,'ETPT Format DDG'!$EA:$EA,"JURISTE AS siège Autres") -> #N/A | AB5: =SUM(X5:AA5) -> #N/A | AC5: =SUMIFS( INDEX( 'ETPT Format DDG'!$A:$EF,,MATCH("3.2. PROTECTION DES MAJEURS",'ETPT Format DDG'!2:2,0)),'ETPT Format DDG'!$C:$C,$D$5,'ETPT Format DDG'!$EA:$EA,"Magistrat SIEGE NS")+ SUMIFS( INDEX( 'ETPT Format DDG'!$A:$EF,,MATCH("3.2. PROTECTION DES MAJEURS",'ETPT Format DDG'!2:2,0)),'ETPT Format DDG'!$C:$C,$D$5,'ETPT Format DDG'!$EA:$EA,"Magistrat SIEGE S") -> #N/A | AD5: =SUMIFS( INDEX( 'ETPT Format DDG'!$A:$EF,,MATCH("3. TOTAL CONTENTIEUX DE LA PROTECTION",'ETPT Format DDG'!2:2,0)),'ETPT Format DDG'!$C:$C,$D$5,'ETPT Format DDG'!$EA:$EA,"Magistrat SIEGE NS")+ SUMIFS( INDEX( 'ETPT Format DDG'!$A:$EF,,MATCH("3. TOTAL CONTENTIEUX DE LA PROTECTION",'ETPT Format DDG'!2:2,0)),'ETPT Format DDG'!$C:$C,$D$5,'ETPT Format DDG'!$EA:$EA,"Magistrat SIEGE S")- SUMIFS( INDEX( 'ETPT Format DDG'!$A:$EF,,MATCH("3.2. PROTECTION DES MAJEURS",'ETPT Format DDG'!2:2,0)),'ETPT Format DDG'!$C:$C,$D$5,'ETPT Format DDG'!$EA:$EA,"Magistrat SIEGE NS")- SUMIFS( INDEX( 'ETPT Format DDG'!$A:$EF,,MATCH("3.2. PROTECTION DES MAJEURS",'ETPT Format DDG'!2:2,0)),'ETPT Format DDG'!$C:$C,$D$5,'ETPT Format DDG'!$EA:$EA,"Magistrat SIEGE S")- SUMIFS( INDEX( 'ETPT Format DDG'!$A:$EF,,MATCH("3.43. INJONCTIONS DE PAYER",'ETPT Format DDG'!2:2,0)),'ETPT Format DDG'!$C:$C,$D$5,'ETPT Format DDG'!$EA:$EA,"Magistrat SIEGE NS")- SUMIFS( INDEX( 'ETPT Format DDG'!$A:$EF,,MATCH("3.43. INJONCTIONS DE PAYER",'ETPT Format DDG'!2:2,0)),'ETPT Format DDG'!$C:$C,$D$5,'ETPT Format DDG'!$EA:$EA,"Magistrat SIEGE S")- SUMIFS( INDEX( 'ETPT Format DDG'!$A:$EF,,MATCH("3.44. SAISIE DES RÉMUNÉRATIONS",'ETPT Format DDG'!2:2,0)),'ETPT Format DDG'!$C:$C,$D$5,'ETPT Format DDG'!$EA:$EA,"Magistrat SIEGE NS")- SUMIFS( INDEX( 'ETPT Format DDG'!$A:$EF,,MATCH("3.44. SAISIE DES RÉMUNÉRATIONS",'ETPT Format DDG'!2:2,0)),'ETPT Format DDG'!$C:$C,$D$5,'ETPT Format DDG'!$EA:$EA,"Magistrat SIEGE S") -> #N/A | AJ5: =SUMIFS( INDEX( 'ETPT Format DDG'!$A:$EF,,MATCH("6.1. ACTIVITÉ CIVILE",'ETPT Format DDG'!2:2,0)),'ETPT Format DDG'!$EA:$EA,"Magistrat SIEGE NS")+ SUMIFS( INDEX( 'ETPT Format DDG'!$A:$EF,,MATCH("6.1. ACTIVITÉ CIVILE",'ETPT Format DDG'!2:2,0)),'ETPT Format DDG'!$EA:$EA,"Magistrat SIEGE S") -> #N/A | AK5: =SUMIFS( INDEX( 'ETPT Format DDG'!$A:$EF,,MATCH("5. TOTAL JLD CIVIL",'ETPT Format DDG'!2:2,0)),'ETPT Format DDG'!$EA:$EA,"Magistrat SIEGE NS")+ SUMIFS( INDEX( 'ETPT Format DDG'!$A:$EF,,MATCH("5. TOTAL JLD CIVIL",'ETPT Format DDG'!2:2,0)),'ETPT Format DDG'!$EA:$EA,"Magistrat SIEGE S") -> #N/A | AL5: =SUM(AC5:AK5) -> #N/A | AS5: =SUMIFS( INDEX( 'ETPT Format DDG'!$A:$EF,,MATCH("1.1. DÉPARTAGE PRUD'HOMAL",'ETPT Format DDG'!2:2,0)),'ETPT Format DDG'!$C:$C,$D$5,'ETPT Format DDG'!$EA:$EA,"Magistrat SIEGE NS") -> #N/A | AT5: =SUMIFS( INDEX( 'ETPT Format DDG'!$A:$EF,,MATCH("4.0. CONTENTIEUX GÉNÉRAL <10.000€",'ETPT Format DDG'!2:2,0)),'ETPT Format DDG'!$C:$C,$D$5,'ETPT Format DDG'!$EA:$EA,"Magistrat SIEGE NS") -> #N/A | AU5: =SUMIFS( INDEX( 'ETPT Format DDG'!$A:$EF,,MATCH("3.43. INJONCTIONS DE PAYER",'ETPT Format DDG'!2:2,0)),'ETPT Format DDG'!$C:$C,$D$5,'ETPT Format DDG'!$EA:$EA,"Magistrat SIEGE NS")+ SUMIFS( INDEX( 'ETPT Format DDG'!$A:$EF,,MATCH("3.44. SAISIE DES RÉMUNÉRATIONS",'ETPT Format DDG'!2:2,0)),'ETPT Format DDG'!$C:$C,$D$5,'ETPT Format DDG'!$EA:$EA,"Magistrat SIEGE NS") -> #N/A | AV5: =SUMIFS( INDEX( 'ETPT Format DDG'!$A:$EF,,MATCH("1. TOTAL CONTENTIEUX SOCIAL",'ETPT Format DDG'!2:2,0)),'ETPT Format DDG'!$C:$C,$D$5,'ETPT Format DDG'!$EA:$EA,"Magistrat SIEGE NS")- SUMIFS( INDEX( 'ETPT Format DDG'!$A:$EF,,MATCH("1.1. DÉPARTAGE PRUD'HOMAL",'ETPT Format DDG'!2:2,0)),'ETPT Format DDG'!$C:$C,$D$5,'ETPT Format DDG'!$EA:$EA,"Magistrat SIEGE NS") -> #N/A | AW5: =SUMIFS( INDEX( 'ETPT Format DDG'!$A:$EF,,MATCH("2. TOTAL CONTENTIEUX JAF",'ETPT Format DDG'!2:2,0)),'ETPT Format DDG'!$EA:$EA,"Magistrat SIEGE NS") -> #N/A | AX5: =SUMIFS( INDEX( 'ETPT Format DDG'!$A:$EF,,MATCH("Temps ventilés sur la période (contentieux civils et sociaux)",'ETPT Format DDG'!2:2,0)),'ETPT Format DDG'!$C:$C,$D$5,'ETPT Format DDG'!$EA:$EA,"Magistrat SIEGE S")- SUMIFS( INDEX( 'ETPT Format DDG'!$A:$EF,,MATCH("3. TOTAL CONTENTIEUX DE LA PROTECTION",'ETPT Format DDG'!2:2,0)),'ETPT Format DDG'!$C:$C,$D$5,'ETPT Format DDG'!$EA:$EA,"Magistrat SIEGE S")+ SUMIFS( INDEX( 'ETPT Format DDG'!$A:$EF,,MATCH("3.43. INJONCTIONS DE PAYER",'ETPT Format DDG'!2:2,0)),'ETPT Format DDG'!$C:$C,$D$5,'ETPT Format DDG'!$EA:$EA,"Magistrat SIEGE S")+ SUMIFS( INDEX( 'ETPT Format DDG'!$A:$EF,,MATCH("3.44. SAISIE DES RÉMUNÉRATIONS",'ETPT Format DDG'!2:2,0)),'ETPT Format DDG'!$C:$C,$D$5,'ETPT Format DDG'!$EA:$EA,"Magistrat SIEGE S")- SUMIFS( INDEX( 'ETPT Format DDG'!$A:$EF,,MATCH("6.1. ACTIVITÉ CIVILE",'ETPT Format DDG'!2:2,0)),'ETPT Format DDG'!$C:$C,$D$5,'ETPT Format DDG'!$EA:$EA,"Magistrat SIEGE S")- SUMIFS( INDEX( 'ETPT Format DDG'!$A:$EF,,MATCH("5. TOTAL JLD CIVIL",'ETPT Format DDG'!2:2,0)),'ETPT Format DDG'!$C:$C,$D$5,'ETPT Format DDG'!$EA:$EA,"Magistrat SIEGE S") -> #N/A | AY5: =SUMIFS( INDEX( 'ETPT Format DDG'!$A:$EF,,MATCH("Temps ventilés sur la période (contentieux civils et sociaux)",'ETPT Format DDG'!2:2,0)),'ETPT Format DDG'!$C:$C,$D$5,'ETPT Format DDG'!$EA:$EA,"Magistrat SIEGE NS")- SUMIFS( INDEX( 'ETPT Format DDG'!$A:$EF,,MATCH("3.2. PROTECTION DES MAJEURS",'ETPT Format DDG'!2:2,0)),'ETPT Format DDG'!$C:$C,$D$5,'ETPT Format DDG'!$EA:$EA,"Magistrat SIEGE NS")- (SUMIFS( INDEX( 'ETPT Format DDG'!$A:$EF,,MATCH("3. TOTAL CONTENTIEUX DE LA PROTECTION",'ETPT Format DDG'!2:2,0)),'ETPT Format DDG'!$C:$C,$D$5,'ETPT Format DDG'!$EA:$EA,"Magistrat SIEGE NS")- SUMIFS( INDEX( 'ETPT Format DDG'!$A:$EF,,MATCH("3.2. PROTECTION DES MAJEURS",'ETPT Format DDG'!2:2,0)),'ETPT Format DDG'!$C:$C,$D$5,'ETPT Format DDG'!$EA:$EA,"Magistrat SIEGE NS")- SUMIFS( INDEX( 'ETPT Format DDG'!$A:$EF,,MATCH("3.43. INJONCTIONS DE PAYER",'ETPT Format DDG'!2:2,0)),'ETPT Format DDG'!$C:$C,$D$5,'ETPT Format DDG'!$EA:$EA,"Magistrat SIEGE NS")- SUMIFS( INDEX( 'ETPT Format DDG'!$A:$EF,,MATCH("3.44. SAISIE DES RÉMUNÉRATIONS",'ETPT Format DDG'!2:2,0)),'ETPT Format DDG'!$C:$C,$D$5,'ETPT Format DDG'!$EA:$EA,"Magistrat SIEGE NS"))- SUMIFS( INDEX( 'ETPT Format DDG'!$A:$EF,,MATCH("6.1. ACTIVITÉ CIVILE",'ETPT Format DDG'!2:2,0)),'ETPT Format DDG'!$C:$C,$D$5,'ETPT Format DDG'!$EA:$EA,"Magistrat SIEGE NS")- SUMIFS( INDEX( 'ETPT Format DDG'!$A:$EF,,MATCH("5. TOTAL JLD CIVIL",'ETPT Format DDG'!2:2,0)),'ETPT Format DDG'!$C:$C,$D$5,'ETPT Format DDG'!$EA:$EA,"Magistrat SIEGE NS")- SUM(AS5:AW5) -> #N/A | AZ5: =SUM(AM5:AY5) -> #N/A | BJ5: =SUM(BA5:BI5) -> 0
A6: ETPT_TJ | D6: =$D$5 | E6: 166-02-NC | F6: Action 2 - Traitement et jugement des affaires pénales | G6: =SUMIFS( INDEX( 'ETPT Format DDG'!$A:$EF,,MATCH("Temps ventilés sur la période (affaires pénales)",'ETPT Format DDG'!2:2,0)),'ETPT Format DDG'!$EA:$EA,"Fonctionnaire CTECH") -> #N/A | H6: =SUM(G6) -> #N/A | J6: =SUMIFS( INDEX( 'ETPT Format DDG'!$A:$EF,,MATCH("11.9. FONCTIONNAIRES AFFECTÉS À L'EXÉCUTION DES PEINES",'ETPT Format DDG'!2:2,0)),'ETPT Format DDG'!$EA:$EA,"Fonctionnaire A-B-CBUR") -> #N/A | K6: =SUMIFS( INDEX( 'ETPT Format DDG'!$A:$EF,,MATCH("7.5. COUR D'ASSISES HORS JIRS",'ETPT Format DDG'!2:2,0)),'ETPT Format DDG'!$EA:$EA,"Fonctionnaire A-B-CBUR")+ SUMIFS( INDEX( 'ETPT Format DDG'!$A:$EF,,MATCH("7.51. COUR D'ASSISES JIRS",'ETPT Format DDG'!2:2,0)),'ETPT Format DDG'!$EA:$EA,"Fonctionnaire A-B-CBUR") -> #N/A | L6: =SUMIFS( INDEX( 'ETPT Format DDG'!$A:$EF,,MATCH("7.52. COUR CRIMINELLE",'ETPT Format DDG'!2:2,0)),'ETPT Format DDG'!$EA:$EA,"Fonctionnaire A-B-CBUR") -> #N/A | M6: =SUMIFS( INDEX( 'ETPT Format DDG'!$A:$EF,,MATCH("8.2. JIRS ÉCO-FI",'ETPT Format DDG'!2:2,0)),'ETPT Format DDG'!$EA:$EA,"Fonctionnaire A-B-CBUR") -> #N/A | N6: =SUMIFS( INDEX( 'ETPT Format DDG'!$A:$EF,,MATCH("8.3. JIRS CRIM-ORG",'ETPT Format DDG'!2:2,0)),'ETPT Format DDG'!$EA:$EA,"Fonctionnaire A-B-CBUR") -> #N/A | O6: =SUMIFS( INDEX( 'ETPT Format DDG'!$A:$EF,,MATCH("8.4. AUTRES SECTIONS SPÉCIALISÉES",'ETPT Format DDG'!2:2,0)),'ETPT Format DDG'!$EA:$EA,"Fonctionnaire A-B-CBUR") -> #N/A | R6: =SUMIFS( INDEX( 'ETPT Format DDG'!$A:$EF,,MATCH("6.2. ACTIVITÉ PÉNALE",'ETPT Format DDG'!2:2,0)),'ETPT Format DDG'!$EA:$EA,"Fonctionnaire A-B-CBUR")+ (SUMIFS( INDEX( 'ETPT Format DDG'!$A:$EF,,MATCH("8. TOTAL JUGES D'INSTRUCTION",'ETPT Format DDG'!2:2,0)),'ETPT Format DDG'!$EA:$EA,"Fonctionnaire A-B-CBUR")- SUMIFS( INDEX( 'ETPT Format DDG'!$A:$EF,,MATCH("8.2. JIRS ÉCO-FI",'ETPT Format DDG'!2:2,0)),'ETPT Format DDG'!$EA:$EA,"Fonctionnaire A-B-CBUR")- SUMIFS( INDEX( 'ETPT Format DDG'!$A:$EF,,MATCH("8.3. JIRS CRIM-ORG",'ETPT Format DDG'!2:2,0)),'ETPT Format DDG'!$EA:$EA,"Fonctionnaire A-B-CBUR")- SUMIFS( INDEX( 'ETPT Format DDG'!$A:$EF,,MATCH("8.4. AUTRES SECTIONS SPÉCIALISÉES",'ETPT Format DDG'!2:2,0)),'ETPT Format DDG'!$EA:$EA,"Fonctionnaire A-B-CBUR"))+ SUMIFS( INDEX( 'ETPT Format DDG'!$A:$EF,,MATCH("9. TOTAL JAP",'ETPT Format DDG'!2:2,0)),'ETPT Format DDG'!$EA:$EA,"Fonctionnaire A-B-CBUR")+ SUMIFS( INDEX( 'ETPT Format DDG'!$A:$EF,,MATCH("10. TOTAL JLD PÉNAL",'ETPT Format DDG'!2:2,0)),'ETPT Format DDG'!$EA:$EA,"Fonctionnaire A-B-CBUR") -> #N/A | V6: =SUMIFS( INDEX( 'ETPT Format DDG'!$A:$EF,,MATCH("Temps ventilés sur la période (affaires pénales)",'ETPT Format DDG'!2:2,0)),'ETPT Format DDG'!$EA:$EA,"Fonctionnaire A-B-CBUR")+ SUMIFS( INDEX( 'ETPT Format DDG'!$A:$EF,,MATCH("11.10. AUTRES FONCTIONNAIRES AFFECTÉS AU PARQUET",'ETPT Format DDG'!2:2,0)),'ETPT Format DDG'!$EA:$EA,"Fonctionnaire A-B-CBUR")- SUM(K6:U6) -> #N/A | W6: =SUM(I6:V6) -> #N/A | X6: =SUMIFS( INDEX( 'ETPT Format DDG'!$A:$EF,,MATCH("Temps ventilés sur la période (affaires pénales)",'ETPT Format DDG'!2:2,0)),'ETPT Format DDG'!$EA:$EA,"CONT A JP Autour du Juge")+ SUMIFS( INDEX( 'ETPT Format DDG'!$A:$EF,,MATCH("11.10. AUTRES FONCTIONNAIRES AFFECTÉS AU PARQUET",'ETPT Format DDG'!2:2,0)),'ETPT Format DDG'!$EA:$EA,"CONT A JP Autour du Juge") -> #N/A | Y6: =SUMIFS( INDEX( 'ETPT Format DDG'!$A:$EF,,MATCH("Temps ventilés sur la période (affaires pénales)",'ETPT Format DDG'!2:2,0)),'ETPT Format DDG'!$EA:$EA,"JURISTE AS Parquet")+ SUMIFS( INDEX( 'ETPT Format DDG'!$A:$EF,,MATCH("11.10. AUTRES FONCTIONNAIRES AFFECTÉS AU PARQUET",'ETPT Format DDG'!2:2,0)),'ETPT Format DDG'!$EA:$EA,"JURISTE AS Parquet") -> #N/A | Z6: =SUMIFS( INDEX( 'ETPT Format DDG'!$A:$EF,,MATCH("Temps ventilés sur la période (affaires pénales)",'ETPT Format DDG'!2:2,0)),'ETPT Format DDG'!$EA:$EA,"JURISTE AS Pôle social")+ SUMIFS( INDEX( 'ETPT Format DDG'!$A:$EF,,MATCH("11.10. AUTRES FONCTIONNAIRES AFFECTÉS AU PARQUET",'ETPT Format DDG'!2:2,0)),'ETPT Format DDG'!$EA:$EA,"JURISTE AS Pôle social") -> #N/A | AA6: =SUMIFS( INDEX( 'ETPT Format DDG'!$A:$EF,,MATCH("Temps ventilés sur la période (affaires pénales)",'ETPT Format DDG'!2:2,0)),'ETPT Format DDG'!$EA:$EA,"JURISTE AS siège Autres")+ SUMIFS( INDEX( 'ETPT Format DDG'!$A:$EF,,MATCH("11.10. AUTRES FONCTIONNAIRES AFFECTÉS AU PARQUET",'ETPT Format DDG'!2:2,0)),'ETPT Format DDG'!$EA:$EA,"JURISTE AS siège Autres") -> #N/A | AB6: =SUM(X6:AA6) -> #N/A | AE6: =SUMIFS( INDEX( 'ETPT Format DDG'!$A:$EF,,MATCH("8.1. SERVICE GÉNÉRAL",'ETPT Format DDG'!2:2,0)),'ETPT Format DDG'!$EA:$EA,"Magistrat SIEGE NS")+ SUMIFS( INDEX( 'ETPT Format DDG'!$A:$EF,,MATCH("8.1. SERVICE GÉNÉRAL",'ETPT Format DDG'!2:2,0)),'ETPT Format DDG'!$EA:$EA,"Magistrat SIEGE S") -> #N/A | AF6: =SUMIFS( INDEX( 'ETPT Format DDG'!$A:$EF,,MATCH("8.2. JIRS ÉCO-FI",'ETPT Format DDG'!2:2,0)),'ETPT Format DDG'!$EA:$EA,"Magistrat SIEGE NS")+ SUMIFS( INDEX( 'ETPT Format DDG'!$A:$EF,,MATCH("8.2. JIRS ÉCO-FI",'ETPT Format DDG'!2:2,0)),'ETPT Format DDG'!$EA:$EA,"Magistrat SIEGE S") -> #N/A | AG6: =SUMIFS( INDEX( 'ETPT Format DDG'!$A:$EF,,MATCH("8.3. JIRS CRIM-ORG",'ETPT Format DDG'!2:2,0)),'ETPT Format DDG'!$EA:$EA,"Magistrat SIEGE NS")+ SUMIFS( INDEX( 'ETPT Format DDG'!$A:$EF,,MATCH("8.3. JIRS CRIM-ORG",'ETPT Format DDG'!2:2,0)),'ETPT Format DDG'!$EA:$EA,"Magistrat SIEGE S") -> #N/A | AH6: =SUMIFS( INDEX( 'ETPT Format DDG'!$A:$EF,,MATCH("8.4. AUTRES SECTIONS SPÉCIALISÉES",'ETPT Format DDG'!2:2,0)),'ETPT Format DDG'!$EA:$EA,"Magistrat SIEGE NS")+ SUMIFS( INDEX( 'ETPT Format DDG'!$A:$EF,,MATCH("8.4. AUTRES SECTIONS SPÉCIALISÉES",'ETPT Format DDG'!2:2,0)),'ETPT Format DDG'!$EA:$EA,"Magistrat SIEGE S") -> #N/A | AI6: =SUMIFS( INDEX( 'ETPT Format DDG'!$A:$EF,,MATCH("9. TOTAL JAP",'ETPT Format DDG'!2:2,0)),'ETPT Format DDG'!$EA:$EA,"Magistrat SIEGE NS")+ SUMIFS( INDEX( 'ETPT Format DDG'!$A:$EF,,MATCH("9. TOTAL JAP",'ETPT Format DDG'!2:2,0)),'ETPT Format DDG'!$EA:$EA,"Magistrat SIEGE S") -> #N/A | AJ6: =SUMIFS( INDEX( 'ETPT Format DDG'!$A:$EF,,MATCH("6.2. ACTIVITÉ PÉNALE",'ETPT Format DDG'!2:2,0)),'ETPT Format DDG'!$EA:$EA,"Magistrat SIEGE NS")+ SUMIFS( INDEX( 'ETPT Format DDG'!$A:$EF,,MATCH("6.2. ACTIVITÉ PÉNALE",'ETPT Format DDG'!2:2,0)),'ETPT Format DDG'!$EA:$EA,"Magistrat SIEGE S") -> #N/A | AK6: =SUMIFS( INDEX( 'ETPT Format DDG'!$A:$EF,,MATCH("10. TOTAL JLD PÉNAL",'ETPT Format DDG'!2:2,0)),'ETPT Format DDG'!$EA:$EA,"Magistrat SIEGE NS")+ SUMIFS( INDEX( 'ETPT Format DDG'!$A:$EF,,MATCH("10. TOTAL JLD PÉNAL",'ETPT Format DDG'!2:2,0)),'ETPT Format DDG'!$EA:$EA,"Magistrat SIEGE S") -> #N/A | AL6: =SUM(AC6:AK6) -> #N/A | AM6: =SUMIFS( INDEX( 'ETPT Format DDG'!$A:$EF,,MATCH("7.5. COUR D'ASSISES HORS JIRS",'ETPT Format DDG'!2:2,0)),'ETPT Format DDG'!$EA:$EA,"Magistrat SIEGE NS")+ SUMIFS( INDEX( 'ETPT Format DDG'!$A:$EF,,MATCH("7.51. COUR D'ASSISES JIRS",'ETPT Format DDG'!2:2,0)),'ETPT Format DDG'!$EA:$EA,"Magistrat SIEGE NS") -> #N/A | AN6: =SUMIFS( INDEX( 'ETPT Format DDG'!$A:$EF,,MATCH("7.52. COUR CRIMINELLE",'ETPT Format DDG'!2:2,0)),'ETPT Format DDG'!$EA:$EA,"Magistrat SIEGE NS") -> #N/A | AO6: =SUMIFS( INDEX( 'ETPT Format DDG'!$A:$EF,,MATCH("7.121. COLLÉGIALES JIRS ECO-FI",'ETPT Format DDG'!2:2,0)),'ETPT Format DDG'!$EA:$EA,"Magistrat SIEGE NS") -> #N/A | AP6: =SUMIFS( INDEX( 'ETPT Format DDG'!$A:$EF,,MATCH("7.12. COLLÉGIALES JIRS CRIM-ORG",'ETPT Format DDG'!2:2,0)),'ETPT Format DDG'!$EA:$EA,"Magistrat SIEGE NS") -> #N/A | AQ6: =SUMIFS( INDEX( 'ETPT Format DDG'!$A:$EF,,MATCH("7.122. COLLÉGIALES AUTRES SECTIONS SPÉCIALISÉES",'ETPT Format DDG'!2:2,0)),'ETPT Format DDG'!$EA:$EA,"Magistrat SIEGE NS") -> #N/A | AR6: =SUMIFS( INDEX( 'ETPT Format DDG'!$A:$EF,,MATCH("7.6. TRIBUNAL DE POLICE",'ETPT Format DDG'!2:2,0)),'ETPT Format DDG'!$EA:$EA,"Magistrat SIEGE NS")+ SUMIFS( INDEX( 'ETPT Format DDG'!$A:$EF,,MATCH("7.7. OP CONTRAVENTIONNELLES",'ETPT Format DDG'!2:2,0)),'ETPT Format DDG'!$EA:$EA,"Magistrat SIEGE NS") -> #N/A | AX6: =SUMIFS( INDEX( 'ETPT Format DDG'!$A:$EF,,MATCH("Temps ventilés sur la période (affaires pénales)",'ETPT Format DDG'!2:2,0)),'ETPT Format DDG'!$EA:$EA,"Magistrat SIEGE S")- SUMIFS( INDEX( 'ETPT Format DDG'!$A:$EF,,MATCH("8.1. SERVICE GÉNÉRAL",'ETPT Format DDG'!2:2,0)),'ETPT Format DDG'!$EA:$EA,"Magistrat SIEGE S")- SUMIFS( INDEX( 'ETPT Format DDG'!$A:$EF,,MATCH("8.2. JIRS ÉCO-FI",'ETPT Format DDG'!2:2,0)),'ETPT Format DDG'!$EA:$EA,"Magistrat SIEGE S")- SUMIFS( INDEX( 'ETPT Format DDG'!$A:$EF,,MATCH("8.3. JIRS CRIM-ORG",'ETPT Format DDG'!2:2,0)),'ETPT Format DDG'!$EA:$EA,"Magistrat SIEGE S")- SUMIFS( INDEX( 'ETPT Format DDG'!$A:$EF,,MATCH("8.4. AUTRES SECTIONS SPÉCIALISÉES",'ETPT Format DDG'!2:2,0)),'ETPT Format DDG'!$EA:$EA,"Magistrat SIEGE S")- SUMIFS( INDEX( 'ETPT Format DDG'!$A:$EF,,MATCH("9. TOTAL JAP",'ETPT Format DDG'!2:2,0)),'ETPT Format DDG'!$EA:$EA,"Magistrat SIEGE S")- SUMIFS( INDEX( 'ETPT Format DDG'!$A:$EF,,MATCH("6.2. ACTIVITÉ PÉNALE",'ETPT Format DDG'!2:2,0)),'ETPT Format DDG'!$EA:$EA,"Magistrat SIEGE S")- SUMIFS( INDEX( 'ETPT Format DDG'!$A:$EF,,MATCH("10. TOTAL JLD PÉNAL",'ETPT Format DDG'!2:2,0)),'ETPT Format DDG'!$EA:$EA,"Magistrat SIEGE S") -> #N/A | AY6: =SUMIFS( INDEX( 'ETPT Format DDG'!$A:$EF,,MATCH("Temps ventilés sur la période (affaires pénales)",'ETPT Format DDG'!2:2,0)),'ETPT Format DDG'!$EA:$EA,"Magistrat SIEGE NS")- SUMIFS( INDEX( 'ETPT Format DDG'!$A:$EF,,MATCH("8.1. SERVICE GÉNÉRAL",'ETPT Format DDG'!2:2,0)),'ETPT Format DDG'!$EA:$EA,"Magistrat SIEGE NS")- SUMIFS( INDEX( 'ETPT Format DDG'!$A:$EF,,MATCH("8.2. JIRS ÉCO-FI",'ETPT Format DDG'!2:2,0)),'ETPT Format DDG'!$EA:$EA,"Magistrat SIEGE NS")- SUMIFS( INDEX( 'ETPT Format DDG'!$A:$EF,,MATCH("8.3. JIRS CRIM-ORG",'ETPT Format DDG'!2:2,0)),'ETPT Format DDG'!$EA:$EA,"Magistrat SIEGE NS")- SUMIFS( INDEX( 'ETPT Format DDG'!$A:$EF,,MATCH("8.4. AUTRES SECTIONS SPÉCIALISÉES",'ETPT Format DDG'!2:2,0)),'ETPT Format DDG'!$EA:$EA,"Magistrat SIEGE NS")- SUMIFS( INDEX( 'ETPT Format DDG'!$A:$EF,,MATCH("9. TOTAL JAP",'ETPT Format DDG'!2:2,0)),'ETPT Format DDG'!$EA:$EA,"Magistrat SIEGE NS")- SUMIFS( INDEX( 'ETPT Format DDG'!$A:$EF,,MATCH("6.2. ACTIVITÉ PÉNALE",'ETPT Format DDG'!2:2,0)),'ETPT Format DDG'!$EA:$EA,"Magistrat SIEGE NS")- SUMIFS( INDEX( 'ETPT Format DDG'!$A:$EF,,MATCH("10. TOTAL JLD PÉNAL",'ETPT Format DDG'!2:2,0)),'ETPT Format DDG'!$EA:$EA,"Magistrat SIEGE NS")- SUM(AM6:AW6) -> #N/A | AZ6: =SUM(AM6:AY6) -> #N/A | BJ6: =SUM(BA6:BI6) -> 0
A7: ETPT_TJ | D7: =$D$5 | E7: 166-04-NC | F7: Action 4 - Conseil supérieur de la magistrature | H7: =SUM(G7) -> 0 | W7: =SUM(I7:V7) -> 0 | AB7: =SUM(X7:AA7) -> 0 | AD7: =SUMIFS( INDEX( 'ETPT Format DDG'!$A:$EF,,MATCH("11.5. CSM",'ETPT Format DDG'!2:2,0)),'ETPT Format DDG'!$C:$C,$D$5,'ETPT Format DDG'!H:H,"JCP")+ SUMIFS( INDEX( 'ETPT Format DDG'!$A:$EF,,MATCH("11.5. CSM",'ETPT Format DDG'!2:2,0)),'ETPT Format DDG'!$C:$C,$D$5,'ETPT Format DDG'!H:H,"VPCP")+ SUMIFS( INDEX( 'ETPT Format DDG'!$A:$EF,,MATCH("11.5. CSM",'ETPT Format DDG'!2:2,0)),'ETPT Format DDG'!$C:$C,$D$5,'ETPT Format DDG'!H:H,"1VPCP") -> #N/A | AE7: =SUMIFS( INDEX( 'ETPT Format DDG'!$A:$EF,,MATCH("11.5. CSM",'ETPT Format DDG'!2:2,0)),'ETPT Format DDG'!$C:$C,$D$5,'ETPT Format DDG'!H:H,"JI")+ SUMIFS( INDEX( 'ETPT Format DDG'!$A:$EF,,MATCH("11.5. CSM",'ETPT Format DDG'!2:2,0)),'ETPT Format DDG'!$C:$C,$D$5,'ETPT Format DDG'!H:H,"VPI")+ SUMIFS( INDEX( 'ETPT Format DDG'!$A:$EF,,MATCH("11.5. CSM",'ETPT Format DDG'!2:2,0)),'ETPT Format DDG'!$C:$C,$D$5,'ETPT Format DDG'!H:H,"1VPI") -> #N/A | AI7: =SUMIFS( INDEX( 'ETPT Format DDG'!$A:$EF,,MATCH("11.5. CSM",'ETPT Format DDG'!2:2,0)),'ETPT Format DDG'!$C:$C,$D$5,'ETPT Format DDG'!H:H,"JAP")+ SUMIFS( INDEX( 'ETPT Format DDG'!$A:$EF,,MATCH("11.5. CSM",'ETPT Format DDG'!2:2,0)),'ETPT Format DDG'!$C:$C,$D$5,'ETPT Format DDG'!H:H,"VPAP")+ SUMIFS( INDEX( 'ETPT Format DDG'!$A:$EF,,MATCH("11.5. CSM",'ETPT Format DDG'!2:2,0)),'ETPT Format DDG'!$C:$C,$D$5,'ETPT Format DDG'!H:H,"1VPAP") -> #N/A | AJ7: =SUMIFS( INDEX( 'ETPT Format DDG'!$A:$EF,,MATCH("11.5. CSM",'ETPT Format DDG'!2:2,0)),'ETPT Format DDG'!$C:$C,$D$5,'ETPT Format DDG'!H:H,"JE")+ SUMIFS( INDEX( 'ETPT Format DDG'!$A:$EF,,MATCH("11.5. CSM",'ETPT Format DDG'!2:2,0)),'ETPT Format DDG'!$C:$C,$D$5,'ETPT Format DDG'!H:H,"VPE")+ SUMIFS( INDEX( 'ETPT Format DDG'!$A:$EF,,MATCH("11.5. CSM",'ETPT Format DDG'!2:2,0)),'ETPT Format DDG'!$C:$C,$D$5,'ETPT Format DDG'!H:H,"1VPE") -> #N/A | AK7: =SUMIFS( INDEX( 'ETPT Format DDG'!$A:$EF,,MATCH("11.5. CSM",'ETPT Format DDG'!2:2,0)),'ETPT Format DDG'!$C:$C,$D$5,'ETPT Format DDG'!H:H,"VPLD")+ SUMIFS( INDEX( 'ETPT Format DDG'!$A:$EF,,MATCH("11.5. CSM",'ETPT Format DDG'!2:2,0)),'ETPT Format DDG'!$C:$C,$D$5,'ETPT Format DDG'!H:H,"1VPLD") -> #N/A | AL7: =SUM(AC7:AK7) -> #N/A | AY7: =SUMIFS( INDEX( 'ETPT Format DDG'!$A:$EF,,MATCH("11.5. CSM",'ETPT Format DDG'!2:2,0)),'ETPT Format DDG'!$C:$C,$D$5,'ETPT Format DDG'!$EA:$EA,"Magistrat SIEGE NS") -> #N/A | AZ7: =SUM(AM7:AY7) -> #N/A | BJ7: =SUM(BA7:BI7) -> 0
A8: ETPT_TJ | D8: =$D$5 | E8: 166-06-99 | F8: Action 6 - Accueil du justiciable (inclus SAUJ) | G8: =SUMIFS( INDEX( 'ETPT Format DDG'!$A:$EF,,MATCH("11.51. ACCUEIL DU JUSTICIABLE (DONT SAUJ)",'ETPT Format DDG'!2:2,0)),'ETPT Format DDG'!$C:$C,$D$5,'ETPT Format DDG'!$EA:$EA,"Fonctionnaire CTECH") -> #N/A | H8: =SUM(G8) -> #N/A | V8: =SUMIFS( INDEX( 'ETPT Format DDG'!$A:$EF,,MATCH("11.51. ACCUEIL DU JUSTICIABLE (DONT SAUJ)",'ETPT Format DDG'!2:2,0)),'ETPT Format DDG'!$C:$C,$D$5,'ETPT Format DDG'!$EA:$EA,"Fonctionnaire A-B-CBUR") -> #N/A | W8: =SUM(I8:V8) -> #N/A | X8: =SUMIFS( INDEX( 'ETPT Format DDG'!$A:$EF,,MATCH("11.51. ACCUEIL DU JUSTICIABLE (DONT SAUJ)",'ETPT Format DDG'!2:2,0)),'ETPT Format DDG'!$C:$C,$D$5,'ETPT Format DDG'!$EA:$EA,"CONT A JP Autour du Juge") -> #N/A | Y8: =SUMIFS( INDEX( 'ETPT Format DDG'!$A:$EF,,MATCH("11.51. ACCUEIL DU JUSTICIABLE (DONT SAUJ)",'ETPT Format DDG'!2:2,0)),'ETPT Format DDG'!$C:$C,$D$5,'ETPT Format DDG'!$EA:$EA,"JURISTE AS Parquet") -> #N/A | Z8: =SUMIFS( INDEX( 'ETPT Format DDG'!$A:$EF,,MATCH("11.51. ACCUEIL DU JUSTICIABLE (DONT SAUJ)",'ETPT Format DDG'!2:2,0)),'ETPT Format DDG'!$C:$C,$D$5,'ETPT Format DDG'!$EA:$EA,"JURISTE AS Pôle social") -> #N/A | AA8: =SUMIFS( INDEX( 'ETPT Format DDG'!$A:$EF,,MATCH("11.51. ACCUEIL DU JUSTICIABLE (DONT SAUJ)",'ETPT Format DDG'!2:2,0)),'ETPT Format DDG'!$C:$C,$D$5,'ETPT Format DDG'!$EA:$EA,"JURISTE AS siège Autres") -> #N/A | AB8: =SUM(X8:AA8) -> #N/A | AL8: =SUM(AC8:AK8) -> 0 | AZ8: =SUM(AM8:AY8) -> 0 | BJ8: =SUM(BA8:BI8) -> 0
A9: ETPT_TJ | D9: =$D$5 | E9: 166-06-NC | F9: Action 6 - Soutien (Hors accueil du justiciable) | G9: =SUMIFS( INDEX( 'ETPT Format DDG'!$A:$EF,,MATCH("11.1. SOUTIEN (HORS FORMATIONS SUIVIES)",'ETPT Format DDG'!2:2,0)),'ETPT Format DDG'!$C:$C,$D$5,'ETPT Format DDG'!$EA:$EA,"Fonctionnaire CTECH")+ SUMIFS( INDEX( 'ETPT Format DDG'!$A:$EF,,MATCH("11.2. FORMATIONS SUIVIES",'ETPT Format DDG'!2:2,0)),'ETPT Format DDG'!$C:$C,$D$5,'ETPT Format DDG'!$EA:$EA,"Fonctionnaire CTECH")+ SUMIFS( INDEX( 'ETPT Format DDG'!$A:$EF,,MATCH("11.6. AUTRES ACTIVITÉS NON JURIDICTIONNELLES",'ETPT Format DDG'!2:2,0)),'ETPT Format DDG'!$C:$C,$D$5,'ETPT Format DDG'!$EA:$EA,"Fonctionnaire CTECH") -> #N/A | H9: =SUM(G9) -> #N/A | V9: =SUMIFS( INDEX( 'ETPT Format DDG'!$A:$EF,,MATCH("11.1. SOUTIEN (HORS FORMATIONS SUIVIES)",'ETPT Format DDG'!2:2,0)),'ETPT Format DDG'!$C:$C,$D$5,'ETPT Format DDG'!$EA:$EA,"Fonctionnaire A-B-CBUR")+ SUMIFS( INDEX( 'ETPT Format DDG'!$A:$EF,,MATCH("11.2. FORMATIONS SUIVIES",'ETPT Format DDG'!2:2,0)),'ETPT Format DDG'!$C:$C,$D$5,'ETPT Format DDG'!$EA:$EA,"Fonctionnaire A-B-CBUR")+ SUMIFS( INDEX( 'ETPT Format DDG'!$A:$EF,,MATCH("11.6. AUTRES ACTIVITÉS NON JURIDICTIONNELLES",'ETPT Format DDG'!2:2,0)),'ETPT Format DDG'!$C:$C,$D$5,'ETPT Format DDG'!$EA:$EA,"Fonctionnaire A-B-CBUR")+ SUMIFS( INDEX( 'ETPT Format DDG'!$A:$EF,,MATCH("Temps ventilé sur la période (y.c. indisponibilité)",'ETPT Format DDG'!2:2,0)),'ETPT Format DDG'!$C:$C,$D$5,'ETPT Format DDG'!$EA:$EA,"CONT A JP Greffe") -> #N/A | W9: =SUM(I9:V9) -> #N/A | X9: =SUMIFS( INDEX( 'ETPT Format DDG'!$A:$EF,,MATCH("11.1. SOUTIEN (HORS FORMATIONS SUIVIES)",'ETPT Format DDG'!2:2,0)),'ETPT Format DDG'!$C:$C,$D$5,'ETPT Format DDG'!$EA:$EA,"CONT A JP Autour du Juge")+ SUMIFS( INDEX( 'ETPT Format DDG'!$A:$EF,,MATCH("11.2. FORMATIONS SUIVIES",'ETPT Format DDG'!2:2,0)),'ETPT Format DDG'!$C:$C,$D$5,'ETPT Format DDG'!$EA:$EA,"CONT A JP Autour du Juge")+ SUMIFS( INDEX( 'ETPT Format DDG'!$A:$EF,,MATCH("11.6. AUTRES ACTIVITÉS NON JURIDICTIONNELLES",'ETPT Format DDG'!2:2,0)),'ETPT Format DDG'!$C:$C,$D$5,'ETPT Format DDG'!$EA:$EA,"CONT A JP Autour du Juge") -> #N/A | Y9: =SUMIFS( INDEX( 'ETPT Format DDG'!$A:$EF,,MATCH("11.1. SOUTIEN (HORS FORMATIONS SUIVIES)",'ETPT Format DDG'!2:2,0)),'ETPT Format DDG'!$C:$C,$D$5,'ETPT Format DDG'!$EA:$EA,"JURISTE AS Parquet")+ SUMIFS( INDEX( 'ETPT Format DDG'!$A:$EF,,MATCH("11.2. FORMATIONS SUIVIES",'ETPT Format DDG'!2:2,0)),'ETPT Format DDG'!$C:$C,$D$5,'ETPT Format DDG'!$EA:$EA,"JURISTE AS Parquet")+ SUMIFS( INDEX( 'ETPT Format DDG'!$A:$EF,,MATCH("11.6. AUTRES ACTIVITÉS NON JURIDICTIONNELLES",'ETPT Format DDG'!2:2,0)),'ETPT Format DDG'!$C:$C,$D$5,'ETPT Format DDG'!$EA:$EA,"JURISTE AS Parquet") -> #N/A | Z9: =SUMIFS( INDEX( 'ETPT Format DDG'!$A:$EF,,MATCH("11.1. SOUTIEN (HORS FORMATIONS SUIVIES)",'ETPT Format DDG'!2:2,0)),'ETPT Format DDG'!$C:$C,$D$5,'ETPT Format DDG'!$EA:$EA,"JURISTE AS Pôle social")+ SUMIFS( INDEX( 'ETPT Format DDG'!$A:$EF,,MATCH("11.2. FORMATIONS SUIVIES",'ETPT Format DDG'!2:2,0)),'ETPT Format DDG'!$C:$C,$D$5,'ETPT Format DDG'!$EA:$EA,"JURISTE AS Pôle social")+ SUMIFS( INDEX( 'ETPT Format DDG'!$A:$EF,,MATCH("11.6. AUTRES ACTIVITÉS NON JURIDICTIONNELLES",'ETPT Format DDG'!2:2,0)),'ETPT Format DDG'!$C:$C,$D$5,'ETPT Format DDG'!$EA:$EA,"JURISTE AS Pôle social") -> #N/A | AA9: =SUMIFS( INDEX( 'ETPT Format DDG'!$A:$EF,,MATCH("11.1. SOUTIEN (HORS FORMATIONS SUIVIES)",'ETPT Format DDG'!2:2,0)),'ETPT Format DDG'!$C:$C,$D$5,'ETPT Format DDG'!$EA:$EA,"JURISTE AS siège Autres")+ SUMIFS( INDEX( 'ETPT Format DDG'!$A:$EF,,MATCH("11.2. FORMATIONS SUIVIES",'ETPT Format DDG'!2:2,0)),'ETPT Format DDG'!$C:$C,$D$5,'ETPT Format DDG'!$EA:$EA,"JURISTE AS siège Autres")+ SUMIFS( INDEX( 'ETPT Format DDG'!$A:$EF,,MATCH("11.6. AUTRES ACTIVITÉS NON JURIDICTIONNELLES",'ETPT Format DDG'!2:2,0)),'ETPT Format DDG'!$C:$C,$D$5,'ETPT Format DDG'!$EA:$EA,"JURISTE AS siège Autres") -> #N/A | AB9: =SUM(X9:AA9) -> #N/A | AD9: =SUMIFS( INDEX( 'ETPT Format DDG'!$A:$EF,,MATCH("11.1. SOUTIEN (HORS FORMATIONS SUIVIES)",'ETPT Format DDG'!2:2,0)),'ETPT Format DDG'!$C:$C,$D$5,'ETPT Format DDG'!$H:$H,"JCP")+ SUMIFS( INDEX( 'ETPT Format DDG'!$A:$EF,,MATCH("11.1. SOUTIEN (HORS FORMATIONS SUIVIES)",'ETPT Format DDG'!2:2,0)),'ETPT Format DDG'!$C:$C,$D$5,'ETPT Format DDG'!$H:$H,"VPCP")+ SUMIFS( INDEX( 'ETPT Format DDG'!$A:$EF,,MATCH("11.1. SOUTIEN (HORS FORMATIONS SUIVIES)",'ETPT Format DDG'!2:2,0)),'ETPT Format DDG'!$C:$C,$D$5,'ETPT Format DDG'!$H:$H,"1VPCP")+ SUMIFS( INDEX( 'ETPT Format DDG'!$A:$EF,,MATCH("11.2. FORMATIONS SUIVIES",'ETPT Format DDG'!2:2,0)),'ETPT Format DDG'!$C:$C,$D$5,'ETPT Format DDG'!$H:$H,"JCP")+ SUMIFS( INDEX( 'ETPT Format DDG'!$A:$EF,,MATCH("11.2. FORMATIONS SUIVIES",'ETPT Format DDG'!2:2,0)),'ETPT Format DDG'!$C:$C,$D$5,'ETPT Format DDG'!$H:$H,"VPCP")+ SUMIFS( INDEX( 'ETPT Format DDG'!$A:$EF,,MATCH("11.2. FORMATIONS SUIVIES",'ETPT Format DDG'!2:2,0)),'ETPT Format DDG'!$C:$C,$D$5,'ETPT Format DDG'!$H:$H,"1VPCP")+ SUMIFS( INDEX( 'ETPT Format DDG'!$A:$EF,,MATCH("11.6. AUTRES ACTIVITÉS NON JURIDICTIONNELLES",'ETPT Format DDG'!2:2,0)),'ETPT Format DDG'!$C:$C,$D$5,'ETPT Format DDG'!$H:$H,"JCP")+ SUMIFS( INDEX( 'ETPT Format DDG'!$A:$EF,,MATCH("11.6. AUTRES ACTIVITÉS NON JURIDICTIONNELLES",'ETPT Format DDG'!2:2,0)),'ETPT Format DDG'!$C:$C,$D$5,'ETPT Format DDG'!$H:$H,"VPCP")+ SUMIFS( INDEX( 'ETPT Format DDG'!$A:$EF,,MATCH("11.6. AUTRES ACTIVITÉS NON JURIDICTIONNELLES",'ETPT Format DDG'!2:2,0)),'ETPT Format DDG'!$C:$C,$D$5,'ETPT Format DDG'!$H:$H,"1VPCP") -> #N/A | AE9: =SUMIFS( INDEX( 'ETPT Format DDG'!$A:$EF,,MATCH("11.1. SOUTIEN (HORS FORMATIONS SUIVIES)",'ETPT Format DDG'!2:2,0)),'ETPT Format DDG'!$C:$C,$D$5,'ETPT Format DDG'!$H:$H,"JI")+ SUMIFS( INDEX( 'ETPT Format DDG'!$A:$EF,,MATCH("11.1. SOUTIEN (HORS FORMATIONS SUIVIES)",'ETPT Format DDG'!2:2,0)),'ETPT Format DDG'!$C:$C,$D$5,'ETPT Format DDG'!$H:$H,"VPI")+ SUMIFS( INDEX( 'ETPT Format DDG'!$A:$EF,,MATCH("11.1. SOUTIEN (HORS FORMATIONS SUIVIES)",'ETPT Format DDG'!2:2,0)),'ETPT Format DDG'!$C:$C,$D$5,'ETPT Format DDG'!$H:$H,"1VPI")+ SUMIFS( INDEX( 'ETPT Format DDG'!$A:$EF,,MATCH("11.2. FORMATIONS SUIVIES",'ETPT Format DDG'!2:2,0)),'ETPT Format DDG'!$C:$C,$D$5,'ETPT Format DDG'!$H:$H,"JI")+ SUMIFS( INDEX( 'ETPT Format DDG'!$A:$EF,,MATCH("11.2. FORMATIONS SUIVIES",'ETPT Format DDG'!2:2,0)),'ETPT Format DDG'!$C:$C,$D$5,'ETPT Format DDG'!$H:$H,"VPI")+ SUMIFS( INDEX( 'ETPT Format DDG'!$A:$EF,,MATCH("11.2. FORMATIONS SUIVIES",'ETPT Format DDG'!2:2,0)),'ETPT Format DDG'!$C:$C,$D$5,'ETPT Format DDG'!$H:$H,"1VPI")+ SUMIFS( INDEX( 'ETPT Format DDG'!$A:$EF,,MATCH("11.6. AUTRES ACTIVITÉS NON JURIDICTIONNELLES",'ETPT Format DDG'!2:2,0)),'ETPT Format DDG'!$C:$C,$D$5,'ETPT Format DDG'!$H:$H,"JI")+ SUMIFS( INDEX( 'ETPT Format DDG'!$A:$EF,,MATCH("11.6. AUTRES ACTIVITÉS NON JURIDICTIONNELLES",'ETPT Format DDG'!2:2,0)),'ETPT Format DDG'!$C:$C,$D$5,'ETPT Format DDG'!$H:$H,"VPI")+ SUMIFS( INDEX( 'ETPT Format DDG'!$A:$EF,,MATCH("11.6. AUTRES ACTIVITÉS NON JURIDICTIONNELLES",'ETPT Format DDG'!2:2,0)),'ETPT Format DDG'!$C:$C,$D$5,'ETPT Format DDG'!$H:$H,"1VPI") -> #N/A | AI9: =SUMIFS( INDEX( 'ETPT Format DDG'!$A:$EF,,MATCH("11.1. SOUTIEN (HORS FORMATIONS SUIVIES)",'ETPT Format DDG'!2:2,0)),'ETPT Format DDG'!$C:$C,$D$5,'ETPT Format DDG'!H:H,"JAP")+ SUMIFS( INDEX( 'ETPT Format DDG'!$A:$EF,,MATCH("11.1. SOUTIEN (HORS FORMATIONS SUIVIES)",'ETPT Format DDG'!2:2,0)),'ETPT Format DDG'!$C:$C,$D$5,'ETPT Format DDG'!H:H,"VPAP")+ SUMIFS( INDEX( 'ETPT Format DDG'!$A:$EF,,MATCH("11.1. SOUTIEN (HORS FORMATIONS SUIVIES)",'ETPT Format DDG'!2:2,0)),'ETPT Format DDG'!$C:$C,$D$5,'ETPT Format DDG'!H:H,"1VPAP")+ SUMIFS( INDEX( 'ETPT Format DDG'!$A:$EF,,MATCH("11.2. FORMATIONS SUIVIES",'ETPT Format DDG'!2:2,0)),'ETPT Format DDG'!$C:$C,$D$5,'ETPT Format DDG'!H:H,"JAP")+ SUMIFS( INDEX( 'ETPT Format DDG'!$A:$EF,,MATCH("11.2. FORMATIONS SUIVIES",'ETPT Format DDG'!2:2,0)),'ETPT Format DDG'!$C:$C,$D$5,'ETPT Format DDG'!H:H,"VPAP")+ SUMIFS( INDEX( 'ETPT Format DDG'!$A:$EF,,MATCH("11.2. FORMATIONS SUIVIES",'ETPT Format DDG'!2:2,0)),'ETPT Format DDG'!$C:$C,$D$5,'ETPT Format DDG'!H:H,"1VPAP")+ SUMIFS( INDEX( 'ETPT Format DDG'!$A:$EF,,MATCH("11.6. AUTRES ACTIVITÉS NON JURIDICTIONNELLES",'ETPT Format DDG'!2:2,0)),'ETPT Format DDG'!$C:$C,$D$5,'ETPT Format DDG'!H:H,"JAP")+ SUMIFS( INDEX( 'ETPT Format DDG'!$A:$EF,,MATCH("11.6. AUTRES ACTIVITÉS NON JURIDICTIONNELLES",'ETPT Format DDG'!2:2,0)),'ETPT Format DDG'!$C:$C,$D$5,'ETPT Format DDG'!H:H,"VPAP")+ SUMIFS( INDEX( 'ETPT Format DDG'!$A:$EF,,MATCH("11.6. AUTRES ACTIVITÉS NON JURIDICTIONNELLES",'ETPT Format DDG'!2:2,0)),'ETPT Format DDG'!$C:$C,$D$5,'ETPT Format DDG'!H:H,"1VPAP") -> #N/A | AJ9: =SUMIFS( INDEX( 'ETPT Format DDG'!$A:$EF,,MATCH("11.1. SOUTIEN (HORS FORMATIONS SUIVIES)",'ETPT Format DDG'!2:2,0)),'ETPT Format DDG'!$C:$C,$D$5,'ETPT Format DDG'!H:H,"JE")+ SUMIFS( INDEX( 'ETPT Format DDG'!$A:$EF,,MATCH("11.1. SOUTIEN (HORS FORMATIONS SUIVIES)",'ETPT Format DDG'!2:2,0)),'ETPT Format DDG'!$C:$C,$D$5,'ETPT Format DDG'!H:H,"VPE")+ SUMIFS( INDEX( 'ETPT Format DDG'!$A:$EF,,MATCH("11.1. SOUTIEN (HORS FORMATIONS SUIVIES)",'ETPT Format DDG'!2:2,0)),'ETPT Format DDG'!$C:$C,$D$5,'ETPT Format DDG'!H:H,"1VPE")+ SUMIFS( INDEX( 'ETPT Format DDG'!$A:$EF,,MATCH("11.2. FORMATIONS SUIVIES",'ETPT Format DDG'!2:2,0)),'ETPT Format DDG'!$C:$C,$D$5,'ETPT Format DDG'!H:H,"JE")+ SUMIFS( INDEX( 'ETPT Format DDG'!$A:$EF,,MATCH("11.2. FORMATIONS SUIVIES",'ETPT Format DDG'!2:2,0)),'ETPT Format DDG'!$C:$C,$D$5,'ETPT Format DDG'!H:H,"VPE")+ SUMIFS( INDEX( 'ETPT Format DDG'!$A:$EF,,MATCH("11.2. FORMATIONS SUIVIES",'ETPT Format DDG'!2:2,0)),'ETPT Format DDG'!$C:$C,$D$5,'ETPT Format DDG'!H:H,"1VPE")+ SUMIFS( INDEX( 'ETPT Format DDG'!$A:$EF,,MATCH("11.6. AUTRES ACTIVITÉS NON JURIDICTIONNELLES",'ETPT Format DDG'!2:2,0)),'ETPT Format DDG'!$C:$C,$D$5,'ETPT Format DDG'!H:H,"JE")+ SUMIFS( INDEX( 'ETPT Format DDG'!$A:$EF,,MATCH("11.6. AUTRES ACTIVITÉS NON JURIDICTIONNELLES",'ETPT Format DDG'!2:2,0)),'ETPT Format DDG'!$C:$C,$D$5,'ETPT Format DDG'!H:H,"VPE")+ SUMIFS( INDEX( 'ETPT Format DDG'!$A:$EF,,MATCH("11.6. AUTRES ACTIVITÉS NON JURIDICTIONNELLES",'ETPT Format DDG'!2:2,0)),'ETPT Format DDG'!$C:$C,$D$5,'ETPT Format DDG'!H:H,"1VPE") -> #N/A | AK9: =SUMIFS( INDEX( 'ETPT Format DDG'!$A:$EF,,MATCH("11.1. SOUTIEN (HORS FORMATIONS SUIVIES)",'ETPT Format DDG'!2:2,0)),'ETPT Format DDG'!$C:$C,$D$5,'ETPT Format DDG'!H:H,"VPLD")+ SUMIFS( INDEX( 'ETPT Format DDG'!$A:$EF,,MATCH("11.1. SOUTIEN (HORS FORMATIONS SUIVIES)",'ETPT Format DDG'!2:2,0)),'ETPT Format DDG'!$C:$C,$D$5,'ETPT Format DDG'!H:H,"1VPLD")+ SUMIFS( INDEX( 'ETPT Format DDG'!$A:$EF,,MATCH("11.2. FORMATIONS SUIVIES",'ETPT Format DDG'!2:2,0)),'ETPT Format DDG'!$C:$C,$D$5,'ETPT Format DDG'!H:H,"VPLD")+ SUMIFS( INDEX( 'ETPT Format DDG'!$A:$EF,,MATCH("11.2. FORMATIONS SUIVIES",'ETPT Format DDG'!2:2,0)),'ETPT Format DDG'!$C:$C,$D$5,'ETPT Format DDG'!H:H,"1VPLD")+ SUMIFS( INDEX( 'ETPT Format DDG'!$A:$EF,,MATCH("11.6. AUTRES ACTIVITÉS NON JURIDICTIONNELLES",'ETPT Format DDG'!2:2,0)),'ETPT Format DDG'!$C:$C,$D$5,'ETPT Format DDG'!H:H,"VPLD")+ SUMIFS( INDEX( 'ETPT Format DDG'!$A:$EF,,MATCH("11.6. AUTRES ACTIVITÉS NON JURIDICTIONNELLES",'ETPT Format DDG'!2:2,0)),'ETPT Format DDG'!$C:$C,$D$5,'ETPT Format DDG'!H:H,"1VPLD") -> #N/A | AL9: =SUM(AC9:AK9) -> #N/A | AY9: =SUMIFS( INDEX( 'ETPT Format DDG'!$A:$EF,,MATCH("11.1. SOUTIEN (HORS FORMATIONS SUIVIES)",'ETPT Format DDG'!2:2,0)),'ETPT Format DDG'!$C:$C,$D$5,'ETPT Format DDG'!$EA:$EA,"Magistrat SIEGE NS")+ SUMIFS( INDEX( 'ETPT Format DDG'!$A:$EF,,MATCH("11.2. FORMATIONS SUIVIES",'ETPT Format DDG'!2:2,0)),'ETPT Format DDG'!$C:$C,$D$5,'ETPT Format DDG'!$EA:$EA,"Magistrat SIEGE NS")+ SUMIFS( INDEX( 'ETPT Format DDG'!$A:$EF,,MATCH("11.6. AUTRES ACTIVITÉS NON JURIDICTIONNELLES",'ETPT Format DDG'!2:2,0)),'ETPT Format DDG'!$C:$C,$D$5,'ETPT Format DDG'!$EA:$EA,"Magistrat SIEGE NS") -> #N/A | AZ9: =SUM(AM9:AY9) -> #N/A | BJ9: =SUM(BA9:BI9) -> 0
