Workbook
Name TJCPH: Juridictions!$J$1:$J$10

Sheet ACCUEIL
C1: Bienvenue dans l'extraction de vos données d'effectifs ! | H1: #! END_ROW
C2: Ce fichier Excel a été extrait automatiquement de votre application A-JUST. Retrouvez ci-dessous quelques indications pour y naviguer en toute fluidité. | H2: #! END_ROW
H3: #! END_ROW
B4: Nom de l'onglet | C4: Description rapide | D4: Usage | E4: Pour une présentation complète | H4: #! END_ROW
B5: ETPT A-JUST | C5: Retrouvez le détail des ventilations individuelles de chaque agent, agrégées sur la période pour laquelle vous avez extrait les données, à l'identique de ce que vous avez renseigné dans A-JUST. | D5: Tout au long de l'année, consultez le détail des affectations de chaque agent, calculées en ETPT, pour la période choisie. | E5: #! HYPERLINK firstLink.label firstLink.url | H5: #! END_ROW
B6: ETPT Format DDG | C6: Vous y trouverez les données individuelles, retraitées conformément aux règles de calcul de la Chancellerie, en procédant à la réintégration de certaines indisponibilités considérées comme de l'absentéisme, ne déduisant pas d'ETPT. | D6: Afin de préparer la collecte de vos ETPT dans les matrices de la DSJ certaines précisions doivent être apportées dans cet onglet. | E6: #! HYPERLINK secondLink.label secondLink.url | H6: #! END_ROW
B7: Synthèse ETPT | C7: Pour chaque juridiction de l'arrondissement judiciaire, cette synthèse présente les ETPT affectés, par catégorie d'agent, à chaque contentieux ou sous-contentieux, l'absentéisme étant réintégré comme dans l'onglet "ETPT Format DDG". | D7: N'hésitez pas à la consulter toute l'année, pour les périodes de votre choix. | E7: #! HYPERLINK firstLink.label firstLink.url | H7: #! END_ROW
B8: ETPT_TJ_DDG | C8: Les tableaux de la Chancellerie, préremplis grâce aux informations saisies dans A-JUST et aux précisions apportées dans l'onglet ETPT Format DDG. Pour les Tribunaux de proximité et CPH, sélectionnez la juridiction dans la cellule D5 et vos tableaux seront prêts ! | D8: Ces données sont prérenseignées dans les tableaux de collecte des ETPT de la Chancellerie mais restent soumises à votre contrôle et éventuels ajustements avant transmission. | E8: #! HYPERLINK thirdLink.label thirdLink.url | H8: #! END_ROW
B9: ETPT_TPRX-DDG | H9: #! END_ROW
B10: ETPT_CPH_DDG | H10: #! END_ROW
B11: ETPT_ATTACHES_JUSTICE_DDG | H11: #! END_ROW
H12: #! END_ROW
C13: Ce fichier, permettant de remplir automatiquement les tableaux de collecte d'ETPT de la Chancellerie à partir des données A-JUST, résulte de la collaboration de l'équipe de la start-up d'Etat A-JUST avec Mme Nathalie DE JONG, statisticienne du SAIR de la Cour d'Appel de LYON. Qu'elle soit ici vivement remerciée, ainsi que sa hiérarchie qui l'a autorisée à consacrer un temps aussi précieux qu'irremplaçable à écrire les formules de calcul permettant d'automatiser l'alimentation des tableaux DDG et faire ainsi gagner à nos utilisateurs un temps considérable chaque année. | H13: #! END_ROW
H14: #! END_ROW
A15: Pour toute question, n'hésitez pas à contacter l'équipe A-JUST : support-utilisateurs@a-just.fr | H15: #! END_ROW
H16: #! FINISH

Sheet ETPT A-JUST
A1: Extracteur de données d'effectifs | G1: #! DUMP_COLS subtitles | H1: #! END_ROW
A2: #! DUMP_COLS days | B2: #! FOR_EACH w stats
A3: #! DUMP_COLS w.actions | B3: #! CONTINUE w
A4: #! DUMP_COLS w.actions | B4: #! END_LOOP w
B5: #! FINISH

Sheet ETPT Format DDG
D1: Extracteur de données d'effectifs - Format DDG (avec réintégration de l'absentéisme) Les lignes en rouge invitent à des vérifications dans les colonnes R, S et T. Veillez à ne pas supprimer de ligne dans le tableau. | R1: #! DUMP_COLS subtitles1 | S1: #! END_ROW
A2: #! DUMP_COLS days1 | B2: #! FOR_EACH x stats1
A3: #! DUMP_COLS x.actions | B3: #! END_LOOP x
B4: #! FINISH

Sheet Synthèse ETPT
A1: Synthèse ETPT | C1: Agrégats DDG | W1: #! END_ROW
A2: Selectionner une juridiction | B2: Code | C2: #! END_ROW
A3: #` ${arrondissement} | B3: =VLOOKUP(A3,#REF!,2,FALSE) -> #REF! | C3: #! END_ROW | D3: Les lignes à fond rouge invitent à des vérifications lors de l'établissement des tableaux de collecte pour les DDG. Pour plus d'informations sur les agents concernés, se référer à l'onglet ETPT Format DDG.
G4: SIEGE | N4: GREFFE | U4: EQUIPE AUTOUR DU MAGISTRAT | X4: #! END_ROW
G5: Magistrats hors placés | H5: %age de l'ETPT | I5: Magistrats placés additionnels | J5: Magistrats placés de substitution | K5: Contractuels et vacataires | L5: TOTAL SIEGE | M5: %age de l'ETPT | N5: Fonctionnaires hors placés | O5: %age de l'ETPT | P5: Fonctionnaires placés additionnels | Q5: Fonctionnaires placés de substitution | R5: Contractuels et vacataires | S5: TOTAL GREFFE | T5: %age de l'ETPT | U5: Contractuels et vacataires | V5: %age de l'ETPT | W5: #! FOR_EACH y agregat
C6: ## y.global | D6: ## y.global1 | E6: ## y.sub | F6: ## y.sub1 | G6: =SUMIFS( INDEX('ETPT Format DDG'!$A:$ZZ,,IFERROR(MATCH(E6,'ETPT Format DDG'!$2:$2,0),MATCH(C6,'ETPT Format DDG'!$2:$2,0))), INDEX( 'ETPT Format DDG'!$A:$ZZ,,MATCH("Fonction agrégat",'ETPT Format DDG'!2:2,0)),"M-TIT", INDEX( 'ETPT Format DDG'!$A:$ZZ,,MATCH("Juridiction",'ETPT Format DDG'!2:2,0)),$A$3) -> #N/A | H6: =IF(AND(OR(LEFT(C6,3)="12.",LEFT(E6,3)="12.",LEFT(E6,5)="CET >",IFERROR(G6/$G$6,"")=0),NOT(AND(LEFT(E6,4)="12.8",IFERROR(G6/$G$6,"")<>0)),NOT(AND(LEFT(E6,5)="12.31",IFERROR(G6/$G$6,"")<>0)),NOT(AND(LEFT(E6,5)="12.32",IFERROR(G6/$G$6,"")<>0))),"", IFERROR(G6/$G$6,"")) | I6: =SUMIFS( INDEX('ETPT Format DDG'!$A:$ZZ,,IFERROR(MATCH(E6,'ETPT Format DDG'!$2:$2,0),MATCH(C6,'ETPT Format DDG'!$2:$2,0))), INDEX( 'ETPT Format DDG'!$A:$ZZ,,MATCH("Fonction agrégat",'ETPT Format DDG'!2:2,0)),"M-PLAC-ADD", INDEX( 'ETPT Format DDG'!$A:$ZZ,,MATCH("Juridiction",'ETPT Format DDG'!2:2,0)),$A$3) -> #N/A | J6: =SUMIFS( INDEX('ETPT Format DDG'!$A:$ZZ,,IFERROR(MATCH(E6,'ETPT Format DDG'!$2:$2,0),MATCH(C6,'ETPT Format DDG'!$2:$2,0))), INDEX( 'ETPT Format DDG'!$A:$ZZ,,MATCH("Fonction agrégat",'ETPT Format DDG'!2:2,0)),"M-PLAC-SUB", INDEX( 'ETPT Format DDG'!$A:$ZZ,,MATCH("Juridiction",'ETPT Format DDG'!2:2,0)),$A$3) -> #N/A | K6: =SUMIFS( INDEX('ETPT Format DDG'!$A:$ZZ,,IFERROR(MATCH(E6,'ETPT Format DDG'!$2:$2,0),MATCH(C6,'ETPT Format DDG'!$2:$2,0))), INDEX( 'ETPT Format DDG'!$A:$ZZ,,MATCH("Fonction agrégat",'ETPT Format DDG'!2:2,0)),"M-CONT", INDEX( 'ETPT Format DDG'!$A:$ZZ,,MATCH("Juridiction",'ETPT Format DDG'!2:2,0)),$A$3, INDEX( 'ETPT Format DDG'!$A:$ZZ,,MATCH("Catégorie",'ETPT Format DDG'!2:2,0)),"Magistrat") -> #N/A | L6: =SUMIFS( INDEX('ETPT Format DDG'!$A:$ZZ,,IFERROR(MATCH(E6,'ETPT Format DDG'!$2:$2,0),MATCH(C6,'ETPT Format DDG'!$2:$2,0))), INDEX( 'ETPT Format DDG'!$A:$ZZ,,MATCH("Juridiction",'ETPT Format DDG'!2:2,0)),$A$3, INDEX( 'ETPT Format DDG'!$A:$ZZ,,MATCH("Catégorie",'ETPT Format DDG'!2:2,0)),"Magistrat") -> #N/A | M6: =IF(AND(OR(LEFT(C6,3)="12.",LEFT(E6,3)="12.",LEFT(E6,5)="CET >", IFERROR(L6/$L$6,"")=0),NOT(AND(LEFT(E6,4)="12.8",IFERROR(G6/$G$6,"")<>0)),NOT(AND(LEFT(E6,5)="12.31",IFERROR(L6/$G$6,"")<>0)),NOT(AND(LEFT(E6,5)="12.32",IFERROR(L6/$G$6,"")<>0))),"", IFERROR(L6/$L$6,"")) | N6: =SUMIFS( INDEX('ETPT Format DDG'!$A:$ZZ,,IFERROR(MATCH(E6,'ETPT Format DDG'!$2:$2,0),MATCH(C6,'ETPT Format DDG'!$2:$2,0))), INDEX( 'ETPT Format DDG'!$A:$ZZ,,MATCH("Fonction agrégat",'ETPT Format DDG'!2:2,0)),"F-TIT", INDEX( 'ETPT Format DDG'!$A:$ZZ,,MATCH("Juridiction",'ETPT Format DDG'!2:2,0)),$A$3) -> #N/A | O6: =IF(AND(OR(LEFT(C6,3)="12.",LEFT(E6,3)="12.",LEFT(E6,5)="CET >",IFERROR(N6/$N$6,"")=0),NOT(AND(LEFT(E6,4)="12.8",IFERROR(G6/$G$6,"")<>0)),NOT(AND(LEFT(E6,5)="12.31",IFERROR(N6/$G$6,"")<>0)),NOT(AND(LEFT(E6,5)="12.32",IFERROR(N6/$G$6,"")<>0))),"",IFERROR(N6/$N$6,"")) | P6: =SUMIFS( INDEX('ETPT Format DDG'!$A:$FB,,IFERROR(MATCH(E6,'ETPT Format DDG'!$2:$2,0),MATCH(C6,'ETPT Format DDG'!$2:$2,0))), INDEX( 'ETPT Format DDG'!$A:$ZZ,,MATCH("Fonction agrégat",'ETPT Format DDG'!2:2,0)),"F-PLAC-ADD", INDEX( 'ETPT Format DDG'!$A:$ZZ,,MATCH("Juridiction",'ETPT Format DDG'!2:2,0)),$A$3) -> #N/A | Q6: =SUMIFS( INDEX('ETPT Format DDG'!$A:$FB,,IFERROR(MATCH(E6,'ETPT Format DDG'!$2:$2,0),MATCH(C6,'ETPT Format DDG'!$2:$2,0))), INDEX( 'ETPT Format DDG'!$A:$ZZ,,MATCH("Fonction agrégat",'ETPT Format DDG'!2:2,0)),"F-PLAC-SUB", INDEX( 'ETPT Format DDG'!$A:$ZZ,,MATCH("Juridiction",'ETPT Format DDG'!2:2,0)),$A$3) -> #N/A | R6: =SUMIFS( INDEX('ETPT Format DDG'!$A:$FB,,IFERROR(MATCH(E6,'ETPT Format DDG'!$2:$2,0),MATCH(C6,'ETPT Format DDG'!$2:$2,0))), INDEX( 'ETPT Format DDG'!$A:$ZZ,,MATCH("Fonction agrégat",'ETPT Format DDG'!2:2,0)),"C", 'ETPT Format DDG'!$H:$H,"Greffe", INDEX( 'ETPT Format DDG'!$A:$ZZ,,MATCH("Juridiction",'ETPT Format DDG'!2:2,0)),$A$3) -> #N/A | S6: =SUMIFS( INDEX('ETPT Format DDG'!$A:$FB,,IFERROR(MATCH(E6,'ETPT Format DDG'!$2:$2,0),MATCH(C6,'ETPT Format DDG'!$2:$2,0))), INDEX( 'ETPT Format DDG'!$A:$ZZ,,MATCH("Catégorie",'ETPT Format DDG'!2:2,0)),"Greffe", INDEX( 'ETPT Format DDG'!$A:$ZZ,,MATCH("Juridiction",'ETPT Format DDG'!2:2,0)),$A$3) -> #N/A | T6: =IF(AND(OR(LEFT(C6,3)="12.",LEFT(E6,3)="12.",LEFT(E6,5)="CET >",IFERROR(S6/$S$6,"")=0),NOT(AND(LEFT(E6,4)="12.8",IFERROR(G6/$G$6,"")<>0)),NOT(AND(LEFT(E6,5)="12.31",IFERROR(S6/$G$6,"")<>0)),NOT(AND(LEFT(E6,5)="12.32",IFERROR(S6/$G$6,"")<>0))),"", IFERROR(S6/$S$6,"")) | U6: =SUMIFS( INDEX('ETPT Format DDG'!$A:$FB,,IFERROR(MATCH(E6,'ETPT Format DDG'!$2:$2,0),MATCH(C6,'ETPT Format DDG'!$2:$2,0))), INDEX( 'ETPT Format DDG'!$A:$ZZ,,MATCH("Fonction agrégat",'ETPT Format DDG'!2:2,0)),"C", INDEX( 'ETPT Format DDG'!$A:$ZZ,,MATCH("Juridiction",'ETPT Format DDG'!2:2,0)),$A$3, INDEX( 'ETPT Format DDG'!$A:$ZZ,,MATCH("Catégorie",'ETPT Format DDG'!2:2,0)),"Autour du magistrat") -> #N/A | V6: =IF(AND(OR(LEFT(C6,3)="12.",LEFT(E6,3)="12.",LEFT(E6,5)="CET >",IFERROR(U6/$U$6,"")=0),NOT(AND(LEFT(E6,4)="12.8",IFERROR(G6/$G$6,"")<>0)),NOT(AND(LEFT(E6,5)="12.31",IFERROR(U6/$G$6,"")<>0)),NOT(AND(LEFT(E6,5)="12.32",IFERROR(U6/$G$6,"")<>0))),"", IFERROR(U6/$U$6,"")) | W6: #! END_LOOP y
W7: #! FINISH

Sheet Table_Fonctions
A1: CONCAT | B1: Catégorie | C1: Label | D1: Position | E1: Code | F1: Fonction recodée DDG | G1: Fonction onglet agrégat | H1: #! FOR_EACH f fonctions
A2: ## f.CONCAT | B2: ## f.category_label | C2: ## f.label | D2: ## f.position | E2: ## f.code | F2: ## f.recodedFunction | G2: ## f.category_detail | H2: #! END_LOOP f
H3: #! FINISH

Sheet ETPT Format DDG DETAIL
A1: Réf. | B1: Nom/Prénom/Matricule | C1: Catégorie | D1: Date d'arrivée | E1: Date de départ | G1: Date de début du segment | H1: Date de fin du segment | I1: Nombre jour ouvré sur période total extaction | J1: Nombre jour ouvré segment | K1: Ratio Jour : Nb jour ouvré segment / Nb jour ouvré total | L1: Temps de travail en ETPT saisie | M1: Valeur de l'ETPT sur période total d'extraction (ETPT saisi x Ratio Jour) | N1: Indisponibilité saisie | O1: Valeur de l'indisponibilité sur la période total d'extraction (Indisponibilité saisie en%/100 x Ratio Jour) | P1: Nb jour ouvré CET sur toute la période d'extraction | Q1: Valeur de l'absentéisme | R1: Valeur de l'action 99 | S1: ETPT effectif sur la période total (ETPT- action 99 + absentéisme) x Ratio Jour | T1: ETPT global sur la période (incluant absentéisme et action 99) | U1: ETPT ventilé | V1: Détails de la ventilation (arrondi au millième) : | W1: #! FOR_EACH log ongletLogs
A2: ## log.id | B2: ## log.name | C2: ## log.category | D2: ## log.humanStart | E2: ## log.humanEnd | F2: ## log.main | G2: ## log.periodStart | H2: ## log.periodEnd | I2: ## log.nbOfWorkingDaysQuery | J2: ## log.workingDays | K2: ## log.dayRate | L2: ## log.filledEtp | M2: ## log.queryEtpValue | N2: ## log.totalIndispo | O2: ## log.queryIndispoValue | P2: ## log.cetDays | Q2: ## log.abs | R2: ## log.action99 | S2: ## log.effectifEtp | T2: ## log.etptGlobal | U2: ## log.logAccVentilation | V2: ## log.ctx | W2: #! END_LOOP log
W3: #! FINISH

Sheet ETPT_TJ
B1: DÉCLARATION ETPT TJ
G2: CTECH | H2: Total fonctionnaires techniques | I2: A-B-CBUR | J2: A-B-CBUR | K2: A-B-CBUR | L2: A-B-CBUR | M2: A-B-CBUR | N2: A-B-CBUR | O2: A-B-CBUR | P2: A-B-CBUR | Q2: A-B-CBUR | R2: A-B-CBUR | S2: A-B-CBUR | T2: A-B-CBUR | U2: A-B-CBUR | V2: A-B-CBUR | W2: Total fonctionnaires administratifs | X2: SIEGE S | Y2: SIEGE S | Z2: SIEGE S | AA2: SIEGE S | AB2: SIEGE S | AC2: SIEGE S | AD2: SIEGE S | AE2: SIEGE S | AF2: SIEGE S | AG2: Total magistrats du siège spécialisés | AH2: SIEGE NS | AI2: SIEGE NS | AJ2: SIEGE NS | AK2: SIEGE NS | AL2: SIEGE NS | AM2: SIEGE NS | AN2: SIEGE NS | AO2: SIEGE NS | AP2: SIEGE NS | AQ2: SIEGE NS | AR2: SIEGE NS | AS2: SIEGE NS | AT2: SIEGE NS | AU2: SIEGE NS | AV2: Total magistrats du siège non spécialisés | AW2: PRQT | AX2: PRQT | AY2: PRQT | AZ2: PRQT | BA2: PRQT | BB2: PRQT | BC2: PRQT | BD2: PRQT | BE2: PRQT | BF2: Total magistrats du parquet
G3: FONCTIONNAIRES_C_TECHNIQUES_SPEC | I3: FONCTIONNAIRES_ACTIVITE_CIV_PRQT | J3: FONCTIONNAIRES_BEX_APP | K3: FONCTIONNAIRES_ASSISES | L3: FONC_COUR_CRIM | M3: FONCTIONNAIRES_JIRS_ECOFI | N3: FONCTIONNAIRES_JIRS_CRIMO | O3: FONCTIONNAIRES_JIRS_SS | P3: FONC_TJ_TUT_MAJ | Q3: FONC_TJ_SURENDETTEMENT | S3: FONC_TJ_IP_SR | T3: FONC_CTX_GEN_INF_DIX_MIL | U3: FONC_P_SOC | V3: FONCTIONNAIRES_HORS_FONCT_SPEC | X3: JCP_TJ_TUT_MAJ | Y3: JCP_TJ_SURENDETTEMENT | Z3: J_INSTRUCTION | AA3: J_INSTRUCTION_JIRS_ECOFI | AB3: J_INSTRUCTION_JIRS_CRIMO | AC3: J_INSTRUCTION_JIRS_SS | AD3: JAP | AE3: JE | AF3: JLD_JNS | AH3: MAG_SIEGE_ASSISES | AI3: JNS_COUR_CRIM | AJ3: MAG_SIEGE_JIRS_ECOFI | AK3: MAG_SIEGE_JIRS_CRIMO | AL3: MAG_SIEGE_JIRS_SS | AM3: MAG_SIEGE_CONTRAV | AN3: TI_ACT_J_DEPARTITEUR | AO3: JUGE_CTX_GEN_INF_DIX_MIL | AP3: JUGE_TJ_IP_SR | AQ3: JUGE_TASS_JNS | AR3: JAF_JNS | AS3: J_SPEC_ACT_NON_SPEC | AU3: AUTRES_JNS | AW3: PARQUET_ACTIVITE_CIV_COM | AX3: PARQUET_EXE_APP_PEINES | AY3: PARQUET_JIRS_ECOFI | AZ3: PARQUET_JIRS_CRIMO | BA3: PARQUET_JIRS_SS | BB3: PARQUET_ASSISES | BC3: PQT_COUR_CRIM | BD3: PARQUET_TI | BE3: AUTRES_PARQUET
B4: UO | C4: Code de la juridiction | D4: Juridiction | E4: Code sous action | F4: Action | G4: Fonctionnaires Catégorie C Technique spécialisés | I4: Fonctionnaires activité civile et commerciale du parquet | J4: Fonctionnaires exécution des peines | K4: Fonctionnaires Assises | L4: Fonctionnaires Cour criminelle | M4: Fonctionnaires JIRS éco-fi | N4: Fonctionnaires JIRS crim-org | O4: Fonctionnaires sections spécialisées | P4: Fonctionnaires TJ Tutelles majeurs | Q4: Fonctionnaires TJ au surendettement et au hors surendettement | R4: Fonctionnaires affectés aux fonctions JI, JE, JAP, JLD (pénal uniquement) | S4: Fonctionnaires TJ IP_Saisies Rém | T4: Fonctionnaires TJ Contentieux général < 10 000 EUR | U4: Fonctionnaires affectés aux pôles sociaux | V4: Fonctionnaires hors fonctions spécifiques | X4: JCP TJ Tutelles majeurs | Y4: JCP TJ surendettement et hors surendettement | Z4: Juges Instruction - service général | AA4: Juges Instruction JIRS éco-fi | AB4: Juges Instruction JIRS crim-org | AC4: Juges Instruction sections spécialisées | AD4: JAP | AE4: Juges des Enfants | AF4: JLD (pénal uniquement) | AH4: Magistrats du Siège assises | AI4: Magistrats du siège Cour criminelle | AJ4: Magistrat du siège JIRS éco-fi | AK4: Magistrat du siège JIRS crim-org | AL4: Magistrat du siège sections spécialisées | AM4: Magistrats du Siège activité contraventionnelle | AN4: Magistrats activité juge départiteur | AO4: Juges TJ Contentieux général < 10 000 EUR | AP4: Juges TJ IP et Saisies Rém | AQ4: Juges du Pôle social | AR4: JAF | AS4: Activités non spécialisés des juges spécialisés | AT4: JNS - HO - CRA - Contention (ex JLD civil) | AU4: Autres Magistrats du Siège non spécialisés | AW4: Magistrats du Parquet - activité civile et commerciale | AX4: Magistrats du Parquet - exécution et appl. des peines | AY4: Magistrats du Parquet JIRS éco-fi | AZ4: Magistrats du Parquet JIRS crim-org | BA4: Magistrats du Parquet JIRS sections spécialisées | BB4: Magistrats du Parquet assises | BC4: Magistrats du Parquet Cour criminelle | BD4: Magistrats du Parquet - activité contraventionnelle | BE4: Autres Magistrats du Parquet
A5: ETPT_TJ | D5: =IF(ETPT_TJ_DDG!$D$5="","",ETPT_TJ_DDG!$D$5) | E5: 166-01-NC | F5: Action 1 - Traitement et jugement des contentieux civils | G5: =SUM(SUMIFS( INDEX( 'ETPT Format DDG'!$A:$ZZ,,MATCH("1. TOTAL CONTENTIEUX SOCIAL",'ETPT Format DDG'!2:2,0)), INDEX( 'ETPT Format DDG'!$A:$ZZ,,MATCH("Fonction recodée",'ETPT Format DDG'!2:2,0)),"Fonctionnaire CTECH", INDEX( 'ETPT Format DDG'!$A:$ZZ,,MATCH("TJCPH",'ETPT Format DDG'!2:2,0)),"OUI"))+ SUM(SUMIFS( INDEX( 'ETPT Format DDG'!$A:$ZZ,,MATCH("2. TOTAL CONTENTIEUX JAF",'ETPT Format DDG'!2:2,0)), INDEX( 'ETPT Format DDG'!$A:$ZZ,,MATCH("Fonction recodée",'ETPT Format DDG'!2:2,0)),"Fonctionnaire CTECH", INDEX( 'ETPT Format DDG'!$A:$ZZ,,MATCH("TJCPH",'ETPT Format DDG'!2:2,0)),"OUI"))+ SUM(SUMIFS( INDEX( 'ETPT Format DDG'!$A:$ZZ,,MATCH("3. TOTAL CONTENTIEUX DE LA PROTECTION",'ETPT Format DDG'!2:2,0)), INDEX( 'ETPT Format DDG'!$A:$ZZ,,MATCH("Fonction recodée",'ETPT Format DDG'!2:2,0)),"Fonctionnaire CTECH", INDEX( 'ETPT Format DDG'!$A:$ZZ,,MATCH("TJCPH",'ETPT Format DDG'!2:2,0)),"OUI"))+ SUM(SUMIFS( INDEX( 'ETPT Format DDG'!$A:$ZZ,,MATCH("4. TOTAL CIVIL NON SPÉCIALISÉ",'ETPT Format DDG'!2:2,0)), INDEX( 'ETPT Format DDG'!$A:$ZZ,,MATCH("Fonction recodée",'ETPT Format DDG'!2:2,0)),"Fonctionnaire CTECH", INDEX( 'ETPT Format DDG'!$A:$ZZ,,MATCH("TJCPH",'ETPT Format DDG'!2:2,0)),"OUI"))+ SUM(SUMIFS( INDEX( 'ETPT Format DDG'!$A:$ZZ,,MATCH("5. TOTAL JLD CIVIL",'ETPT Format DDG'!2:2,0)), INDEX( 'ETPT Format DDG'!$A:$ZZ,,MATCH("Fonction recodée",'ETPT Format DDG'!2:2,0)),"Fonctionnaire CTECH", INDEX( 'ETPT Format DDG'!$A:$ZZ,,MATCH("TJCPH",'ETPT Format DDG'!2:2,0)),"OUI"))+ SUM(SUMIFS( INDEX( 'ETPT Format DDG'!$A:$ZZ,,MATCH("6.1. ACTIVITÉ CIVILE",'ETPT Format DDG'!2:2,0)), INDEX( 'ETPT Format DDG'!$A:$ZZ,,MATCH("Fonction recodée",'ETPT Format DDG'!2:2,0)),"Fonctionnaire CTECH", INDEX( 'ETPT Format DDG'!$A:$ZZ,,MATCH("TJCPH",'ETPT Format DDG'!2:2,0)),"OUI"))+ SUM(SUMIFS( INDEX( 'ETPT Format DDG'!$A:$ZZ,,MATCH("11.7. FONCTIONNAIRES AFFECTÉS AU CPH",'ETPT Format DDG'!2:2,0)), INDEX( 'ETPT Format DDG'!$A:$ZZ,,MATCH("Fonction recodée",'ETPT Format DDG'!2:2,0)),"Fonctionnaire CTECH", INDEX( 'ETPT Format DDG'!$A:$ZZ,,MATCH("TJCPH",'ETPT Format DDG'!2:2,0)),"OUI"))+ SUM(SUMIFS( INDEX( 'ETPT Format DDG'!$A:$ZZ,,MATCH("11.8. FONCTIONNAIRES AFFECTÉS AUX ACTIVITÉS CIVILES ET COMMERCIALES DU PARQUET",'ETPT Format DDG'!2:2,0)), INDEX( 'ETPT Format DDG'!$A:$ZZ,,MATCH("Fonction recodée",'ETPT Format DDG'!2:2,0)),"Fonctionnaire CTECH", INDEX( 'ETPT Format DDG'!$A:$ZZ,,MATCH("TJCPH",'ETPT Format DDG'!2:2,0)),"OUI")) -> #N/A | H5: =_xlfn.AGGREGATE(9,6,G5) -> 0 | I5: =SUM(SUMIFS( INDEX( 'ETPT Format DDG'!$A:$ZZ,,MATCH("11.8. FONCTIONNAIRES AFFECTÉS AUX ACTIVITÉS CIVILES ET COMMERCIALES DU PARQUET",'ETPT Format DDG'!2:2,0)), INDEX( 'ETPT Format DDG'!$A:$ZZ,,MATCH("Fonction recodée",'ETPT Format DDG'!2:2,0)),"Fonctionnaire A-B-CBUR", INDEX( 'ETPT Format DDG'!$A:$ZZ,,MATCH("TJCPH",'ETPT Format DDG'!2:2,0)),"OUI")) -> #N/A | P5: =SUM(SUMIFS( INDEX( 'ETPT Format DDG'!$A:$ZZ,,MATCH("3.2. PROTECTION DES MAJEURS",'ETPT Format DDG'!2:2,0)), INDEX( 'ETPT Format DDG'!$A:$ZZ,,MATCH("Fonction recodée",'ETPT Format DDG'!2:2,0)),"Fonctionnaire A-B-CBUR", INDEX( 'ETPT Format DDG'!$A:$ZZ,,MATCH("TJCPH",'ETPT Format DDG'!2:2,0)),"OUI")) -> #N/A | Q5: =SUM(SUMIFS( INDEX( 'ETPT Format DDG'!$A:$ZZ,,MATCH("3. TOTAL CONTENTIEUX DE LA PROTECTION",'ETPT Format DDG'!2:2,0)), INDEX( 'ETPT Format DDG'!$A:$ZZ,,MATCH("Fonction recodée",'ETPT Format DDG'!2:2,0)),"Fonctionnaire A-B-CBUR", INDEX( 'ETPT Format DDG'!$A:$ZZ,,MATCH("TJCPH",'ETPT Format DDG'!2:2,0)),"OUI"))- SUM(SUMIFS( INDEX( 'ETPT Format DDG'!$A:$ZZ,,MATCH("3.2. PROTECTION DES MAJEURS",'ETPT Format DDG'!2:2,0)), INDEX( 'ETPT Format DDG'!$A:$ZZ,,MATCH("Fonction recodée",'ETPT Format DDG'!2:2,0)),"Fonctionnaire A-B-CBUR", INDEX( 'ETPT Format DDG'!$A:$ZZ,,MATCH("TJCPH",'ETPT Format DDG'!2:2,0)),"OUI"))- SUM(SUMIFS( INDEX( 'ETPT Format DDG'!$A:$ZZ,,MATCH("3.43. INJONCTIONS DE PAYER",'ETPT Format DDG'!2:2,0)), INDEX( 'ETPT Format DDG'!$A:$ZZ,,MATCH("Fonction recodée",'ETPT Format DDG'!2:2,0)),"Fonctionnaire A-B-CBUR", INDEX( 'ETPT Format DDG'!$A:$ZZ,,MATCH("TJCPH",'ETPT Format DDG'!2:2,0)),"OUI"))- SUM(SUMIFS( INDEX( 'ETPT Format DDG'!$A:$ZZ,,MATCH("3.44. SAISIE DES RÉMUNÉRATIONS",'ETPT Format DDG'!2:2,0)), INDEX( 'ETPT Format DDG'!$A:$ZZ,,MATCH("Fonction recodée",'ETPT Format DDG'!2:2,0)),"Fonctionnaire A-B-CBUR", INDEX( 'ETPT Format DDG'!$A:$ZZ,,MATCH("TJCPH",'ETPT Format DDG'!2:2,0)),"OUI")) -> #N/A | R5: =SUM(SUMIFS( INDEX( 'ETPT Format DDG'!$A:$ZZ,,MATCH("6.1. ACTIVITÉ CIVILE",'ETPT Format DDG'!2:2,0)), INDEX( 'ETPT Format DDG'!$A:$ZZ,,MATCH("Fonction recodée",'ETPT Format DDG'!2:2,0)),"Fonctionnaire A-B-CBUR", INDEX( 'ETPT Format DDG'!$A:$ZZ,,MATCH("TJCPH",'ETPT Format DDG'!2:2,0)),"OUI")) -> #N/A | S5: =SUM(SUMIFS( INDEX( 'ETPT Format DDG'!$A:$ZZ,,MATCH("3.43. INJONCTIONS DE PAYER",'ETPT Format DDG'!2:2,0)), INDEX( 'ETPT Format DDG'!$A:$ZZ,,MATCH("Fonction recodée",'ETPT Format DDG'!2:2,0)),"Fonctionnaire A-B-CBUR", INDEX( 'ETPT Format DDG'!$A:$ZZ,,MATCH("TJCPH",'ETPT Format DDG'!2:2,0)),"OUI"))+ SUM(SUMIFS( INDEX( 'ETPT Format DDG'!$A:$ZZ,,MATCH("3.44. SAISIE DES RÉMUNÉRATIONS",'ETPT Format DDG'!2:2,0)), INDEX( 'ETPT Format DDG'!$A:$ZZ,,MATCH("Fonction recodée",'ETPT Format DDG'!2:2,0)),"Fonctionnaire A-B-CBUR", INDEX( 'ETPT Format DDG'!$A:$ZZ,,MATCH("TJCPH",'ETPT Format DDG'!2:2,0)),"OUI")) -> #N/A | T5: =SUM(SUMIFS( INDEX( 'ETPT Format DDG'!$A:$ZZ,,MATCH("4.0. CONTENTIEUX GÉNÉRAL <10.000€",'ETPT Format DDG'!2:2,0)), INDEX( 'ETPT Format DDG'!$A:$ZZ,,MATCH("Fonction recodée",'ETPT Format DDG'!2:2,0)),"Fonctionnaire A-B-CBUR", INDEX( 'ETPT Format DDG'!$A:$ZZ,,MATCH("TJCPH",'ETPT Format DDG'!2:2,0)),"OUI")) -> #N/A | U5: =SUM(SUMIFS( INDEX( 'ETPT Format DDG'!$A:$ZZ,,MATCH("1. TOTAL CONTENTIEUX SOCIAL",'ETPT Format DDG'!2:2,0)), INDEX( 'ETPT Format DDG'!$A:$ZZ,,MATCH("Fonction recodée",'ETPT Format DDG'!2:2,0)),"Fonctionnaire A-B-CBUR", INDEX( 'ETPT Format DDG'!$A:$ZZ,,MATCH("TJCPH",'ETPT Format DDG'!2:2,0)),"OUI")) -> #N/A | V5: =SUM(SUMIFS( INDEX( 'ETPT Format DDG'!$A:$ZZ,,MATCH("5. TOTAL JLD CIVIL",'ETPT Format DDG'!2:2,0)), INDEX( 'ETPT Format DDG'!$A:$ZZ,,MATCH("Fonction recodée",'ETPT Format DDG'!2:2,0)),"Fonctionnaire A-B-CBUR", INDEX( 'ETPT Format DDG'!$A:$ZZ,,MATCH("TJCPH",'ETPT Format DDG'!2:2,0)),"OUI"))+ SUM(SUMIFS( INDEX( 'ETPT Format DDG'!$A:$ZZ,,MATCH("2. TOTAL CONTENTIEUX JAF",'ETPT Format DDG'!2:2,0)), INDEX( 'ETPT Format DDG'!$A:$ZZ,,MATCH("Fonction recodée",'ETPT Format DDG'!2:2,0)),"Fonctionnaire A-B-CBUR", INDEX( 'ETPT Format DDG'!$A:$ZZ,,MATCH("TJCPH",'ETPT Format DDG'!2:2,0)),"OUI"))+ SUM(SUMIFS( INDEX( 'ETPT Format DDG'!$A:$ZZ,,MATCH("4. TOTAL CIVIL NON SPÉCIALISÉ",'ETPT Format DDG'!2:2,0)), INDEX( 'ETPT Format DDG'!$A:$ZZ,,MATCH("Fonction recodée",'ETPT Format DDG'!2:2,0)),"Fonctionnaire A-B-CBUR", INDEX( 'ETPT Format DDG'!$A:$ZZ,,MATCH("TJCPH",'ETPT Format DDG'!2:2,0)),"OUI"))- SUM(SUMIFS( INDEX( 'ETPT Format DDG'!$A:$ZZ,,MATCH("4.0. CONTENTIEUX GÉNÉRAL <10.000€",'ETPT Format DDG'!2:2,0)), INDEX( 'ETPT Format DDG'!$A:$ZZ,,MATCH("Fonction recodée",'ETPT Format DDG'!2:2,0)),"Fonctionnaire A-B-CBUR", INDEX( 'ETPT Format DDG'!$A:$ZZ,,MATCH("TJCPH",'ETPT Format DDG'!2:2,0)),"OUI")) -> #N/A | W5: =_xlfn.AGGREGATE(9,6,I5:V5) -> 0 | X5: {=SUM(SUMIFS( INDEX( 'ETPT Format DDG'!$A:$ZZ,,MATCH("3.2. PROTECTION DES MAJEURS",'ETPT Format DDG'!2:2,0)), INDEX( 'ETPT Format DDG'!$A:$ZZ,,MATCH("Fonction recodée",'ETPT Format DDG'!2:2,0)),{"Magistrat SIEGE S";"Magistrat SIEGE NS"}, INDEX( 'ETPT Format DDG'!$A:$ZZ,,MATCH("TJCPH",'ETPT Format DDG'!2:2,0)),"OUI"))} -> #N/A | Y5: {=SUM(SUMIFS( INDEX( 'ETPT Format DDG'!$A:$ZZ,,MATCH("3. TOTAL CONTENTIEUX DE LA PROTECTION",'ETPT Format DDG'!2:2,0)), INDEX( 'ETPT Format DDG'!$A:$ZZ,,MATCH("Fonction recodée",'ETPT Format DDG'!2:2,0)),{"Magistrat SIEGE S";"Magistrat SIEGE NS"}, INDEX( 'ETPT Format DDG'!$A:$ZZ,,MATCH("TJCPH",'ETPT Format DDG'!2:2,0)),"OUI"))- SUM(SUMIFS( INDEX( 'ETPT Format DDG'!$A:$ZZ,,MATCH("3.2. PROTECTION DES MAJEURS",'ETPT Format DDG'!2:2,0)), INDEX( 'ETPT Format DDG'!$A:$ZZ,,MATCH("Fonction recodée",'ETPT Format DDG'!2:2,0)),{"Magistrat SIEGE S";"Magistrat SIEGE NS"}, INDEX( 'ETPT Format DDG'!$A:$ZZ,,MATCH("TJCPH",'ETPT Format DDG'!2:2,0)),"OUI"))- SUM(SUMIFS( INDEX( 'ETPT Format DDG'!$A:$ZZ,,MATCH("3.43. INJONCTIONS DE PAYER",'ETPT Format DDG'!2:2,0)), INDEX( 'ETPT Format DDG'!$A:$ZZ,,MATCH("Fonction recodée",'ETPT Format DDG'!2:2,0)),{"Magistrat SIEGE S";"Magistrat SIEGE NS"}, INDEX( 'ETPT Format DDG'!$A:$ZZ,,MATCH("TJCPH",'ETPT Format DDG'!2:2,0)),"OUI"))- SUM(SUMIFS( INDEX( 'ETPT Format DDG'!$A:$ZZ,,MATCH("3.44. SAISIE DES RÉMUNÉRATIONS",'ETPT Format DDG'!2:2,0)), INDEX( 'ETPT Format DDG'!$A:$ZZ,,MATCH("Fonction recodée",'ETPT Format DDG'!2:2,0)),{"Magistrat SIEGE S";"Magistrat SIEGE NS"}, INDEX( 'ETPT Format DDG'!$A:$ZZ,,MATCH("TJCPH",'ETPT Format DDG'!2:2,0)),"OUI"))} -> #N/A | AE5: {=SUM(SUMIFS( INDEX( 'ETPT Format DDG'!$A:$ZZ,,MATCH("6.1. ACTIVITÉ CIVILE",'ETPT Format DDG'!2:2,0)), INDEX( 'ETPT Format DDG'!$A:$ZZ,,MATCH("Fonction recodée",'ETPT Format DDG'!2:2,0)),{"Magistrat SIEGE S";"Magistrat SIEGE NS"}))} -> #N/A | AG5: =_xlfn.AGGREGATE(9,6,X5:AF5) -> 0 | AN5: {=SUM(SUMIFS( INDEX( 'ETPT Format DDG'!$A:$ZZ,,MATCH("1.1. DÉPARTAGE PRUD'HOMAL",'ETPT Format DDG'!2:2,0)), INDEX( 'ETPT Format DDG'!$A:$ZZ,,MATCH("Fonction recodée",'ETPT Format DDG'!2:2,0)),{"Magistrat SIEGE S";"Magistrat SIEGE NS"}, INDEX( 'ETPT Format DDG'!$A:$ZZ,,MATCH("TJCPH",'ETPT Format DDG'!2:2,0)),"OUI"))} -> #N/A | AO5: {=SUM(SUMIFS( INDEX( 'ETPT Format DDG'!$A:$ZZ,,MATCH("4.0. CONTENTIEUX GÉNÉRAL <10.000€",'ETPT Format DDG'!2:2,0)), INDEX( 'ETPT Format DDG'!$A:$ZZ,,MATCH("Fonction recodée",'ETPT Format DDG'!2:2,0)),{"Magistrat SIEGE S";"Magistrat SIEGE NS"}, INDEX( 'ETPT Format DDG'!$A:$ZZ,,MATCH("TJCPH",'ETPT Format DDG'!2:2,0)),"OUI"))} -> #N/A | AP5: {=SUM(SUMIFS( INDEX( 'ETPT Format DDG'!$A:$ZZ,,MATCH("3.43. INJONCTIONS DE PAYER",'ETPT Format DDG'!2:2,0)), INDEX( 'ETPT Format DDG'!$A:$ZZ,,MATCH("Fonction recodée",'ETPT Format DDG'!2:2,0)),{"Magistrat SIEGE S";"Magistrat SIEGE NS"}, INDEX( 'ETPT Format DDG'!$A:$ZZ,,MATCH("TJCPH",'ETPT Format DDG'!2:2,0)),"OUI"))+ SUM(SUMIFS( INDEX( 'ETPT Format DDG'!$A:$ZZ,,MATCH("3.44. SAISIE DES RÉMUNÉRATIONS",'ETPT Format DDG'!2:2,0)), INDEX( 'ETPT Format DDG'!$A:$ZZ,,MATCH("Fonction recodée",'ETPT Format DDG'!2:2,0)),{"Magistrat SIEGE S";"Magistrat SIEGE NS"}, INDEX( 'ETPT Format DDG'!$A:$ZZ,,MATCH("TJCPH",'ETPT Format DDG'!2:2,0)),"OUI"))} -> #N/A | AQ5: {=SUM(SUMIFS( INDEX( 'ETPT Format DDG'!$A:$ZZ,,MATCH("1. TOTAL CONTENTIEUX SOCIAL",'ETPT Format DDG'!2:2,0)), INDEX( 'ETPT Format DDG'!$A:$ZZ,,MATCH("Fonction recodée",'ETPT Format DDG'!2:2,0)),{"Magistrat SIEGE S";"Magistrat SIEGE NS"}, INDEX( 'ETPT Format DDG'!$A:$ZZ,,MATCH("TJCPH",'ETPT Format DDG'!2:2,0)),"OUI"))- SUM(SUMIFS( INDEX( 'ETPT Format DDG'!$A:$ZZ,,MATCH("1.1. DÉPARTAGE PRUD'HOMAL",'ETPT Format DDG'!2:2,0)), INDEX( 'ETPT Format DDG'!$A:$ZZ,,MATCH("Fonction recodée",'ETPT Format DDG'!2:2,0)),{"Magistrat SIEGE S";"Magistrat SIEGE NS"}, INDEX( 'ETPT Format DDG'!$A:$ZZ,,MATCH("TJCPH",'ETPT Format DDG'!2:2,0)),"OUI"))} -> #N/A | AR5: {=SUM(SUMIFS( INDEX( 'ETPT Format DDG'!$A:$ZZ,,MATCH("2. TOTAL CONTENTIEUX JAF",'ETPT Format DDG'!2:2,0)), INDEX( 'ETPT Format DDG'!$A:$ZZ,,MATCH("Fonction recodée",'ETPT Format DDG'!2:2,0)),{"Magistrat SIEGE S";"Magistrat SIEGE NS"}))} -> #N/A | AS5: =MAX(0,SUM(SUMIFS( INDEX( 'ETPT Format DDG'!$A:$ZZ,,MATCH("4. TOTAL CIVIL NON SPÉCIALISÉ",'ETPT Format DDG'!2:2,0)), INDEX( 'ETPT Format DDG'!$A:$ZZ,,MATCH("Fonction recodée",'ETPT Format DDG'!2:2,0)),"Magistrat SIEGE S", INDEX( 'ETPT Format DDG'!$A:$ZZ,,MATCH("TJCPH",'ETPT Format DDG'!2:2,0)),"OUI"))- SUM(SUMIFS( INDEX( 'ETPT Format DDG'!$A:$ZZ,,MATCH("4.0. CONTENTIEUX GÉNÉRAL <10.000€",'ETPT Format DDG'!2:2,0)), INDEX( 'ETPT Format DDG'!$A:$ZZ,,MATCH("Fonction recodée",'ETPT Format DDG'!2:2,0)),"Magistrat SIEGE S", INDEX( 'ETPT Format DDG'!$A:$ZZ,,MATCH("TJCPH",'ETPT Format DDG'!2:2,0)),"OUI"))) -> #N/A | AT5: {=SUM(SUMIFS( INDEX( 'ETPT Format DDG'!$A:$ZZ,,MATCH("5. TOTAL JLD CIVIL",'ETPT Format DDG'!2:2,0)), INDEX( 'ETPT Format DDG'!$A:$ZZ,,MATCH("Fonction recodée",'ETPT Format DDG'!2:2,0)),{"Magistrat SIEGE S";"Magistrat SIEGE NS"}))} -> #N/A | AU5: =MAX(0,SUM(SUMIFS( INDEX( 'ETPT Format DDG'!$A:$ZZ,,MATCH("4. TOTAL CIVIL NON SPÉCIALISÉ",'ETPT Format DDG'!2:2,0)), INDEX( 'ETPT Format DDG'!$A:$ZZ,,MATCH("Fonction recodée",'ETPT Format DDG'!2:2,0)),"Magistrat SIEGE NS", INDEX( 'ETPT Format DDG'!$A:$ZZ,,MATCH("TJCPH",'ETPT Format DDG'!2:2,0)),"OUI"))- SUM(SUMIFS( INDEX( 'ETPT Format DDG'!$A:$ZZ,,MATCH("4.0. CONTENTIEUX GÉNÉRAL <10.000€",'ETPT Format DDG'!2:2,0)), INDEX( 'ETPT Format DDG'!$A:$ZZ,,MATCH("Fonction recodée",'ETPT Format DDG'!2:2,0)),"Magistrat SIEGE NS", INDEX( 'ETPT Format DDG'!$A:$ZZ,,MATCH("TJCPH",'ETPT Format DDG'!2:2,0)),"OUI"))) -> #N/A | AV5: =_xlfn.AGGREGATE(9,6,AH5:AU5) -> 0 | BF5: =SUM(AW5:BE5) -> 0
A6: ETPT_TJ | D6: =$D$5 | E6: 166-02-NC | F6: Action 2 - Traitement et jugement des affaires pénales | G6: =SUM(SUMIFS( INDEX( 'ETPT Format DDG'!$A:$ZZ,,MATCH("6.2. ACTIVITÉ PÉNALE",'ETPT Format DDG'!2:2,0)), INDEX( 'ETPT Format DDG'!$A:$ZZ,,MATCH("Fonction recodée",'ETPT Format DDG'!2:2,0)),"Fonctionnaire CTECH")) + SUM(SUMIFS( INDEX( 'ETPT Format DDG'!$A:$ZZ,,MATCH("7. TOTAL SIÈGE PÉNAL",'ETPT Format DDG'!2:2,0)), INDEX( 'ETPT Format DDG'!$A:$ZZ,,MATCH("Fonction recodée",'ETPT Format DDG'!2:2,0)),"Fonctionnaire CTECH")) + SUM(SUMIFS( INDEX( 'ETPT Format DDG'!$A:$ZZ,,MATCH("8. TOTAL JUGES D'INSTRUCTION",'ETPT Format DDG'!2:2,0)), INDEX( 'ETPT Format DDG'!$A:$ZZ,,MATCH("Fonction recodée",'ETPT Format DDG'!2:2,0)),"Fonctionnaire CTECH")) + SUM(SUMIFS( INDEX( 'ETPT Format DDG'!$A:$ZZ,,MATCH("9. TOTAL JAP",'ETPT Format DDG'!2:2,0)), INDEX( 'ETPT Format DDG'!$A:$ZZ,,MATCH("Fonction recodée",'ETPT Format DDG'!2:2,0)),"Fonctionnaire CTECH")) + SUM(SUMIFS( INDEX( 'ETPT Format DDG'!$A:$ZZ,,MATCH("10. TOTAL JLD PÉNAL",'ETPT Format DDG'!2:2,0)), INDEX( 'ETPT Format DDG'!$A:$ZZ,,MATCH("Fonction recodée",'ETPT Format DDG'!2:2,0)),"Fonctionnaire CTECH")) + SUM(SUMIFS( INDEX( 'ETPT Format DDG'!$A:$ZZ,,MATCH("11.9. FONCTIONNAIRES AFFECTÉS À L'EXÉCUTION DES PEINES",'ETPT Format DDG'!2:2,0)), INDEX( 'ETPT Format DDG'!$A:$ZZ,,MATCH("Fonction recodée",'ETPT Format DDG'!2:2,0)),"Fonctionnaire CTECH")) + SUM(SUMIFS( INDEX( 'ETPT Format DDG'!$A:$ZZ,,MATCH("11.10. AUTRES FONCTIONNAIRES AFFECTÉS AU PARQUET",'ETPT Format DDG'!2:2,0)), INDEX( 'ETPT Format DDG'!$A:$ZZ,,MATCH("Fonction recodée",'ETPT Format DDG'!2:2,0)),"Fonctionnaire CTECH")) -> #N/A | H6: =_xlfn.AGGREGATE(9,6,G6) -> 0 | J6: =SUM(SUMIFS( INDEX( 'ETPT Format DDG'!$A:$ZZ,,MATCH("11.9. FONCTIONNAIRES AFFECTÉS À L'EXÉCUTION DES PEINES",'ETPT Format DDG'!2:2,0)), INDEX( 'ETPT Format DDG'!$A:$ZZ,,MATCH("Fonction recodée",'ETPT Format DDG'!2:2,0)),"Fonctionnaire A-B-CBUR")) -> #N/A | K6: =SUM(SUMIFS( INDEX( 'ETPT Format DDG'!$A:$ZZ,,MATCH("7.5. COUR D'ASSISES HORS JIRS",'ETPT Format DDG'!2:2,0)), INDEX( 'ETPT Format DDG'!$A:$ZZ,,MATCH("Fonction recodée",'ETPT Format DDG'!2:2,0)),"Fonctionnaire A-B-CBUR"))+ SUM(SUMIFS( INDEX( 'ETPT Format DDG'!$A:$ZZ,,MATCH("7.51. COUR D'ASSISES JIRS",'ETPT Format DDG'!2:2,0)), INDEX( 'ETPT Format DDG'!$A:$ZZ,,MATCH("Fonction recodée",'ETPT Format DDG'!2:2,0)),"Fonctionnaire A-B-CBUR")) -> #N/A | L6: =SUM(SUMIFS( INDEX( 'ETPT Format DDG'!$A:$ZZ,,MATCH("7.52. COUR CRIMINELLE",'ETPT Format DDG'!2:2,0)), INDEX( 'ETPT Format DDG'!$A:$ZZ,,MATCH("Fonction recodée",'ETPT Format DDG'!2:2,0)),"Fonctionnaire A-B-CBUR")) -> #N/A | M6: =SUM(SUMIFS( INDEX( 'ETPT Format DDG'!$A:$ZZ,,MATCH("7.121. COLLÉGIALES JIRS ÉCO-FI",'ETPT Format DDG'!2:2,0)), INDEX( 'ETPT Format DDG'!$A:$ZZ,,MATCH("Fonction recodée",'ETPT Format DDG'!2:2,0)),"Fonctionnaire A-B-CBUR", INDEX( 'ETPT Format DDG'!$A:$ZZ,,MATCH("Jirs",'ETPT Format DDG'!2:2,0)),"x")) -> #N/A | N6: =SUM(SUMIFS( INDEX( 'ETPT Format DDG'!$A:$ZZ,,MATCH("7.12. COLLÉGIALES JIRS CRIM-ORG",'ETPT Format DDG'!2:2,0)), INDEX( 'ETPT Format DDG'!$A:$ZZ,,MATCH("Fonction recodée",'ETPT Format DDG'!2:2,0)),"Fonctionnaire A-B-CBUR")) -> #N/A | O6: =SUM(SUMIFS( INDEX( 'ETPT Format DDG'!$A:$ZZ,,MATCH("7.122. COLLÉGIALES AUTRES SECTIONS SPÉCIALISÉES",'ETPT Format DDG'!2:2,0)), INDEX( 'ETPT Format DDG'!$A:$ZZ,,MATCH("Fonction recodée",'ETPT Format DDG'!2:2,0)),"Fonctionnaire A-B-CBUR"))+ SUM(SUMIFS( INDEX( 'ETPT Format DDG'!$A:$ZZ,,MATCH("7.121. COLLÉGIALES JIRS ÉCO-FI",'ETPT Format DDG'!2:2,0)), INDEX( 'ETPT Format DDG'!$A:$ZZ,,MATCH("Fonction recodée",'ETPT Format DDG'!2:2,0)),"Fonctionnaire A-B-CBUR", INDEX( 'ETPT Format DDG'!$A:$ZZ,,MATCH("Jirs",'ETPT Format DDG'!2:2,0)),"")) -> #N/A | R6: =SUM(SUMIFS( INDEX( 'ETPT Format DDG'!$A:$ZZ,,MATCH("6.2. ACTIVITÉ PÉNALE",'ETPT Format DDG'!2:2,0)), INDEX( 'ETPT Format DDG'!$A:$ZZ,,MATCH("Fonction recodée",'ETPT Format DDG'!2:2,0)),"Fonctionnaire A-B-CBUR"))+ SUM(SUMIFS( INDEX( 'ETPT Format DDG'!$A:$ZZ,,MATCH("8. TOTAL JUGES D'INSTRUCTION",'ETPT Format DDG'!2:2,0)), INDEX( 'ETPT Format DDG'!$A:$ZZ,,MATCH("Fonction recodée",'ETPT Format DDG'!2:2,0)),"Fonctionnaire A-B-CBUR"))+ SUM(SUMIFS( INDEX( 'ETPT Format DDG'!$A:$ZZ,,MATCH("9. TOTAL JAP",'ETPT Format DDG'!2:2,0)), INDEX( 'ETPT Format DDG'!$A:$ZZ,,MATCH("Fonction recodée",'ETPT Format DDG'!2:2,0)),"Fonctionnaire A-B-CBUR"))+ SUM(SUMIFS( INDEX( 'ETPT Format DDG'!$A:$ZZ,,MATCH("10. TOTAL JLD PÉNAL",'ETPT Format DDG'!2:2,0)), INDEX( 'ETPT Format DDG'!$A:$ZZ,,MATCH("Fonction recodée",'ETPT Format DDG'!2:2,0)),"Fonctionnaire A-B-CBUR")) -> #N/A | V6: =MAX(0,SUM(SUMIFS( INDEX( 'ETPT Format DDG'!$A:$ZZ,,MATCH("7. TOTAL SIÈGE PÉNAL",'ETPT Format DDG'!2:2,0)), INDEX( 'ETPT Format DDG'!$A:$ZZ,,MATCH("Fonction recodée",'ETPT Format DDG'!2:2,0)),"Fonctionnaire A-B-CBUR"))+ SUM(SUMIFS( INDEX( 'ETPT Format DDG'!$A:$ZZ,,MATCH("11.10. AUTRES FONCTIONNAIRES AFFECTÉS AU PARQUET",'ETPT Format DDG'!2:2,0)), INDEX( 'ETPT Format DDG'!$A:$ZZ,,MATCH("Fonction recodée",'ETPT Format DDG'!2:2,0)),"Fonctionnaire A-B-CBUR"))- SUM(SUMIFS( INDEX( 'ETPT Format DDG'!$A:$ZZ,,MATCH("7.5. COUR D'ASSISES HORS JIRS",'ETPT Format DDG'!2:2,0)), INDEX( 'ETPT Format DDG'!$A:$ZZ,,MATCH("Fonction recodée",'ETPT Format DDG'!2:2,0)),"Fonctionnaire A-B-CBUR"))- SUM(SUMIFS( INDEX( 'ETPT Format DDG'!$A:$ZZ,,MATCH("7.51. COUR D'ASSISES JIRS",'ETPT Format DDG'!2:2,0)), INDEX( 'ETPT Format DDG'!$A:$ZZ,,MATCH("Fonction recodée",'ETPT Format DDG'!2:2,0)),"Fonctionnaire A-B-CBUR"))- SUM(SUMIFS( INDEX( 'ETPT Format DDG'!$A:$ZZ,,MATCH("7.52. COUR CRIMINELLE",'ETPT Format DDG'!2:2,0)), INDEX( 'ETPT Format DDG'!$A:$ZZ,,MATCH("Fonction recodée",'ETPT Format DDG'!2:2,0)),"Fonctionnaire A-B-CBUR"))- SUM(SUMIFS( INDEX( 'ETPT Format DDG'!$A:$ZZ,,MATCH("7.121. COLLÉGIALES JIRS ÉCO-FI",'ETPT Format DDG'!2:2,0)), INDEX( 'ETPT Format DDG'!$A:$ZZ,,MATCH("Fonction recodée",'ETPT Format DDG'!2:2,0)),"Fonctionnaire A-B-CBUR"))- SUM(SUMIFS( INDEX( 'ETPT Format DDG'!$A:$ZZ,,MATCH("7.12. COLLÉGIALES JIRS CRIM-ORG",'ETPT Format DDG'!2:2,0)), INDEX( 'ETPT Format DDG'!$A:$ZZ,,MATCH("Fonction recodée",'ETPT Format DDG'!2:2,0)),"Fonctionnaire A-B-CBUR"))- SUM(SUMIFS( INDEX( 'ETPT Format DDG'!$A:$ZZ,,MATCH("7.122. COLLÉGIALES AUTRES SECTIONS SPÉCIALISÉES",'ETPT Format DDG'!2:2,0)), INDEX( 'ETPT Format DDG'!$A:$ZZ,,MATCH("Fonction recodée",'ETPT Format DDG'!2:2,0)),"Fonctionnaire A-B-CBUR"))) -> #N/A | W6: =_xlfn.AGGREGATE(9,6,I6:V6) -> 0 | Z6: {=SUM(SUMIFS( INDEX( 'ETPT Format DDG'!$A:$ZZ,,MATCH("8.1. SERVICE GÉNÉRAL",'ETPT Format DDG'!2:2,0)), INDEX( 'ETPT Format DDG'!$A:$ZZ,,MATCH("Fonction recodée",'ETPT Format DDG'!2:2,0)),{"Magistrat SIEGE S";"Magistrat SIEGE NS"}))} -> #N/A | AA6: {=SUM(SUMIFS( INDEX( 'ETPT Format DDG'!$A:$ZZ,,MATCH("8.2. JIRS ÉCO-FI",'ETPT Format DDG'!2:2,0)), INDEX( 'ETPT Format DDG'!$A:$ZZ,,MATCH("Fonction recodée",'ETPT Format DDG'!2:2,0)),{"Magistrat SIEGE S";"Magistrat SIEGE NS"}))} -> #N/A | AB6: {=SUM(SUMIFS( INDEX( 'ETPT Format DDG'!$A:$ZZ,,MATCH("8.3. JIRS CRIM-ORG",'ETPT Format DDG'!2:2,0)), INDEX( 'ETPT Format DDG'!$A:$ZZ,,MATCH("Fonction recodée",'ETPT Format DDG'!2:2,0)),{"Magistrat SIEGE S";"Magistrat SIEGE NS"}))} -> #N/A | AC6: {=SUM(SUMIFS( INDEX( 'ETPT Format DDG'!$A:$ZZ,,MATCH("8.4. AUTRES SECTIONS SPÉCIALISÉES",'ETPT Format DDG'!2:2,0)), INDEX( 'ETPT Format DDG'!$A:$ZZ,,MATCH("Fonction recodée",'ETPT Format DDG'!2:2,0)),{"Magistrat SIEGE S";"Magistrat SIEGE NS"}))+ SUM(SUMIFS( INDEX( 'ETPT Format DDG'!$A:$ZZ,,MATCH("8.11. ECO-FI HORS JIRS",'ETPT Format DDG'!2:2,0)), INDEX( 'ETPT Format DDG'!$A:$ZZ,,MATCH("Fonction recodée",'ETPT Format DDG'!2:2,0)),{"Magistrat SIEGE S";"Magistrat SIEGE NS"}))} -> #N/A | AD6: {=SUM(SUMIFS( INDEX( 'ETPT Format DDG'!$A:$ZZ,,MATCH("9. TOTAL JAP",'ETPT Format DDG'!2:2,0)), INDEX( 'ETPT Format DDG'!$A:$ZZ,,MATCH("Fonction recodée",'ETPT Format DDG'!2:2,0)),{"Magistrat SIEGE S";"Magistrat SIEGE NS"}))} -> #N/A | AE6: {=SUM(SUMIFS( INDEX( 'ETPT Format DDG'!$A:$ZZ,,MATCH("6.2. ACTIVITÉ PÉNALE",'ETPT Format DDG'!2:2,0)), INDEX( 'ETPT Format DDG'!$A:$ZZ,,MATCH("Fonction recodée",'ETPT Format DDG'!2:2,0)),{"Magistrat SIEGE S";"Magistrat SIEGE NS"}))} -> #N/A | AF6: {=SUM(SUMIFS( INDEX( 'ETPT Format DDG'!$A:$ZZ,,MATCH("10. TOTAL JLD PÉNAL",'ETPT Format DDG'!2:2,0)), INDEX( 'ETPT Format DDG'!$A:$ZZ,,MATCH("Fonction recodée",'ETPT Format DDG'!2:2,0)),{"Magistrat SIEGE S";"Magistrat SIEGE NS"}))} -> #N/A | AG6: =_xlfn.AGGREGATE(9,6,X6:AF6) -> 0 | AH6: {=SUM(SUMIFS( INDEX( 'ETPT Format DDG'!$A:$ZZ,,MATCH("7.5. COUR D'ASSISES HORS JIRS",'ETPT Format DDG'!2:2,0)), INDEX( 'ETPT Format DDG'!$A:$ZZ,,MATCH("Fonction recodée",'ETPT Format DDG'!2:2,0)),{"Magistrat SIEGE S";"Magistrat SIEGE NS"}))+ SUM(SUMIFS( INDEX( 'ETPT Format DDG'!$A:$ZZ,,MATCH("7.51. COUR D'ASSISES JIRS",'ETPT Format DDG'!2:2,0)), INDEX( 'ETPT Format DDG'!$A:$ZZ,,MATCH("Fonction recodée",'ETPT Format DDG'!2:2,0)),{"Magistrat SIEGE S";"Magistrat SIEGE NS"}))} -> #N/A | AI6: {=SUM(SUMIFS( INDEX( 'ETPT Format DDG'!$A:$ZZ,,MATCH("7.52. COUR CRIMINELLE",'ETPT Format DDG'!2:2,0)), INDEX( 'ETPT Format DDG'!$A:$ZZ,,MATCH("Fonction recodée",'ETPT Format DDG'!2:2,0)),{"Magistrat SIEGE S";"Magistrat SIEGE NS"}))} -> #N/A | AJ6: {=SUM(SUMIFS( INDEX( 'ETPT Format DDG'!$A:$ZZ,,MATCH("7.121. COLLÉGIALES JIRS ÉCO-FI",'ETPT Format DDG'!2:2,0)), INDEX( 'ETPT Format DDG'!$A:$ZZ,,MATCH("Fonction recodée",'ETPT Format DDG'!2:2,0)),{"Magistrat SIEGE S";"Magistrat SIEGE NS"}, INDEX( 'ETPT Format DDG'!$A:$ZZ,,MATCH("Jirs",'ETPT Format DDG'!2:2,0)),"x"))} -> #N/A | AK6: {=SUM(SUMIFS( INDEX( 'ETPT Format DDG'!$A:$ZZ,,MATCH("7.12. COLLÉGIALES JIRS CRIM-ORG",'ETPT Format DDG'!2:2,0)), INDEX( 'ETPT Format DDG'!$A:$ZZ,,MATCH("Fonction recodée",'ETPT Format DDG'!2:2,0)),{"Magistrat SIEGE S";"Magistrat SIEGE NS"}))} -> #N/A | AL6: {=SUM(SUMIFS( INDEX( 'ETPT Format DDG'!$A:$ZZ,,MATCH("7.122. COLLÉGIALES AUTRES SECTIONS SPÉCIALISÉES",'ETPT Format DDG'!2:2,0)), INDEX( 'ETPT Format DDG'!$A:$ZZ,,MATCH("Fonction recodée",'ETPT Format DDG'!2:2,0)),{"Magistrat SIEGE S";"Magistrat SIEGE NS"}))+ SUM(SUMIFS( INDEX( 'ETPT Format DDG'!$A:$ZZ,,MATCH("7.121. COLLÉGIALES JIRS ÉCO-FI",'ETPT Format DDG'!2:2,0)), INDEX( 'ETPT Format DDG'!$A:$ZZ,,MATCH("Fonction recodée",'ETPT Format DDG'!2:2,0)),{"Magistrat SIEGE S";"Magistrat SIEGE NS"}, INDEX( 'ETPT Format DDG'!$A:$ZZ,,MATCH("Jirs",'ETPT Format DDG'!2:2,0)),""))} -> #N/A | AM6: {=SUM(SUMIFS( INDEX( 'ETPT Format DDG'!$A:$ZZ,,MATCH("7.6. TRIBUNAL DE POLICE",'ETPT Format DDG'!2:2,0)), INDEX( 'ETPT Format DDG'!$A:$ZZ,,MATCH("Fonction recodée",'ETPT Format DDG'!2:2,0)),{"Magistrat SIEGE S";"Magistrat SIEGE NS"}))+ SUM(SUMIFS( INDEX( 'ETPT Format DDG'!$A:$ZZ,,MATCH("7.7. OP CONTRAVENTIONNELLES",'ETPT Format DDG'!2:2,0)), INDEX( 'ETPT Format DDG'!$A:$ZZ,,MATCH("Fonction recodée",'ETPT Format DDG'!2:2,0)),{"Magistrat SIEGE S";"Magistrat SIEGE NS"}))} -> #N/A | AS6: =MAX(0,SUMIFS( INDEX( 'ETPT Format DDG'!$A:$ZZ,,MATCH("7. TOTAL SIÈGE PÉNAL",'ETPT Format DDG'!2:2,0)), INDEX( 'ETPT Format DDG'!$A:$ZZ,,MATCH("Fonction recodée",'ETPT Format DDG'!2:2,0)),"Magistrat SIEGE S")- SUMIFS( INDEX( 'ETPT Format DDG'!$A:$ZZ,,MATCH("7.5. COUR D'ASSISES HORS JIRS",'ETPT Format DDG'!2:2,0)), INDEX( 'ETPT Format DDG'!$A:$ZZ,,MATCH("Fonction recodée",'ETPT Format DDG'!2:2,0)),"Magistrat SIEGE S")- SUMIFS( INDEX( 'ETPT Format DDG'!$A:$ZZ,,MATCH("7.51. COUR D'ASSISES JIRS",'ETPT Format DDG'!2:2,0)), INDEX( 'ETPT Format DDG'!$A:$ZZ,,MATCH("Fonction recodée",'ETPT Format DDG'!2:2,0)),"Magistrat SIEGE S")- SUMIFS( INDEX( 'ETPT Format DDG'!$A:$ZZ,,MATCH("7.52. COUR CRIMINELLE",'ETPT Format DDG'!2:2,0)), INDEX( 'ETPT Format DDG'!$A:$ZZ,,MATCH("Fonction recodée",'ETPT Format DDG'!2:2,0)),"Magistrat SIEGE S")- SUMIFS( INDEX( 'ETPT Format DDG'!$A:$ZZ,,MATCH("7.121. COLLÉGIALES JIRS ÉCO-FI",'ETPT Format DDG'!2:2,0)), INDEX( 'ETPT Format DDG'!$A:$ZZ,,MATCH("Fonction recodée",'ETPT Format DDG'!2:2,0)),"Magistrat SIEGE S")- SUMIFS( INDEX( 'ETPT Format DDG'!$A:$ZZ,,MATCH("7.12. COLLÉGIALES JIRS CRIM-ORG",'ETPT Format DDG'!2:2,0)), INDEX( 'ETPT Format DDG'!$A:$ZZ,,MATCH("Fonction recodée",'ETPT Format DDG'!2:2,0)),"Magistrat SIEGE S")- SUMIFS( INDEX( 'ETPT Format DDG'!$A:$ZZ,,MATCH("7.122. COLLÉGIALES AUTRES SECTIONS SPÉCIALISÉES",'ETPT Format DDG'!2:2,0)), INDEX( 'ETPT Format DDG'!$A:$ZZ,,MATCH("Fonction recodée",'ETPT Format DDG'!2:2,0)),"Magistrat SIEGE S")- SUMIFS( INDEX( 'ETPT Format DDG'!$A:$ZZ,,MATCH("7.6. TRIBUNAL DE POLICE",'ETPT Format DDG'!2:2,0)), INDEX( 'ETPT Format DDG'!$A:$ZZ,,MATCH("Fonction recodée",'ETPT Format DDG'!2:2,0)),"Magistrat SIEGE S")- SUMIFS( INDEX( 'ETPT Format DDG'!$A:$ZZ,,MATCH("7.7. OP CONTRAVENTIONNELLES",'ETPT Format DDG'!2:2,0)), INDEX( 'ETPT Format DDG'!$A:$ZZ,,MATCH("Fonction recodée",'ETPT Format DDG'!2:2,0)),"Magistrat SIEGE S")) -> #N/A | AU6: =MAX(0,SUMIFS( INDEX( 'ETPT Format DDG'!$A:$ZZ,,MATCH("7. TOTAL SIÈGE PÉNAL",'ETPT Format DDG'!2:2,0)), INDEX( 'ETPT Format DDG'!$A:$ZZ,,MATCH("Fonction recodée",'ETPT Format DDG'!2:2,0)),"Magistrat SIEGE NS")- SUMIFS( INDEX( 'ETPT Format DDG'!$A:$ZZ,,MATCH("7.5. COUR D'ASSISES HORS JIRS",'ETPT Format DDG'!2:2,0)), INDEX( 'ETPT Format DDG'!$A:$ZZ,,MATCH("Fonction recodée",'ETPT Format DDG'!2:2,0)),"Magistrat SIEGE NS")- SUMIFS( INDEX( 'ETPT Format DDG'!$A:$ZZ,,MATCH("7.51. COUR D'ASSISES JIRS",'ETPT Format DDG'!2:2,0)), INDEX( 'ETPT Format DDG'!$A:$ZZ,,MATCH("Fonction recodée",'ETPT Format DDG'!2:2,0)),"Magistrat SIEGE NS")- SUMIFS( INDEX( 'ETPT Format DDG'!$A:$ZZ,,MATCH("7.52. COUR CRIMINELLE",'ETPT Format DDG'!2:2,0)), INDEX( 'ETPT Format DDG'!$A:$ZZ,,MATCH("Fonction recodée",'ETPT Format DDG'!2:2,0)),"Magistrat SIEGE NS")- SUMIFS( INDEX( 'ETPT Format DDG'!$A:$ZZ,,MATCH("7.121. COLLÉGIALES JIRS ÉCO-FI",'ETPT Format DDG'!2:2,0)), INDEX( 'ETPT Format DDG'!$A:$ZZ,,MATCH("Fonction recodée",'ETPT Format DDG'!2:2,0)),"Magistrat SIEGE NS")- SUMIFS( INDEX( 'ETPT Format DDG'!$A:$ZZ,,MATCH("7.12. COLLÉGIALES JIRS CRIM-ORG",'ETPT Format DDG'!2:2,0)), INDEX( 'ETPT Format DDG'!$A:$ZZ,,MATCH("Fonction recodée",'ETPT Format DDG'!2:2,0)),"Magistrat SIEGE NS")- SUMIFS( INDEX( 'ETPT Format DDG'!$A:$ZZ,,MATCH("7.122. COLLÉGIALES AUTRES SECTIONS SPÉCIALISÉES",'ETPT Format DDG'!2:2,0)), INDEX( 'ETPT Format DDG'!$A:$ZZ,,MATCH("Fonction recodée",'ETPT Format DDG'!2:2,0)),"Magistrat SIEGE NS")- SUMIFS( INDEX( 'ETPT Format DDG'!$A:$ZZ,,MATCH("7.6. TRIBUNAL DE POLICE",'ETPT Format DDG'!2:2,0)), INDEX( 'ETPT Format DDG'!$A:$ZZ,,MATCH("Fonction recodée",'ETPT Format DDG'!2:2,0)),"Magistrat SIEGE NS")- SUMIFS( INDEX( 'ETPT Format DDG'!$A:$ZZ,,MATCH("7.7. OP CONTRAVENTIONNELLES",'ETPT Format DDG'!2:2,0)), INDEX( 'ETPT Format DDG'!$A:$ZZ,,MATCH("Fonction recodée",'ETPT Format DDG'!2:2,0)),"Magistrat SIEGE NS")) -> #N/A | AV6: =_xlfn.AGGREGATE(9,6,AH6:AU6) -> 0 | BF6: =SUM(AW6:BE6) -> 0
A7: ETPT_TJ | D7: =$D$5 | E7: 166-04-NC | F7: Action 4 - Conseil supérieur de la magistrature | H7: =_xlfn.AGGREGATE(9,6,G7) -> 0 | W7: =_xlfn.AGGREGATE(9,6,I7:V7) -> 0 | Y7: {=SUM(SUMIFS( INDEX( 'ETPT Format DDG'!$A:$ZZ,,MATCH("11.5. CSM",'ETPT Format DDG'!2:2,0)), INDEX( 'ETPT Format DDG'!$A:$ZZ,,MATCH("Fonction",'ETPT Format DDG'!2:2,0)),{"JCP";"VPCP";"1VPCP"}, INDEX( 'ETPT Format DDG'!$A:$ZZ,,MATCH("TJCPH",'ETPT Format DDG'!2:2,0)),"OUI"))} -> #N/A | Z7: {=SUM(SUMIFS( INDEX( 'ETPT Format DDG'!$A:$ZZ,,MATCH("11.5. CSM",'ETPT Format DDG'!2:2,0)), INDEX( 'ETPT Format DDG'!$A:$ZZ,,MATCH("Fonction",'ETPT Format DDG'!2:2,0)),{"JI";"VPI";"1VPI"}, INDEX( 'ETPT Format DDG'!$A:$ZZ,,MATCH("TJCPH",'ETPT Format DDG'!2:2,0)),"OUI"))} -> #N/A | AD7: {=SUM(SUMIFS( INDEX( 'ETPT Format DDG'!$A:$ZZ,,MATCH("11.5. CSM",'ETPT Format DDG'!2:2,0)), INDEX( 'ETPT Format DDG'!$A:$ZZ,,MATCH("Fonction",'ETPT Format DDG'!2:2,0)),{"JAP";"VPAP";"1VPAP"}, INDEX( 'ETPT Format DDG'!$A:$ZZ,,MATCH("TJCPH",'ETPT Format DDG'!2:2,0)),"OUI"))} -> #N/A | AE7: {=SUM(SUMIFS( INDEX( 'ETPT Format DDG'!$A:$ZZ,,MATCH("11.5. CSM",'ETPT Format DDG'!2:2,0)), INDEX( 'ETPT Format DDG'!$A:$ZZ,,MATCH("Fonction",'ETPT Format DDG'!2:2,0)),{"JE";"VPE";"1VPE"}, INDEX( 'ETPT Format DDG'!$A:$ZZ,,MATCH("TJCPH",'ETPT Format DDG'!2:2,0)),"OUI"))} -> #N/A | AF7: {=SUM(SUMIFS( INDEX( 'ETPT Format DDG'!$A:$ZZ,,MATCH("11.5. CSM",'ETPT Format DDG'!2:2,0)), INDEX( 'ETPT Format DDG'!$A:$ZZ,,MATCH("Fonction",'ETPT Format DDG'!2:2,0)),{"VPLD";"1VPLD"}, INDEX( 'ETPT Format DDG'!$A:$ZZ,,MATCH("TJCPH",'ETPT Format DDG'!2:2,0)),"OUI"))} -> #N/A | AG7: =_xlfn.AGGREGATE(9,6,X7:AF7) -> 0 | AU7: =SUM(SUMIFS( INDEX( 'ETPT Format DDG'!$A:$ZZ,,MATCH("11.5. CSM",'ETPT Format DDG'!2:2,0)), INDEX( 'ETPT Format DDG'!$A:$ZZ,,MATCH("Fonction recodée",'ETPT Format DDG'!2:2,0)),"Magistrat SIEGE NS", INDEX( 'ETPT Format DDG'!$A:$ZZ,,MATCH("TJCPH",'ETPT Format DDG'!2:2,0)),"OUI")) -> #N/A | AV7: =_xlfn.AGGREGATE(9,6,AH7:AU7) -> 0 | BF7: =SUM(AW7:BE7) -> 0
A8: ETPT_TJ | D8: =$D$5 | E8: 166-06-99 | F8: Action 6 - Accueil du justiciable (inclus SAUJ) | G8: =SUM(SUMIFS( INDEX( 'ETPT Format DDG'!$A:$ZZ,,MATCH("11.51. ACCUEIL DU JUSTICIABLE (DONT SAUJ)",'ETPT Format DDG'!2:2,0)), INDEX( 'ETPT Format DDG'!$A:$ZZ,,MATCH("Fonction recodée",'ETPT Format DDG'!2:2,0)),"Fonctionnaire CTECH", INDEX( 'ETPT Format DDG'!$A:$ZZ,,MATCH("TJCPH",'ETPT Format DDG'!2:2,0)),"OUI")) -> #N/A | H8: =_xlfn.AGGREGATE(9,6,G8) -> 0 | V8: =SUM(SUMIFS( INDEX( 'ETPT Format DDG'!$A:$ZZ,,MATCH("11.51. ACCUEIL DU JUSTICIABLE (DONT SAUJ)",'ETPT Format DDG'!2:2,0)), INDEX( 'ETPT Format DDG'!$A:$ZZ,,MATCH("Fonction recodée",'ETPT Format DDG'!2:2,0)),"Fonctionnaire A-B-CBUR", INDEX( 'ETPT Format DDG'!$A:$ZZ,,MATCH("TJCPH",'ETPT Format DDG'!2:2,0)),"OUI")) -> #N/A | W8: =_xlfn.AGGREGATE(9,6,I8:V8) -> 0 | Y8: {=SUM(SUMIFS( INDEX( 'ETPT Format DDG'!$A:$ZZ,,MATCH("11.51. ACCUEIL DU JUSTICIABLE (DONT SAUJ)",'ETPT Format DDG'!2:2,0)), INDEX( 'ETPT Format DDG'!$A:$ZZ,,MATCH("Fonction",'ETPT Format DDG'!2:2,0)),{"JCP";"VPCP";"1VPCP"}, INDEX( 'ETPT Format DDG'!$A:$ZZ,,MATCH("TJCPH",'ETPT Format DDG'!2:2,0)),"OUI"))} -> #N/A | Z8: {=SUM(SUMIFS( INDEX( 'ETPT Format DDG'!$A:$ZZ,,MATCH("11.51. ACCUEIL DU JUSTICIABLE (DONT SAUJ)",'ETPT Format DDG'!2:2,0)), INDEX( 'ETPT Format DDG'!$A:$ZZ,,MATCH("Fonction",'ETPT Format DDG'!2:2,0)),{"JI";"VPI";"1VPI"}, INDEX( 'ETPT Format DDG'!$A:$ZZ,,MATCH("TJCPH",'ETPT Format DDG'!2:2,0)),"OUI"))} -> #N/A | AD8: {=SUM(SUMIFS( INDEX( 'ETPT Format DDG'!$A:$ZZ,,MATCH("11.51. ACCUEIL DU JUSTICIABLE (DONT SAUJ)",'ETPT Format DDG'!2:2,0)), INDEX( 'ETPT Format DDG'!$A:$ZZ,,MATCH("Fonction",'ETPT Format DDG'!2:2,0)),{"JAP";"VPAP";"1VPAP"}, INDEX( 'ETPT Format DDG'!$A:$ZZ,,MATCH("TJCPH",'ETPT Format DDG'!2:2,0)),"OUI"))} -> #N/A | AE8: {=SUM(SUMIFS( INDEX( 'ETPT Format DDG'!$A:$ZZ,,MATCH("11.51. ACCUEIL DU JUSTICIABLE (DONT SAUJ)",'ETPT Format DDG'!2:2,0)), INDEX( 'ETPT Format DDG'!$A:$ZZ,,MATCH("Fonction",'ETPT Format DDG'!2:2,0)),{"JE";"VPE";"1VPE"}, INDEX( 'ETPT Format DDG'!$A:$ZZ,,MATCH("TJCPH",'ETPT Format DDG'!2:2,0)),"OUI"))} -> #N/A | AF8: {=SUM(SUMIFS( INDEX( 'ETPT Format DDG'!$A:$ZZ,,MATCH("11.51. ACCUEIL DU JUSTICIABLE (DONT SAUJ)",'ETPT Format DDG'!2:2,0)), INDEX( 'ETPT Format DDG'!$A:$ZZ,,MATCH("Fonction",'ETPT Format DDG'!2:2,0)),{"VPLD";"1VPLD"}, INDEX( 'ETPT Format DDG'!$A:$ZZ,,MATCH("TJCPH",'ETPT Format DDG'!2:2,0)),"OUI"))} -> #N/A | AG8: =_xlfn.AGGREGATE(9,6,X8:AF8) -> 0 | AU8: =SUM(SUMIFS( INDEX( 'ETPT Format DDG'!$A:$ZZ,,MATCH("11.51. ACCUEIL DU JUSTICIABLE (DONT SAUJ)",'ETPT Format DDG'!2:2,0)), INDEX( 'ETPT Format DDG'!$A:$ZZ,,MATCH("Fonction recodée",'ETPT Format DDG'!2:2,0)),"Magistrat SIEGE NS", INDEX( 'ETPT Format DDG'!$A:$ZZ,,MATCH("TJCPH",'ETPT Format DDG'!2:2,0)),"OUI")) -> #N/A | AV8: =_xlfn.AGGREGATE(9,6,AH8:AU8) -> 0 | BF8: =SUM(AW8:BE8) -> 0
A9: ETPT_TJ | D9: =$D$5 | E9: 166-06-NC | F9: Action 6 - Soutien (Hors accueil du justiciable) | G9: =SUM(SUMIFS( INDEX( 'ETPT Format DDG'!$A:$ZZ,,MATCH("11.1. SOUTIEN (HORS FORMATIONS SUIVIES)",'ETPT Format DDG'!2:2,0)), INDEX( 'ETPT Format DDG'!$A:$ZZ,,MATCH("Fonction recodée",'ETPT Format DDG'!2:2,0)),"Fonctionnaire CTECH", INDEX( 'ETPT Format DDG'!$A:$ZZ,,MATCH("TJCPH",'ETPT Format DDG'!2:2,0)),"OUI"))+ SUM(SUMIFS( INDEX( 'ETPT Format DDG'!$A:$ZZ,,MATCH("11.2. FORMATIONS SUIVIES",'ETPT Format DDG'!2:2,0)), INDEX( 'ETPT Format DDG'!$A:$ZZ,,MATCH("Fonction recodée",'ETPT Format DDG'!2:2,0)),"Fonctionnaire CTECH", INDEX( 'ETPT Format DDG'!$A:$ZZ,,MATCH("TJCPH",'ETPT Format DDG'!2:2,0)),"OUI"))+ SUM(SUMIFS( INDEX( 'ETPT Format DDG'!$A:$ZZ,,MATCH("11.6. AUTRES ACTIVITÉS NON JURIDICTIONNELLES",'ETPT Format DDG'!2:2,0)), INDEX( 'ETPT Format DDG'!$A:$ZZ,,MATCH("Fonction recodée",'ETPT Format DDG'!2:2,0)),"Fonctionnaire CTECH", INDEX( 'ETPT Format DDG'!$A:$ZZ,,MATCH("TJCPH",'ETPT Format DDG'!2:2,0)),"OUI")) -> #N/A | H9: =_xlfn.AGGREGATE(9,6,G9) -> 0 | V9: =SUM(SUMIFS( INDEX( 'ETPT Format DDG'!$A:$ZZ,,MATCH("11.1. SOUTIEN (HORS FORMATIONS SUIVIES)",'ETPT Format DDG'!2:2,0)), INDEX( 'ETPT Format DDG'!$A:$ZZ,,MATCH("Fonction recodée",'ETPT Format DDG'!2:2,0)),"Fonctionnaire A-B-CBUR", INDEX( 'ETPT Format DDG'!$A:$ZZ,,MATCH("TJCPH",'ETPT Format DDG'!2:2,0)),"OUI"))+ SUM(SUMIFS( INDEX( 'ETPT Format DDG'!$A:$ZZ,,MATCH("11.2. FORMATIONS SUIVIES",'ETPT Format DDG'!2:2,0)), INDEX( 'ETPT Format DDG'!$A:$ZZ,,MATCH("Fonction recodée",'ETPT Format DDG'!2:2,0)),"Fonctionnaire A-B-CBUR", INDEX( 'ETPT Format DDG'!$A:$ZZ,,MATCH("TJCPH",'ETPT Format DDG'!2:2,0)),"OUI"))+ SUM(SUMIFS( INDEX( 'ETPT Format DDG'!$A:$ZZ,,MATCH("11.6. AUTRES ACTIVITÉS NON JURIDICTIONNELLES",'ETPT Format DDG'!2:2,0)), INDEX( 'ETPT Format DDG'!$A:$ZZ,,MATCH("Fonction recodée",'ETPT Format DDG'!2:2,0)),"Fonctionnaire A-B-CBUR", INDEX( 'ETPT Format DDG'!$A:$ZZ,,MATCH("TJCPH",'ETPT Format DDG'!2:2,0)),"OUI")) -> #N/A | W9: =_xlfn.AGGREGATE(9,6,I9:V9) -> 0 | Y9: {=SUM(SUMIFS( INDEX( 'ETPT Format DDG'!$A:$ZZ,,MATCH("11.1. SOUTIEN (HORS FORMATIONS SUIVIES)",'ETPT Format DDG'!2:2,0)), INDEX( 'ETPT Format DDG'!$A:$ZZ,,MATCH("Fonction",'ETPT Format DDG'!2:2,0)),{"JCP";"VPCP";"1VPCP"}, INDEX( 'ETPT Format DDG'!$A:$ZZ,,MATCH("TJCPH",'ETPT Format DDG'!2:2,0)),"OUI"))+ SUM(SUMIFS( INDEX( 'ETPT Format DDG'!$A:$ZZ,,MATCH("11.2. FORMATIONS SUIVIES",'ETPT Format DDG'!2:2,0)), INDEX( 'ETPT Format DDG'!$A:$ZZ,,MATCH("Fonction",'ETPT Format DDG'!2:2,0)),{"JCP";"VPCP";"1VPCP"}, INDEX( 'ETPT Format DDG'!$A:$ZZ,,MATCH("TJCPH",'ETPT Format DDG'!2:2,0)),"OUI"))+ SUM(SUMIFS( INDEX( 'ETPT Format DDG'!$A:$ZZ,,MATCH("11.6. AUTRES ACTIVITÉS NON JURIDICTIONNELLES",'ETPT Format DDG'!2:2,0)), INDEX( 'ETPT Format DDG'!$A:$ZZ,,MATCH("Fonction",'ETPT Format DDG'!2:2,0)),{"JCP";"VPCP";"1VPCP"}, INDEX( 'ETPT Format DDG'!$A:$ZZ,,MATCH("TJCPH",'ETPT Format DDG'!2:2,0)),"OUI"))} -> #N/A | Z9: {=SUM(SUMIFS( INDEX( 'ETPT Format DDG'!$A:$ZZ,,MATCH("11.1. SOUTIEN (HORS FORMATIONS SUIVIES)",'ETPT Format DDG'!2:2,0)), INDEX( 'ETPT Format DDG'!$A:$ZZ,,MATCH("Fonction",'ETPT Format DDG'!2:2,0)),{"JI";"VPI";"1VPI"}, INDEX( 'ETPT Format DDG'!$A:$ZZ,,MATCH("TJCPH",'ETPT Format DDG'!2:2,0)),"OUI"))+ SUM(SUMIFS( INDEX( 'ETPT Format DDG'!$A:$ZZ,,MATCH("11.2. FORMATIONS SUIVIES",'ETPT Format DDG'!2:2,0)), INDEX( 'ETPT Format DDG'!$A:$ZZ,,MATCH("Fonction",'ETPT Format DDG'!2:2,0)),{"JI";"VPI";"1VPI"}, INDEX( 'ETPT Format DDG'!$A:$ZZ,,MATCH("TJCPH",'ETPT Format DDG'!2:2,0)),"OUI"))+ SUM(SUMIFS( INDEX( 'ETPT Format DDG'!$A:$ZZ,,MATCH("11.6. AUTRES ACTIVITÉS NON JURIDICTIONNELLES",'ETPT Format DDG'!2:2,0)), INDEX( 'ETPT Format DDG'!$A:$ZZ,,MATCH("Fonction",'ETPT Format DDG'!2:2,0)),{"JI";"VPI";"1VPI"}, INDEX( 'ETPT Format DDG'!$A:$ZZ,,MATCH("TJCPH",'ETPT Format DDG'!2:2,0)),"OUI"))} -> #N/A | AD9: {=SUM(SUMIFS( INDEX( 'ETPT Format DDG'!$A:$ZZ,,MATCH("11.1. SOUTIEN (HORS FORMATIONS SUIVIES)",'ETPT Format DDG'!2:2,0)), INDEX( 'ETPT Format DDG'!$A:$ZZ,,MATCH("Fonction",'ETPT Format DDG'!2:2,0)),{"JAP";"VPAP";"1VPAP"}, INDEX( 'ETPT Format DDG'!$A:$ZZ,,MATCH("TJCPH",'ETPT Format DDG'!2:2,0)),"OUI"))+ SUM(SUMIFS( INDEX( 'ETPT Format DDG'!$A:$ZZ,,MATCH("11.2. FORMATIONS SUIVIES",'ETPT Format DDG'!2:2,0)), INDEX( 'ETPT Format DDG'!$A:$ZZ,,MATCH("Fonction",'ETPT Format DDG'!2:2,0)),{"JAP";"VPAP";"1VPAP"}, INDEX( 'ETPT Format DDG'!$A:$ZZ,,MATCH("TJCPH",'ETPT Format DDG'!2:2,0)),"OUI"))+ SUM(SUMIFS( INDEX( 'ETPT Format DDG'!$A:$ZZ,,MATCH("11.6. AUTRES ACTIVITÉS NON JURIDICTIONNELLES",'ETPT Format DDG'!2:2,0)), INDEX( 'ETPT Format DDG'!$A:$ZZ,,MATCH("Fonction",'ETPT Format DDG'!2:2,0)),{"JAP";"VPAP";"1VPAP"}, INDEX( 'ETPT Format DDG'!$A:$ZZ,,MATCH("TJCPH",'ETPT Format DDG'!2:2,0)),"OUI"))} -> #N/A | AE9: {=SUM(SUMIFS( INDEX( 'ETPT Format DDG'!$A:$ZZ,,MATCH("11.1. SOUTIEN (HORS FORMATIONS SUIVIES)",'ETPT Format DDG'!2:2,0)), INDEX( 'ETPT Format DDG'!$A:$ZZ,,MATCH("Fonction",'ETPT Format DDG'!2:2,0)),{"JE";"VPE";"1VPE"}, INDEX( 'ETPT Format DDG'!$A:$ZZ,,MATCH("TJCPH",'ETPT Format DDG'!2:2,0)),"OUI"))+ SUM(SUMIFS( INDEX( 'ETPT Format DDG'!$A:$ZZ,,MATCH("11.2. FORMATIONS SUIVIES",'ETPT Format DDG'!2:2,0)), INDEX( 'ETPT Format DDG'!$A:$ZZ,,MATCH("Fonction",'ETPT Format DDG'!2:2,0)),{"JE";"VPE";"1VPE"}, INDEX( 'ETPT Format DDG'!$A:$ZZ,,MATCH("TJCPH",'ETPT Format DDG'!2:2,0)),"OUI"))+ SUM(SUMIFS( INDEX( 'ETPT Format DDG'!$A:$ZZ,,MATCH("11.6. AUTRES ACTIVITÉS NON JURIDICTIONNELLES",'ETPT Format DDG'!2:2,0)), INDEX( 'ETPT Format DDG'!$A:$ZZ,,MATCH("Fonction",'ETPT Format DDG'!2:2,0)),{"JE";"VPE";"1VPE"}, INDEX( 'ETPT Format DDG'!$A:$ZZ,,MATCH("TJCPH",'ETPT Format DDG'!2:2,0)),"OUI"))} -> #N/A | AF9: {=SUM(SUMIFS( INDEX( 'ETPT Format DDG'!$A:$ZZ,,MATCH("11.1. SOUTIEN (HORS FORMATIONS SUIVIES)",'ETPT Format DDG'!2:2,0)), INDEX( 'ETPT Format DDG'!$A:$ZZ,,MATCH("Fonction",'ETPT Format DDG'!2:2,0)),{"VPLD";"1VPLD"}, INDEX( 'ETPT Format DDG'!$A:$ZZ,,MATCH("TJCPH",'ETPT Format DDG'!2:2,0)),"OUI"))+ SUM(SUMIFS( INDEX( 'ETPT Format DDG'!$A:$ZZ,,MATCH("11.2. FORMATIONS SUIVIES",'ETPT Format DDG'!2:2,0)), INDEX( 'ETPT Format DDG'!$A:$ZZ,,MATCH("Fonction",'ETPT Format DDG'!2:2,0)),{"VPLD";"1VPLD"}, INDEX( 'ETPT Format DDG'!$A:$ZZ,,MATCH("TJCPH",'ETPT Format DDG'!2:2,0)),"OUI"))+ SUM(SUMIFS( INDEX( 'ETPT Format DDG'!$A:$ZZ,,MATCH("11.6. AUTRES ACTIVITÉS NON JURIDICTIONNELLES",'ETPT Format DDG'!2:2,0)), INDEX( 'ETPT Format DDG'!$A:$ZZ,,MATCH("Fonction",'ETPT Format DDG'!2:2,0)),{"VPLD";"1VPLD"}, INDEX( 'ETPT Format DDG'!$A:$ZZ,,MATCH("TJCPH",'ETPT Format DDG'!2:2,0)),"OUI"))} -> #N/A | AG9: =_xlfn.AGGREGATE(9,6,X9:AF9) -> 0 | AU9: =SUM(SUMIFS( INDEX( 'ETPT Format DDG'!$A:$ZZ,,MATCH("11.1. SOUTIEN (HORS FORMATIONS SUIVIES)",'ETPT Format DDG'!2:2,0)), INDEX( 'ETPT Format DDG'!$A:$ZZ,,MATCH("Fonction recodée",'ETPT Format DDG'!2:2,0)),"Magistrat SIEGE NS", INDEX( 'ETPT Format DDG'!$A:$ZZ,,MATCH("TJCPH",'ETPT Format DDG'!2:2,0)),"OUI"))+ SUM(SUMIFS( INDEX( 'ETPT Format DDG'!$A:$ZZ,,MATCH("11.2. FORMATIONS SUIVIES",'ETPT Format DDG'!2:2,0)), INDEX( 'ETPT Format DDG'!$A:$ZZ,,MATCH("Fonction recodée",'ETPT Format DDG'!2:2,0)),"Magistrat SIEGE NS", INDEX( 'ETPT Format DDG'!$A:$ZZ,,MATCH("TJCPH",'ETPT Format DDG'!2:2,0)),"OUI"))+ SUM(SUMIFS( INDEX( 'ETPT Format DDG'!$A:$ZZ,,MATCH("11.6. AUTRES ACTIVITÉS NON JURIDICTIONNELLES",'ETPT Format DDG'!2:2,0)), INDEX( 'ETPT Format DDG'!$A:$ZZ,,MATCH("Fonction recodée",'ETPT Format DDG'!2:2,0)),"Magistrat SIEGE NS", INDEX( 'ETPT Format DDG'!$A:$ZZ,,MATCH("TJCPH",'ETPT Format DDG'!2:2,0)),"OUI")) -> #N/A | AV9: =_xlfn.AGGREGATE(9,6,AH9:AU9) -> 0 | BF9: =SUM(AW9:BE9) -> 0
A10: ETPT_TJ | D10: =$D$5 | E10: 166-07-NC | F10: Action 7 - Formation dispensée | G10: =SUM(SUMIFS( INDEX( 'ETPT Format DDG'!$A:$ZZ,,MATCH("11.3. FORMATIONS DISPENSÉES",'ETPT Format DDG'!2:2,0)), INDEX( 'ETPT Format DDG'!$A:$ZZ,,MATCH("Fonction recodée",'ETPT Format DDG'!2:2,0)),"Fonctionnaire CTECH", INDEX( 'ETPT Format DDG'!$A:$ZZ,,MATCH("TJCPH",'ETPT Format DDG'!2:2,0)),"OUI")) -> #N/A | H10: =_xlfn.AGGREGATE(9,6,G10) -> 0 | V10: =SUM(SUMIFS( INDEX( 'ETPT Format DDG'!$A:$ZZ,,MATCH("11.3. FORMATIONS DISPENSÉES",'ETPT Format DDG'!2:2,0)), INDEX( 'ETPT Format DDG'!$A:$ZZ,,MATCH("Fonction recodée",'ETPT Format DDG'!2:2,0)),"Fonctionnaire A-B-CBUR", INDEX( 'ETPT Format DDG'!$A:$ZZ,,MATCH("TJCPH",'ETPT Format DDG'!2:2,0)),"OUI")) -> #N/A | W10: =_xlfn.AGGREGATE(9,6,I10:V10) -> 0 | Y10: {=SUM(SUMIFS( INDEX( 'ETPT Format DDG'!$A:$ZZ,,MATCH("11.3. FORMATIONS DISPENSÉES",'ETPT Format DDG'!2:2,0)), INDEX( 'ETPT Format DDG'!$A:$ZZ,,MATCH("Fonction",'ETPT Format DDG'!2:2,0)),{"JCP";"VPCP";"1VPCP"}, INDEX( 'ETPT Format DDG'!$A:$ZZ,,MATCH("TJCPH",'ETPT Format DDG'!2:2,0)),"OUI"))} -> #N/A | Z10: {=SUM(SUMIFS( INDEX( 'ETPT Format DDG'!$A:$ZZ,,MATCH("11.3. FORMATIONS DISPENSÉES",'ETPT Format DDG'!2:2,0)), INDEX( 'ETPT Format DDG'!$A:$ZZ,,MATCH("Fonction",'ETPT Format DDG'!2:2,0)),{"JI";"VPI";"1VPI"}, INDEX( 'ETPT Format DDG'!$A:$ZZ,,MATCH("TJCPH",'ETPT Format DDG'!2:2,0)),"OUI"))} -> #N/A | AD10: {=SUM(SUMIFS( INDEX( 'ETPT Format DDG'!$A:$ZZ,,MATCH("11.3. FORMATIONS DISPENSÉES",'ETPT Format DDG'!2:2,0)), INDEX( 'ETPT Format DDG'!$A:$ZZ,,MATCH("Fonction",'ETPT Format DDG'!2:2,0)),{"JAP";"VPAP";"1VPAP"}, INDEX( 'ETPT Format DDG'!$A:$ZZ,,MATCH("TJCPH",'ETPT Format DDG'!2:2,0)),"OUI"))} -> #N/A | AE10: {=SUM(SUMIFS( INDEX( 'ETPT Format DDG'!$A:$ZZ,,MATCH("11.3. FORMATIONS DISPENSÉES",'ETPT Format DDG'!2:2,0)), INDEX( 'ETPT Format DDG'!$A:$ZZ,,MATCH("Fonction",'ETPT Format DDG'!2:2,0)),{"JE";"VPE";"1VPE"}, INDEX( 'ETPT Format DDG'!$A:$ZZ,,MATCH("TJCPH",'ETPT Format DDG'!2:2,0)),"OUI"))} -> #N/A | AF10: {=SUM(SUMIFS( INDEX( 'ETPT Format DDG'!$A:$ZZ,,MATCH("11.3. FORMATIONS DISPENSÉES",'ETPT Format DDG'!2:2,0)), INDEX( 'ETPT Format DDG'!$A:$ZZ,,MATCH("Fonction",'ETPT Format DDG'!2:2,0)),{"VPLD";"1VPLD"}, INDEX( 'ETPT Format DDG'!$A:$ZZ,,MATCH("TJCPH",'ETPT Format DDG'!2:2,0)),"OUI"))} -> #N/A | AG10: =_xlfn.AGGREGATE(9,6,X10:AF10) -> 0 | AU10: =SUM(SUMIFS( INDEX( 'ETPT Format DDG'!$A:$ZZ,,MATCH("11.3. FORMATIONS DISPENSÉES",'ETPT Format DDG'!2:2,0)), INDEX( 'ETPT Format DDG'!$A:$ZZ,,MATCH("Fonction recodée",'ETPT Format DDG'!2:2,0)),"Magistrat SIEGE NS", INDEX( 'ETPT Format DDG'!$A:$ZZ,,MATCH("TJCPH",'ETPT Format DDG'!2:2,0)),"OUI")) -> #N/A | AV10: =_xlfn.AGGREGATE(9,6,AH10:AU10) -> 0 | BF10: =SUM(AW10:BE10) -> 0
