Workbook

Sheet ACCUEIL
C1: Bienvenue dans l'extraction de vos données d'effectifs ! | H1: #! END_ROW
C2: Ce fichier Excel a été extrait automatiquement de votre application A-JUST CA. Retrouvez ci-dessous quelques indications pour y naviguer en toute fluidité. | H2: #! END_ROW
H3: #! END_ROW
B4: Nom de l'onglet | C4: Description rapide | D4: Usage | E4: Pour une présentation complète | H4: #! END_ROW
B5: ETPT A-JUST | C5: Retrouvez le détail des ventilations individuelles de chaque agent, agrégées sur la période pour laquelle vous avez extrait les données, à l'identique de ce que vous avez renseigné dans A-JUST. | D5: Tout au long de l'année, consultez le détail des affectations de chaque agent, calculées en ETPT, pour la période choisie. | E5: #! HYPERLINK firstLink.label firstLink.url | H5: #! END_ROW
B6: ETPT Format DDG | C6: Vous y trouverez les données individuelles, retraitées conformément aux règles de calcul de la Chancellerie, en procédant à la réintégration de certaines indisponibilités considérées comme de l'absentéisme, ne déduisant pas d'ETPT. | D6: Afin de préparer la collecte de vos ETPT dans les matrices de la DSJ certaines précisions doivent être apportées dans cet onglet. | E6: #! HYPERLINK secondLink.label secondLink.url | H6: #! END_ROW
B7: Synthèse ETPT | C7: Cette synthèse présente les ETPT affectés, par catégorie d'agent, à chaque contentieux ou sous-contentieux, l'absentéisme étant réintégré comme dans l'onglet "ETPT Format DDG". | D7: N'hésitez pas à la consulter toute l'année, pour les périodes de votre choix. | E7: #! HYPERLINK firstLink.label firstLink.url | H7: #! END_ROW
B8: ETPT_CA_DDG | C8: Les tableaux de la Chancellerie, préremplis grâce aux informations saisies dans A-JUST et aux précisions apportées dans l'onglet ETPT Format DDG. | D8: Ces données sont prérenseignées dans les tableaux de collecte des ETPT de la Chancellerie mais restent soumises à votre contrôle et éventuels ajustements avant transmission. | E8: #! HYPERLINK thirdLink.label thirdLink.url | H8: #! END_ROW
B9: ETPT_ATTACHES_JUSTICE_DDG | H9: #! END_ROW
H10: #! END_ROW
C11: Ce fichier, permettant de remplir automatiquement les tableaux de collecte d'ETPT de la Chancellerie à partir des données A-JUST, résulte de la collaboration de l'équipe de la start-up d'Etat A-JUST avec Mme Nathalie DE JONG, statisticienne du SAIR de la Cour d'Appel de LYON. Qu'elle soit ici vivement remerciée, ainsi que sa hiérarchie qui l'a autorisée à consacrer un temps aussi précieux qu'irremplaçable à écrire les formules de calcul permettant d'automatiser l'alimentation des tableaux DDG et faire ainsi gagner à nos utilisateurs un temps considérable chaque année. | H11: #! END_ROW
H12: #! END_ROW
A13: Pour toute question, n'hésitez pas à contacter l'équipe A-JUST : support-utilisateurs@a-just.fr | H13: #! END_ROW
H14: #! FINISH

Sheet ETPT A-JUST
A1: Extracteur de données d'effectifs | G1: #! DUMP_COLS subtitles | H1: #! END_ROW
A2: #! DUMP_COLS days | B2: #! FOR_EACH w stats
A3: #! DUMP_COLS w.actions | B3: #! CONTINUE w
A4: #! DUMP_COLS w.actions | B4: #! END_LOOP w
B5: #! FINISH

Sheet ETPT Format DDG
D1: Extracteur de données d'effectifs - Format DDG (avec réintégration de l'absentéisme) Les lignes en rouge invitent à des vérifications dans les colonnes R et S. Veillez à ne pas supprimer de ligne dans le tableau. | R1: #! DUMP_COLS subtitles1 | S1: #! END_ROW | FA1: #! END_ROW | FB1: #! END_ROW
A2: #! DUMP_COLS days1 | B2: #! FOR_EACH x stats1
A3: #! DUMP_COLS x.actions | B3: #! END_LOOP x
B4: #! FINISH

Sheet Synthèse ETPT
C1: Agrégats DDG | D1: Synthèse ETPT | J1: #! DUMP_COLS subtitles | K1: #! END_ROW
A2: Selectionner une juridiction | B2: Code | C2: #! END_ROW
A3: #` ${arrondissement} | B3: =VLOOKUP(A3,'codage tribunal'!A:B,2,FALSE) -> #N/A | C3: #! END_ROW
G4: SIEGE | N4: GREFFE | U4: EQUIPE AUTOUR DU MAGISTRAT | X4: #! END_ROW
G5: Magistrats hors placés | H5: %age de l'ETPT | I5: Magistrats placés additionnels | J5: Magistrats placés de substitution | K5: Contractuels et vacataires | L5: TOTAL SIEGE | M5: %age de l'ETPT | N5: Fonctionnaires hors placés | O5: %age de l'ETPT | P5: Fonctionnaires placés additionnels | Q5: Fonctionnaires placés de substitution | R5: Contractuels et vacataires | S5: TOTAL GREFFE | T5: %age de l'ETPT | U5: Contractuels et vacataires | V5: %age de l'ETPT | W5: #! FOR_EACH y agregat
C6: ## y.global | D6: ## y.global1 | E6: ## y.sub | F6: ## y.sub1 | G6: =SUMIFS( INDEX('ETPT Format DDG'!$A:$ZZ,,IFERROR(MATCH(E6,'ETPT Format DDG'!$2:$2,0),MATCH(C6,'ETPT Format DDG'!$2:$2,0))), INDEX( 'ETPT Format DDG'!$A:$ZZ,,MATCH("Fonction agrégat",'ETPT Format DDG'!2:2,0)),"M-TIT") -> #N/A | H6: =IF(AND(OR(LEFT(C6,3)="14.",LEFT(E6,3)="14.",LEFT(E6,5)="CET >", IFERROR(G6/$G$6,"")=0),NOT(AND(LEFT(E6,4)="14.4",IFERROR(G6/$G$6,"")<>0)),NOT(AND(LEFT(E6,4)="14.5",IFERROR(G6/$G$6,"")<>0)),NOT(AND(LEFT(E6,5)="14.14",IFERROR(G6/$G$6,"")<>0))),"", IFERROR(G6/$G$6,"")) | I6: =SUMIFS( INDEX('ETPT Format DDG'!$A:$ZZ,,IFERROR(MATCH(E6,'ETPT Format DDG'!$2:$2,0),MATCH(C6,'ETPT Format DDG'!$2:$2,0))), INDEX( 'ETPT Format DDG'!$A:$ZZ,,MATCH("Fonction agrégat",'ETPT Format DDG'!2:2,0)),"M-PLAC-ADD") -> #N/A | J6: =SUMIFS( INDEX('ETPT Format DDG'!$A:$ZZ,,IFERROR(MATCH(E6,'ETPT Format DDG'!$2:$2,0),MATCH(C6,'ETPT Format DDG'!$2:$2,0))), INDEX( 'ETPT Format DDG'!$A:$ZZ,,MATCH("Fonction agrégat",'ETPT Format DDG'!2:2,0)),"M-PLAC-SUB") -> #N/A | K6: =SUMIFS( INDEX('ETPT Format DDG'!$A:$ZZ,,IFERROR(MATCH(E6,'ETPT Format DDG'!$2:$2,0),MATCH(C6,'ETPT Format DDG'!$2:$2,0))), INDEX( 'ETPT Format DDG'!$A:$ZZ,,MATCH("Fonction agrégat",'ETPT Format DDG'!2:2,0)),"M-CONT", INDEX( 'ETPT Format DDG'!$A:$ZZ,,MATCH("Catégorie",'ETPT Format DDG'!2:2,0)),"Magistrat") -> #N/A | L6: =SUMIFS( INDEX('ETPT Format DDG'!$A:$ZZ,,IFERROR(MATCH(E6,'ETPT Format DDG'!$2:$2,0),MATCH(C6,'ETPT Format DDG'!$2:$2,0))), INDEX( 'ETPT Format DDG'!$A:$ZZ,,MATCH("Catégorie",'ETPT Format DDG'!2:2,0)),"Magistrat") -> #N/A | M6: =IF(AND(OR(LEFT(C6,3)="14.",LEFT(E6,3)="14.",LEFT(E6,5)="CET >", IFERROR(L6/$L$6,"")=0),NOT(AND(LEFT(E6,4)="14.4",IFERROR(L6/$G$6,"")<>0)),NOT(AND(LEFT(E6,4)="14.5",IFERROR(L6/$G$6,"")<>0)),NOT(AND(LEFT(E6,5)="14.14",IFERROR(L6/$G$6,"")<>0))),"", IFERROR(L6/$L$6,"")) | N6: =SUMIFS( INDEX('ETPT Format DDG'!$A:$ZZ,,IFERROR(MATCH(E6,'ETPT Format DDG'!$2:$2,0),MATCH(C6,'ETPT Format DDG'!$2:$2,0))), INDEX( 'ETPT Format DDG'!$A:$ZZ,,MATCH("Fonction agrégat",'ETPT Format DDG'!2:2,0)),"F-TIT") -> #N/A | O6: =IF(AND(OR(LEFT(C6,3)="14.",LEFT(E6,3)="14.",LEFT(E6,5)="CET >", IFERROR(N6/$N$6,"")=0),NOT(AND(LEFT(E6,4)="14.4",IFERROR(N6/$N$6,"")<>0)),NOT(AND(LEFT(E6,4)="14.5",IFERROR(N6/$N$6,"")<>0)),NOT(AND(LEFT(E6,5)="14.14",IFERROR(N6/$N$6,"")<>0))),"", IFERROR(N6/$N$6,"")) | P6: =SUMIFS( INDEX('ETPT Format DDG'!$A:$FB,,IFERROR(MATCH(E6,'ETPT Format DDG'!$2:$2,0),MATCH(C6,'ETPT Format DDG'!$2:$2,0))), INDEX( 'ETPT Format DDG'!$A:$ZZ,,MATCH("Fonction agrégat",'ETPT Format DDG'!2:2,0)),"F-PLAC-ADD") -> #N/A | Q6: =SUMIFS( INDEX('ETPT Format DDG'!$A:$FB,,IFERROR(MATCH(E6,'ETPT Format DDG'!$2:$2,0),MATCH(C6,'ETPT Format DDG'!$2:$2,0))), INDEX( 'ETPT Format DDG'!$A:$ZZ,,MATCH("Fonction agrégat",'ETPT Format DDG'!2:2,0)),"F-PLAC-SUB") -> #N/A | R6: =SUMIFS( INDEX('ETPT Format DDG'!$A:$FB,,IFERROR(MATCH(E6,'ETPT Format DDG'!$2:$2,0),MATCH(C6,'ETPT Format DDG'!$2:$2,0))), INDEX( 'ETPT Format DDG'!$A:$ZZ,,MATCH("Fonction agrégat",'ETPT Format DDG'!2:2,0)),"C", INDEX( 'ETPT Format DDG'!$A:$ZZ,,MATCH("Catégorie",'ETPT Format DDG'!2:2,0)),"Greffe") -> #N/A | S6: =SUMIFS( INDEX('ETPT Format DDG'!$A:$FB,,IFERROR(MATCH(E6,'ETPT Format DDG'!$2:$2,0),MATCH(C6,'ETPT Format DDG'!$2:$2,0))), INDEX( 'ETPT Format DDG'!$A:$ZZ,,MATCH("Catégorie",'ETPT Format DDG'!2:2,0)),"Greffe") -> #N/A | T6: =IF(AND(OR(LEFT(C6,3)="14.",LEFT(E6,3)="14.",LEFT(E6,5)="CET >", IFERROR(S6/$S$6,"")=0),NOT(AND(LEFT(E6,4)="14.4",IFERROR(S6/$S$6,"")<>0)),NOT(AND(LEFT(E6,4)="14.5",IFERROR(S6/$S$6,"")<>0)),NOT(AND(LEFT(E6,5)="14.14",IFERROR(S6/$S$6,"")<>0))),"", IFERROR(S6/$S$6,"")) | U6: =SUMIFS( INDEX('ETPT Format DDG'!$A:$FB,,IFERROR(MATCH(E6,'ETPT Format DDG'!$2:$2,0),MATCH(C6,'ETPT Format DDG'!$2:$2,0))), INDEX( 'ETPT Format DDG'!$A:$ZZ,,MATCH("Fonction agrégat",'ETPT Format DDG'!2:2,0)),"C", INDEX( 'ETPT Format DDG'!$A:$ZZ,,MATCH("Catégorie",'ETPT Format DDG'!2:2,0)),"Autour du magistrat") -> #N/A | V6: =IF(AND(OR(LEFT(C6,3)="14.",LEFT(E6,3)="14.",LEFT(E6,5)="CET >", IFERROR(U6/$U$6,"")=0),NOT(AND(LEFT(E6,4)="14.4",IFERROR(U6/$U$6,"")<>0)),NOT(AND(LEFT(E6,4)="14.5",IFERROR(U6/$U$6,"")<>0)),NOT(AND(LEFT(E6,5)="14.14",IFERROR(U6/$U$6,"")<>0))),"", IFERROR(U6/$U$6,"")) | W6: #! END_LOOP y
W7: #! FINISH

Sheet ETPT Format DDG DETAIL
A1: Réf. | B1: Nom/Prénom/Matricule | C1: Catégorie | D1: Date d'arrivée | E1: Date de départ | G1: Date de début du segment | H1: Date de fin du segment | I1: Nombre jour ouvré sur période total extaction | J1: Nombre jour ouvré segment | K1: Ratio Jour : Nb jour ouvré segment / Nb jour ouvré total | L1: Temps de travail en ETPT saisie | M1: Valeur de l'ETPT sur période total d'extraction (ETPT saisi x Ratio Jour) | N1: Indisponibilité saisie | O1: Valeur de l'indisponibilité sur la période total d'extraction (Indisponibilité saisie en%/100 x Ratio Jour) | P1: Nb jour ouvré CET sur toute la période d'extraction | Q1: Valeur de l'absentéisme | R1: Valeur de l'action 99 | S1: ETPT effectif sur la période total (ETPT- action 99 + absentéisme) x Ratio Jour | T1: ETPT global sur la période (incluant absentéisme et action 99) | U1: ETPT ventilé | V1: Détails de la ventilation (arrondi au millième) : | W1: #! FOR_EACH log ongletLogs
A2: ## log.id | B2: ## log.name | C2: ## log.category | D2: ## log.humanStart | E2: ## log.humanEnd | F2: ## log.main | G2: ## log.periodStart | H2: ## log.periodEnd | I2: ## log.nbOfWorkingDaysQuery | J2: ## log.workingDays | K2: ## log.dayRate | L2: ## log.filledEtp | M2: ## log.queryEtpValue | N2: ## log.totalIndispo | O2: ## log.queryIndispoValue | P2: ## log.cetDays | Q2: ## log.abs | R2: ## log.action99 | S2: ## log.effectifEtp | T2: ## log.etptGlobal | U2: ## log.logAccVentilation | V2: ## log.ctx | W2: #! END_LOOP log
W3: #! FINISH

Sheet codage tribunal
L1: #! END_ROW
L2: #! END_ROW
L3: #! END_ROW
L4: #! END_ROW
L5: #! END_ROW
L6: #! END_ROW
L7: #! END_ROW
L8: #! END_ROW
L9: #! END_ROW
L10: #! END_ROW
L11: #! END_ROW
L12: #! END_ROW
... L19: #! FINISH

Sheet Juridictions
A1: TJ | D1: TPROX | G1: CPH | I1: CPH détachés | M1: #! END_ROW
M2: #! END_ROW
M3: #! END_ROW
M4: #! END_ROW
M5: #! END_ROW
M6: #! END_ROW
M7: #! END_ROW
M8: #! END_ROW
M9: #! END_ROW
M10: #! END_ROW
M11: #! END_ROW
M12: #! END_ROW
M13: #! END_ROW
... M19: #! FINISH

Sheet Table_Fonctions
A1: CONCAT | B1: Catégorie | C1: Label | D1: Position | E1: Code | F1: Fonction recodée DDG | G1: Fonction onglet agrégat | H1: #! FOR_EACH f fonctions
A2: ## f.CONCAT | B2: ## f.category_label | C2: ## f.label | D2: ## f.position | E2: ## f.code | F2: ## f.recodedFunction | G2: ## f.category_detail | H2: #! END_LOOP f
H3: #! FINISH

Sheet ETPT_CA_JUR
A1: Agrégats DDG | D1: Déclaration des ETPT CA
B2: UO | C2: Code de la juridiction | D2: Juridiction | E2: Code sous action | F2: Action | G2: Fonctionnaires Catégorie C Technique spécialisés | H2: Total fonctionnaires techniques | I2: Fonctionnaires activité civile et commerciale du parquet | J2: Fonctionnaires Assises | K2: Fonctionnaires Cour criminelle | L2: Fonctionnaires JIRS | M2: Fonctionnaires chambres sociales | N2: Fonctionnaires hors fonctions spécifiques | O2: Total fonctionnaires administratifs | P2: Magistrats du Siège assises | Q2: Magistrats du siège Cour criminelle | R2: Autres Magistrats du Siège JIRS | S2: Magistrats du Siège chambres sociales | T2: Autres Magistrats du Siège non spécialisés | U2: Total magistrats du siège non spécialisés | V2: Magistrats du Parquet - activité civile et commerciale | W2: Magistrats du Parquet JIRS | X2: Magistrats du Parquet assises | Y2: Magistrats du Parquet Cour criminelle | Z2: Autres Magistrats du Parquet | AA2: Total magistrats du parquet
D3: =ETPT_CA_JUR_DDG!$D$5 | E3: 166-01-NC | F3: Action 1 - Traitement et jugement des contentieux civils | G3: =SUM(SUMIFS( INDEX( 'ETPT Format DDG'!$A:$ZZ,,MATCH("1. TOTAL CONTENTIEUX SOCIAL",'ETPT Format DDG'!2:2,0)), INDEX( 'ETPT Format DDG'!$A:$ZZ,,MATCH("Fonction recodée",'ETPT Format DDG'!2:2,0)),"Fonctionnaire CTECH"))+ SUM(SUMIFS( INDEX( 'ETPT Format DDG'!$A:$ZZ,,MATCH("2. TOTAL CONTENTIEUX COMMERCIAL",'ETPT Format DDG'!2:2,0)), INDEX( 'ETPT Format DDG'!$A:$ZZ,,MATCH("Fonction recodée",'ETPT Format DDG'!2:2,0)),"Fonctionnaire CTECH"))+ SUM(SUMIFS( INDEX( 'ETPT Format DDG'!$A:$ZZ,,MATCH("3. TOTAL CONTENTIEUX DE LA FAMILLE",'ETPT Format DDG'!2:2,0)), INDEX( 'ETPT Format DDG'!$A:$ZZ,,MATCH("Fonction recodée",'ETPT Format DDG'!2:2,0)),"Fonctionnaire CTECH"))+ SUM(SUMIFS( INDEX( 'ETPT Format DDG'!$A:$ZZ,,MATCH("4. TOTAL CONTENTIEUX DE LA PROTECTION",'ETPT Format DDG'!2:2,0)), INDEX( 'ETPT Format DDG'!$A:$ZZ,,MATCH("Fonction recodée",'ETPT Format DDG'!2:2,0)),"Fonctionnaire CTECH"))+ SUM(SUMIFS( INDEX( 'ETPT Format DDG'!$A:$ZZ,,MATCH("5. TOTAL CONTENTIEUX CIVIL NON SPÉCIALISÉ",'ETPT Format DDG'!2:2,0)), INDEX( 'ETPT Format DDG'!$A:$ZZ,,MATCH("Fonction recodée",'ETPT Format DDG'!2:2,0)),"Fonctionnaire CTECH"))+ SUM(SUMIFS( INDEX( 'ETPT Format DDG'!$A:$ZZ,,MATCH("12. TOTAL ATTRIBUTIONS DU PP",'ETPT Format DDG'!2:2,0)), INDEX( 'ETPT Format DDG'!$A:$ZZ,,MATCH("Fonction recodée",'ETPT Format DDG'!2:2,0)),"Fonctionnaire CTECH"))- SUM(SUMIFS( INDEX( 'ETPT Format DDG'!$A:$ZZ,,MATCH("12.5. EXTRADITIONS ET MAE",'ETPT Format DDG'!2:2,0)), INDEX( 'ETPT Format DDG'!$A:$ZZ,,MATCH("Fonction recodée",'ETPT Format DDG'!2:2,0)),"Fonctionnaire CTECH"))- SUM(SUMIFS( INDEX( 'ETPT Format DDG'!$A:$ZZ,,MATCH("12.6. SAISIES ET CONFISCATIONS DES AVOIRS CRIMINELS",'ETPT Format DDG'!2:2,0)), INDEX( 'ETPT Format DDG'!$A:$ZZ,,MATCH("Fonction recodée",'ETPT Format DDG'!2:2,0)),"Fonctionnaire CTECH"))- SUM(SUMIFS( INDEX( 'ETPT Format DDG'!$A:$ZZ,,MATCH("12.9. AUTRES APPELS JLD",'ETPT Format DDG'!2:2,0)), INDEX( 'ETPT Format DDG'!$A:$ZZ,,MATCH("Fonction recodée",'ETPT Format DDG'!2:2,0)),"Fonctionnaire CTECH"))+ SUM(SUMIFS( INDEX( 'ETPT Format DDG'!$A:$ZZ,,MATCH("7.1. ACTIVITÉ CIVILE",'ETPT Format DDG'!2:2,0)), INDEX( 'ETPT Format DDG'!$A:$ZZ,,MATCH("Fonction recodée",'ETPT Format DDG'!2:2,0)),"Fonctionnaire CTECH"))+ SUM(SUMIFS( INDEX( 'ETPT Format DDG'!$A:$ZZ,,MATCH("13.9. FONCTIONNAIRES / AJ AFFECTÉS AUX ACTIVITÉS CIVILES ET COMMERCIALES DU PARQUET GÉNÉRAL",'ETPT Format DDG'!2:2,0)), INDEX( 'ETPT Format DDG'!$A:$ZZ,,MATCH("Fonction recodée",'ETPT Format DDG'!2:2,0)),"Fonctionnaire CTECH")) -> #N/A | H3: =_xlfn.AGGREGATE(9,6,G3) -> 0 | I3: =SUM(SUMIFS( INDEX( 'ETPT Format DDG'!$A:$ZZ,,MATCH("13.9. FONCTIONNAIRES / AJ AFFECTÉS AUX ACTIVITÉS CIVILES ET COMMERCIALES DU PARQUET GÉNÉRAL",'ETPT Format DDG'!2:2,0)), INDEX( 'ETPT Format DDG'!$A:$ZZ,,MATCH("Fonction recodée",'ETPT Format DDG'!2:2,0)),"Fonctionnaire A-B-CBUR")) -> #N/A | M3: =SUM(SUMIFS( INDEX( 'ETPT Format DDG'!$A:$ZZ,,MATCH("1. TOTAL CONTENTIEUX SOCIAL",'ETPT Format DDG'!2:2,0)), INDEX( 'ETPT Format DDG'!$A:$ZZ,,MATCH("Fonction recodée",'ETPT Format DDG'!2:2,0)),"Fonctionnaire A-B-CBUR")) -> #N/A | N3: =SUM(SUMIFS( INDEX( 'ETPT Format DDG'!$A:$ZZ,,MATCH("2. TOTAL CONTENTIEUX COMMERCIAL",'ETPT Format DDG'!2:2,0)), INDEX( 'ETPT Format DDG'!$A:$ZZ,,MATCH("Fonction recodée",'ETPT Format DDG'!2:2,0)),"Fonctionnaire A-B-CBUR"))+ SUM(SUMIFS( INDEX( 'ETPT Format DDG'!$A:$ZZ,,MATCH("3. TOTAL CONTENTIEUX DE LA FAMILLE",'ETPT Format DDG'!2:2,0)), INDEX( 'ETPT Format DDG'!$A:$ZZ,,MATCH("Fonction recodée",'ETPT Format DDG'!2:2,0)),"Fonctionnaire A-B-CBUR"))+ SUM(SUMIFS( INDEX( 'ETPT Format DDG'!$A:$ZZ,,MATCH("4. TOTAL CONTENTIEUX DE LA PROTECTION",'ETPT Format DDG'!2:2,0)), INDEX( 'ETPT Format DDG'!$A:$ZZ,,MATCH("Fonction recodée",'ETPT Format DDG'!2:2,0)),"Fonctionnaire A-B-CBUR"))+ SUM(SUMIFS( INDEX( 'ETPT Format DDG'!$A:$ZZ,,MATCH("5. TOTAL CONTENTIEUX CIVIL NON SPÉCIALISÉ",'ETPT Format DDG'!2:2,0)), INDEX( 'ETPT Format DDG'!$A:$ZZ,,MATCH("Fonction recodée",'ETPT Format DDG'!2:2,0)),"Fonctionnaire A-B-CBUR"))+ SUM(SUMIFS( INDEX( 'ETPT Format DDG'!$A:$ZZ,,MATCH("12. TOTAL ATTRIBUTIONS DU PP",'ETPT Format DDG'!2:2,0)), INDEX( 'ETPT Format DDG'!$A:$ZZ,,MATCH("Fonction recodée",'ETPT Format DDG'!2:2,0)),"Fonctionnaire A-B-CBUR"))- SUM(SUMIFS( INDEX( 'ETPT Format DDG'!$A:$ZZ,,MATCH("12.5. EXTRADITIONS ET MAE",'ETPT Format DDG'!2:2,0)), INDEX( 'ETPT Format DDG'!$A:$ZZ,,MATCH("Fonction recodée",'ETPT Format DDG'!2:2,0)),"Fonctionnaire A-B-CBUR"))- SUM(SUMIFS( INDEX( 'ETPT Format DDG'!$A:$ZZ,,MATCH("12.6. SAISIES ET CONFISCATIONS DES AVOIRS CRIMINELS",'ETPT Format DDG'!2:2,0)), INDEX( 'ETPT Format DDG'!$A:$ZZ,,MATCH("Fonction recodée",'ETPT Format DDG'!2:2,0)),"Fonctionnaire A-B-CBUR"))- SUM(SUMIFS( INDEX( 'ETPT Format DDG'!$A:$ZZ,,MATCH("12.9. AUTRES APPELS JLD",'ETPT Format DDG'!2:2,0)), INDEX( 'ETPT Format DDG'!$A:$ZZ,,MATCH("Fonction recodée",'ETPT Format DDG'!2:2,0)),"Fonctionnaire A-B-CBUR"))+ SUM(SUMIFS( INDEX( 'ETPT Format DDG'!$A:$ZZ,,MATCH("7.1. ACTIVITÉ CIVILE",'ETPT Format DDG'!2:2,0)), INDEX( 'ETPT Format DDG'!$A:$ZZ,,MATCH("Fonction recodée",'ETPT Format DDG'!2:2,0)),"Fonctionnaire A-B-CBUR")) -> #N/A | O3: =_xlfn.AGGREGATE(9,6,I3:N3) -> 0 | S3: =SUM(SUMIFS( INDEX( 'ETPT Format DDG'!$A:$ZZ,,MATCH("1. TOTAL CONTENTIEUX SOCIAL",'ETPT Format DDG'!2:2,0)), INDEX( 'ETPT Format DDG'!$A:$ZZ,,MATCH("Fonction recodée",'ETPT Format DDG'!2:2,0)),"Magistrat SIEGE")) -> #N/A | T3: =SUM(SUMIFS( INDEX( 'ETPT Format DDG'!$A:$ZZ,,MATCH("2. TOTAL CONTENTIEUX COMMERCIAL",'ETPT Format DDG'!2:2,0)), INDEX( 'ETPT Format DDG'!$A:$ZZ,,MATCH("Fonction recodée",'ETPT Format DDG'!2:2,0)),"Magistrat SIEGE"))+ SUM(SUMIFS( INDEX( 'ETPT Format DDG'!$A:$ZZ,,MATCH("3. TOTAL CONTENTIEUX DE LA FAMILLE",'ETPT Format DDG'!2:2,0)), INDEX( 'ETPT Format DDG'!$A:$ZZ,,MATCH("Fonction recodée",'ETPT Format DDG'!2:2,0)),"Magistrat SIEGE"))+ SUM(SUMIFS( INDEX( 'ETPT Format DDG'!$A:$ZZ,,MATCH("4. TOTAL CONTENTIEUX DE LA PROTECTION",'ETPT Format DDG'!2:2,0)), INDEX( 'ETPT Format DDG'!$A:$ZZ,,MATCH("Fonction recodée",'ETPT Format DDG'!2:2,0)),"Magistrat SIEGE"))+ SUM(SUMIFS( INDEX( 'ETPT Format DDG'!$A:$ZZ,,MATCH("5. TOTAL CONTENTIEUX CIVIL NON SPÉCIALISÉ",'ETPT Format DDG'!2:2,0)), INDEX( 'ETPT Format DDG'!$A:$ZZ,,MATCH("Fonction recodée",'ETPT Format DDG'!2:2,0)),"Magistrat SIEGE"))+ SUM(SUMIFS( INDEX( 'ETPT Format DDG'!$A:$ZZ,,MATCH("12. TOTAL ATTRIBUTIONS DU PP",'ETPT Format DDG'!2:2,0)), INDEX( 'ETPT Format DDG'!$A:$ZZ,,MATCH("Fonction recodée",'ETPT Format DDG'!2:2,0)),"Magistrat SIEGE"))- SUM(SUMIFS( INDEX( 'ETPT Format DDG'!$A:$ZZ,,MATCH("12.5. EXTRADITIONS ET MAE",'ETPT Format DDG'!2:2,0)), INDEX( 'ETPT Format DDG'!$A:$ZZ,,MATCH("Fonction recodée",'ETPT Format DDG'!2:2,0)),"Magistrat SIEGE"))- SUM(SUMIFS( INDEX( 'ETPT Format DDG'!$A:$ZZ,,MATCH("12.6. SAISIES ET CONFISCATIONS DES AVOIRS CRIMINELS",'ETPT Format DDG'!2:2,0)), INDEX( 'ETPT Format DDG'!$A:$ZZ,,MATCH("Fonction recodée",'ETPT Format DDG'!2:2,0)),"Magistrat SIEGE"))- SUM(SUMIFS( INDEX( 'ETPT Format DDG'!$A:$ZZ,,MATCH("12.9. AUTRES APPELS JLD",'ETPT Format DDG'!2:2,0)), INDEX( 'ETPT Format DDG'!$A:$ZZ,,MATCH("Fonction recodée",'ETPT Format DDG'!2:2,0)),"Magistrat SIEGE"))+ SUM(SUMIFS( INDEX( 'ETPT Format DDG'!$A:$ZZ,,MATCH("7.1. ACTIVITÉ CIVILE",'ETPT Format DDG'!2:2,0)), INDEX( 'ETPT Format DDG'!$A:$ZZ,,MATCH("Fonction recodée",'ETPT Format DDG'!2:2,0)),"Magistrat SIEGE")) -> #N/A | U3: =_xlfn.AGGREGATE(9,6,P3:T3) -> 0 | AA3: =_xlfn.AGGREGATE(9,6,V3:Z3) -> 0
D4: =IF(ISBLANK($D$3),"",$D$3) -> =ETPT_CA_JUR_DDG!$D$5 | E4: 166-02-NC | F4: Action 2 - Traitement et jugement des affaires pénales | G4: =SUM(SUMIFS( INDEX( 'ETPT Format DDG'!$A:$ZZ,,MATCH("12.5. EXTRADITIONS ET MAE",'ETPT Format DDG'!2:2,0)), INDEX( 'ETPT Format DDG'!$A:$ZZ,,MATCH("Fonction recodée",'ETPT Format DDG'!2:2,0)),"Fonctionnaire CTECH"))+ SUM(SUMIFS( INDEX( 'ETPT Format DDG'!$A:$ZZ,,MATCH("12.6. SAISIES ET CONFISCATIONS DES AVOIRS CRIMINELS",'ETPT Format DDG'!2:2,0)), INDEX( 'ETPT Format DDG'!$A:$ZZ,,MATCH("Fonction recodée",'ETPT Format DDG'!2:2,0)),"Fonctionnaire CTECH"))+ SUM(SUMIFS( INDEX( 'ETPT Format DDG'!$A:$ZZ,,MATCH("12.9. AUTRES APPELS JLD",'ETPT Format DDG'!2:2,0)), INDEX( 'ETPT Format DDG'!$A:$ZZ,,MATCH("Fonction recodée",'ETPT Format DDG'!2:2,0)),"Fonctionnaire CTECH"))+ SUM(SUMIFS( INDEX( 'ETPT Format DDG'!$A:$ZZ,,MATCH("7.2. ACTIVITÉ PÉNALE",'ETPT Format DDG'!2:2,0)), INDEX( 'ETPT Format DDG'!$A:$ZZ,,MATCH("Fonction recodée",'ETPT Format DDG'!2:2,0)),"Fonctionnaire CTECH"))+ SUM(SUMIFS( INDEX( 'ETPT Format DDG'!$A:$ZZ,,MATCH("8. TOTAL CORRECTIONNEL",'ETPT Format DDG'!2:2,0)), INDEX( 'ETPT Format DDG'!$A:$ZZ,,MATCH("Fonction recodée",'ETPT Format DDG'!2:2,0)),"Fonctionnaire CTECH"))+ SUM(SUMIFS( INDEX( 'ETPT Format DDG'!$A:$ZZ,,MATCH("9. TOTAL INSTRUCTION ET ENTRAIDE",'ETPT Format DDG'!2:2,0)), INDEX( 'ETPT Format DDG'!$A:$ZZ,,MATCH("Fonction recodée",'ETPT Format DDG'!2:2,0)),"Fonctionnaire CTECH"))+ SUM(SUMIFS( INDEX( 'ETPT Format DDG'!$A:$ZZ,,MATCH("10. TOTAL APPLICATION DES PEINES",'ETPT Format DDG'!2:2,0)), INDEX( 'ETPT Format DDG'!$A:$ZZ,,MATCH("Fonction recodée",'ETPT Format DDG'!2:2,0)),"Fonctionnaire CTECH"))+ SUM(SUMIFS( INDEX( 'ETPT Format DDG'!$A:$ZZ,,MATCH("11. TOTAL CONTENTIEUX CRIMINEL",'ETPT Format DDG'!2:2,0)), INDEX( 'ETPT Format DDG'!$A:$ZZ,,MATCH("Fonction recodée",'ETPT Format DDG'!2:2,0)),"Fonctionnaire CTECH"))+ SUM(SUMIFS( INDEX( 'ETPT Format DDG'!$A:$ZZ,,MATCH("13.10. AUTRES FONCTIONNAIRES / AJ AFFECTÉS AU PARQUET GÉNÉRAL",'ETPT Format DDG'!2:2,0)), INDEX( 'ETPT Format DDG'!$A:$ZZ,,MATCH("Fonction recodée",'ETPT Format DDG'!2:2,0)),"Fonctionnaire CTECH")) -> #N/A | H4: =_xlfn.AGGREGATE(9,6,G4) -> 0 | J4: =SUM(SUMIFS( INDEX( 'ETPT Format DDG'!$A:$ZZ,,MATCH("11.1. ASSISES HORS JIRS",'ETPT Format DDG'!2:2,0)), INDEX( 'ETPT Format DDG'!$A:$ZZ,,MATCH("Fonction recodée",'ETPT Format DDG'!2:2,0)),"Fonctionnaire A-B-CBUR"))+ SUM(SUMIFS( INDEX( 'ETPT Format DDG'!$A:$ZZ,,MATCH("11.2 ASSISES JIRS",'ETPT Format DDG'!2:2,0)), INDEX( 'ETPT Format DDG'!$A:$ZZ,,MATCH("Fonction recodée",'ETPT Format DDG'!2:2,0)),"Fonctionnaire A-B-CBUR")) -> #N/A | K4: =SUM(SUMIFS( INDEX( 'ETPT Format DDG'!$A:$ZZ,,MATCH("11.3. COUR CRIMINELLE DÉPARTEMENTALE",'ETPT Format DDG'!2:2,0)), INDEX( 'ETPT Format DDG'!$A:$ZZ,,MATCH("Fonction recodée",'ETPT Format DDG'!2:2,0)),"Fonctionnaire A-B-CBUR")) -> #N/A | L4: =SUM(SUMIFS( INDEX( 'ETPT Format DDG'!$A:$ZZ,,MATCH("8.4. CONTENTIEUX JIRS CRIM-ORG",'ETPT Format DDG'!2:2,0)), INDEX( 'ETPT Format DDG'!$A:$ZZ,,MATCH("Fonction recodée",'ETPT Format DDG'!2:2,0)),"Fonctionnaire A-B-CBUR"))+ SUM(SUMIFS( INDEX( 'ETPT Format DDG'!$A:$ZZ,,MATCH("8.7. CONTENTIEUX JIRS ÉCO-FI",'ETPT Format DDG'!2:2,0)), INDEX( 'ETPT Format DDG'!$A:$ZZ,,MATCH("Fonction recodée",'ETPT Format DDG'!2:2,0)),"Fonctionnaire A-B-CBUR"))+ SUM(SUMIFS( INDEX( 'ETPT Format DDG'!$A:$ZZ,,MATCH("9.3. CONTENTIEUX DE LA DÉTENTION JIRS",'ETPT Format DDG'!2:2,0)), INDEX( 'ETPT Format DDG'!$A:$ZZ,,MATCH("Fonction recodée",'ETPT Format DDG'!2:2,0)),"Fonctionnaire A-B-CBUR"))+ SUM(SUMIFS( INDEX( 'ETPT Format DDG'!$A:$ZZ,,MATCH("9.5. CONTENTIEUX DU CONTRÔLE JUDICIAIRE JIRS",'ETPT Format DDG'!2:2,0)), INDEX( 'ETPT Format DDG'!$A:$ZZ,,MATCH("Fonction recodée",'ETPT Format DDG'!2:2,0)),"Fonctionnaire A-B-CBUR"))+ SUM(SUMIFS( INDEX( 'ETPT Format DDG'!$A:$ZZ,,MATCH("9.7. CONTENTIEUX DE FOND JIRS",'ETPT Format DDG'!2:2,0)), INDEX( 'ETPT Format DDG'!$A:$ZZ,,MATCH("Fonction recodée",'ETPT Format DDG'!2:2,0)),"Fonctionnaire A-B-CBUR")) -> #N/A | N4: =SUM(SUMIFS( INDEX( 'ETPT Format DDG'!$A:$ZZ,,MATCH("12.5. EXTRADITIONS ET MAE",'ETPT Format DDG'!2:2,0)), INDEX( 'ETPT Format DDG'!$A:$ZZ,,MATCH("Fonction recodée",'ETPT Format DDG'!2:2,0)),"Fonctionnaire A-B-CBUR"))+ SUM(SUMIFS( INDEX( 'ETPT Format DDG'!$A:$ZZ,,MATCH("12.6. SAISIES ET CONFISCATIONS DES AVOIRS CRIMINELS",'ETPT Format DDG'!2:2,0)), INDEX( 'ETPT Format DDG'!$A:$ZZ,,MATCH("Fonction recodée",'ETPT Format DDG'!2:2,0)),"Fonctionnaire A-B-CBUR"))+ SUM(SUMIFS( INDEX( 'ETPT Format DDG'!$A:$ZZ,,MATCH("12.9. AUTRES APPELS JLD",'ETPT Format DDG'!2:2,0)), INDEX( 'ETPT Format DDG'!$A:$ZZ,,MATCH("Fonction recodée",'ETPT Format DDG'!2:2,0)),"Fonctionnaire A-B-CBUR"))+ SUM(SUMIFS( INDEX( 'ETPT Format DDG'!$A:$ZZ,,MATCH("7.2. ACTIVITÉ PÉNALE",'ETPT Format DDG'!2:2,0)), INDEX( 'ETPT Format DDG'!$A:$ZZ,,MATCH("Fonction recodée",'ETPT Format DDG'!2:2,0)),"Fonctionnaire A-B-CBUR"))+ SUM(SUMIFS( INDEX( 'ETPT Format DDG'!$A:$ZZ,,MATCH("8. TOTAL CORRECTIONNEL",'ETPT Format DDG'!2:2,0)), INDEX( 'ETPT Format DDG'!$A:$ZZ,,MATCH("Fonction recodée",'ETPT Format DDG'!2:2,0)),"Fonctionnaire A-B-CBUR"))+ SUM(SUMIFS( INDEX( 'ETPT Format DDG'!$A:$ZZ,,MATCH("9. TOTAL INSTRUCTION ET ENTRAIDE",'ETPT Format DDG'!2:2,0)), INDEX( 'ETPT Format DDG'!$A:$ZZ,,MATCH("Fonction recodée",'ETPT Format DDG'!2:2,0)),"Fonctionnaire A-B-CBUR"))+ SUM(SUMIFS( INDEX( 'ETPT Format DDG'!$A:$ZZ,,MATCH("10. TOTAL APPLICATION DES PEINES",'ETPT Format DDG'!2:2,0)), INDEX( 'ETPT Format DDG'!$A:$ZZ,,MATCH("Fonction recodée",'ETPT Format DDG'!2:2,0)),"Fonctionnaire A-B-CBUR"))+ SUM(SUMIFS( INDEX( 'ETPT Format DDG'!$A:$ZZ,,MATCH("11. TOTAL CONTENTIEUX CRIMINEL",'ETPT Format DDG'!2:2,0)), INDEX( 'ETPT Format DDG'!$A:$ZZ,,MATCH("Fonction recodée",'ETPT Format DDG'!2:2,0)),"Fonctionnaire A-B-CBUR"))+ SUM(SUMIFS( INDEX( 'ETPT Format DDG'!$A:$ZZ,,MATCH("13.10. AUTRES FONCTIONNAIRES / AJ AFFECTÉS AU PARQUET GÉNÉRAL",'ETPT Format DDG'!2:2,0)), INDEX( 'ETPT Format DDG'!$A:$ZZ,,MATCH("Fonction recodée",'ETPT Format DDG'!2:2,0)),"Fonctionnaire A-B-CBUR"))- SUM(I4:M4) -> #N/A | O4: =_xlfn.AGGREGATE(9,6,I4:N4) -> 0 | P4: =SUM(SUMIFS( INDEX( 'ETPT Format DDG'!$A:$ZZ,,MATCH("11.1. ASSISES HORS JIRS",'ETPT Format DDG'!2:2,0)), INDEX( 'ETPT Format DDG'!$A:$ZZ,,MATCH("Fonction recodée",'ETPT Format DDG'!2:2,0)),"Magistrat SIEGE"))+ SUM(SUMIFS( INDEX( 'ETPT Format DDG'!$A:$ZZ,,MATCH("11.2 ASSISES JIRS",'ETPT Format DDG'!2:2,0)), INDEX( 'ETPT Format DDG'!$A:$ZZ,,MATCH("Fonction recodée",'ETPT Format DDG'!2:2,0)),"Magistrat SIEGE")) -> #N/A | Q4: =SUM(SUMIFS( INDEX( 'ETPT Format DDG'!$A:$ZZ,,MATCH("11.3. COUR CRIMINELLE DÉPARTEMENTALE",'ETPT Format DDG'!2:2,0)), INDEX( 'ETPT Format DDG'!$A:$ZZ,,MATCH("Fonction recodée",'ETPT Format DDG'!2:2,0)),"Magistrat SIEGE")) -> #N/A | R4: =SUM(SUMIFS( INDEX( 'ETPT Format DDG'!$A:$ZZ,,MATCH("8.4. CONTENTIEUX JIRS CRIM-ORG",'ETPT Format DDG'!2:2,0)), INDEX( 'ETPT Format DDG'!$A:$ZZ,,MATCH("Fonction recodée",'ETPT Format DDG'!2:2,0)),"Magistrat SIEGE"))+ SUM(SUMIFS( INDEX( 'ETPT Format DDG'!$A:$ZZ,,MATCH("8.7. CONTENTIEUX JIRS ÉCO-FI",'ETPT Format DDG'!2:2,0)), INDEX( 'ETPT Format DDG'!$A:$ZZ,,MATCH("Fonction recodée",'ETPT Format DDG'!2:2,0)),"Magistrat SIEGE"))+ SUM(SUMIFS( INDEX( 'ETPT Format DDG'!$A:$ZZ,,MATCH("9.3. CONTENTIEUX DE LA DÉTENTION JIRS",'ETPT Format DDG'!2:2,0)), INDEX( 'ETPT Format DDG'!$A:$ZZ,,MATCH("Fonction recodée",'ETPT Format DDG'!2:2,0)),"Magistrat SIEGE"))+ SUM(SUMIFS( INDEX( 'ETPT Format DDG'!$A:$ZZ,,MATCH("9.5. CONTENTIEUX DU CONTRÔLE JUDICIAIRE JIRS",'ETPT Format DDG'!2:2,0)), INDEX( 'ETPT Format DDG'!$A:$ZZ,,MATCH("Fonction recodée",'ETPT Format DDG'!2:2,0)),"Magistrat SIEGE"))+ SUM(SUMIFS( INDEX( 'ETPT Format DDG'!$A:$ZZ,,MATCH("9.7. CONTENTIEUX DE FOND JIRS",'ETPT Format DDG'!2:2,0)), INDEX( 'ETPT Format DDG'!$A:$ZZ,,MATCH("Fonction recodée",'ETPT Format DDG'!2:2,0)),"Magistrat SIEGE")) -> #N/A | T4: =SUM(SUMIFS( INDEX( 'ETPT Format DDG'!$A:$ZZ,,MATCH("12.5. EXTRADITIONS ET MAE",'ETPT Format DDG'!2:2,0)), INDEX( 'ETPT Format DDG'!$A:$ZZ,,MATCH("Fonction recodée",'ETPT Format DDG'!2:2,0)),"Magistrat SIEGE"))+ SUM(SUMIFS( INDEX( 'ETPT Format DDG'!$A:$ZZ,,MATCH("12.6. SAISIES ET CONFISCATIONS DES AVOIRS CRIMINELS",'ETPT Format DDG'!2:2,0)), INDEX( 'ETPT Format DDG'!$A:$ZZ,,MATCH("Fonction recodée",'ETPT Format DDG'!2:2,0)),"Magistrat SIEGE"))+ SUM(SUMIFS( INDEX( 'ETPT Format DDG'!$A:$ZZ,,MATCH("12.9. AUTRES APPELS JLD",'ETPT Format DDG'!2:2,0)), INDEX( 'ETPT Format DDG'!$A:$ZZ,,MATCH("Fonction recodée",'ETPT Format DDG'!2:2,0)),"Magistrat SIEGE"))+ SUM(SUMIFS( INDEX( 'ETPT Format DDG'!$A:$ZZ,,MATCH("7.2. ACTIVITÉ PÉNALE",'ETPT Format DDG'!2:2,0)), INDEX( 'ETPT Format DDG'!$A:$ZZ,,MATCH("Fonction recodée",'ETPT Format DDG'!2:2,0)),"Magistrat SIEGE"))+ SUM(SUMIFS( INDEX( 'ETPT Format DDG'!$A:$ZZ,,MATCH("8. TOTAL CORRECTIONNEL",'ETPT Format DDG'!2:2,0)), INDEX( 'ETPT Format DDG'!$A:$ZZ,,MATCH("Fonction recodée",'ETPT Format DDG'!2:2,0)),"Magistrat SIEGE"))+ SUM(SUMIFS( INDEX( 'ETPT Format DDG'!$A:$ZZ,,MATCH("9. TOTAL INSTRUCTION ET ENTRAIDE",'ETPT Format DDG'!2:2,0)), INDEX( 'ETPT Format DDG'!$A:$ZZ,,MATCH("Fonction recodée",'ETPT Format DDG'!2:2,0)),"Magistrat SIEGE"))+ SUM(SUMIFS( INDEX( 'ETPT Format DDG'!$A:$ZZ,,MATCH("10. TOTAL APPLICATION DES PEINES",'ETPT Format DDG'!2:2,0)), INDEX( 'ETPT Format DDG'!$A:$ZZ,,MATCH("Fonction recodée",'ETPT Format DDG'!2:2,0)),"Magistrat SIEGE"))+ SUM(SUMIFS( INDEX( 'ETPT Format DDG'!$A:$ZZ,,MATCH("11. TOTAL CONTENTIEUX CRIMINEL",'ETPT Format DDG'!2:2,0)), INDEX( 'ETPT Format DDG'!$A:$ZZ,,MATCH("Fonction recodée",'ETPT Format DDG'!2:2,0)),"Magistrat SIEGE"))- SUM(P4:S4) -> #N/A | U4: =_xlfn.AGGREGATE(9,6,P4:T4) -> 0 | AA4: =_xlfn.AGGREGATE(9,6,V4:Z4) -> 0
D5: =IF(ISBLANK($D$3),"",$D$3) -> =ETPT_CA_JUR_DDG!$D$5 | E5: 166-04-NC | F5: Action 4 - Conseil supérieur de la magistrature | H5: =_xlfn.AGGREGATE(9,6,G5) -> 0 | O5: =_xlfn.AGGREGATE(9,6,I5:N5) -> 0 | T5: =SUM(SUMIFS( INDEX( 'ETPT Format DDG'!$A:$ZZ,,MATCH("13.4 CSM",'ETPT Format DDG'!2:2,0)), INDEX( 'ETPT Format DDG'!$A:$ZZ,,MATCH("Fonction recodée",'ETPT Format DDG'!2:2,0)),"Magistrat SIEGE")) -> #N/A | U5: =_xlfn.AGGREGATE(9,6,P5:T5) -> 0 | AA5: =_xlfn.AGGREGATE(9,6,V5:Z5) -> 0
D6: =IF(ISBLANK($D$3),"",$D$3) -> =ETPT_CA_JUR_DDG!$D$5 | E6: 166-06-99 | F6: Action 6 - Accueil du justiciable (inclus SAUJ) | G6: =SUM(SUMIFS( INDEX( 'ETPT Format DDG'!$A:$ZZ,,MATCH("13.8. ACCUEIL DU JUSTICIABLE",'ETPT Format DDG'!2:2,0)), INDEX( 'ETPT Format DDG'!$A:$ZZ,,MATCH("Fonction recodée",'ETPT Format DDG'!2:2,0)),"Fonctionnaire CTECH")) -> #N/A | H6: =_xlfn.AGGREGATE(9,6,G6) -> 0 | N6: =SUM(SUMIFS( INDEX( 'ETPT Format DDG'!$A:$ZZ,,MATCH("13.8. ACCUEIL DU JUSTICIABLE",'ETPT Format DDG'!2:2,0)), INDEX( 'ETPT Format DDG'!$A:$ZZ,,MATCH("Fonction recodée",'ETPT Format DDG'!2:2,0)),"Fonctionnaire A-B-CBUR")) -> #N/A | O6: =_xlfn.AGGREGATE(9,6,I6:N6) -> 0 | T6: =SUM(SUMIFS( INDEX( 'ETPT Format DDG'!$A:$ZZ,,MATCH("13.8. ACCUEIL DU JUSTICIABLE",'ETPT Format DDG'!2:2,0)), INDEX( 'ETPT Format DDG'!$A:$ZZ,,MATCH("Fonction recodée",'ETPT Format DDG'!2:2,0)),"Magistrat SIEGE")) -> #N/A | U6: =_xlfn.AGGREGATE(9,6,P6:T6) -> 0 | AA6: =_xlfn.AGGREGATE(9,6,V6:Z6) -> 0
D7: =IF(ISBLANK($D$3),"",$D$3) -> =ETPT_CA_JUR_DDG!$D$5 | E7: 166-06-NC | F7: Action 6 - Soutien (Hors accueil du justiciable) | G7: =SUM(SUMIFS( INDEX( 'ETPT Format DDG'!$A:$ZZ,,MATCH("13.11. ACTIVITÉS EXTÉRIEURES ET PARTENARIATS",'ETPT Format DDG'!2:2,0)), INDEX( 'ETPT Format DDG'!$A:$ZZ,,MATCH("Fonction recodée",'ETPT Format DDG'!2:2,0)),"Fonctionnaire CTECH"))+ SUM(SUMIFS( INDEX( 'ETPT Format DDG'!$A:$ZZ,,MATCH("13.13. COMMUNICATION",'ETPT Format DDG'!2:2,0)), INDEX( 'ETPT Format DDG'!$A:$ZZ,,MATCH("Fonction recodée",'ETPT Format DDG'!2:2,0)),"Fonctionnaire CTECH"))+ SUM(SUMIFS( INDEX( 'ETPT Format DDG'!$A:$ZZ,,MATCH("13.12. ÉQUIPEMENT",'ETPT Format DDG'!2:2,0)), INDEX( 'ETPT Format DDG'!$A:$ZZ,,MATCH("Fonction recodée",'ETPT Format DDG'!2:2,0)),"Fonctionnaire CTECH"))+ SUM(SUMIFS( INDEX( 'ETPT Format DDG'!$A:$ZZ,,MATCH("13.5. EXPERTISES (SUIVI ET LISTES)",'ETPT Format DDG'!2:2,0)), INDEX( 'ETPT Format DDG'!$A:$ZZ,,MATCH("Fonction recodée",'ETPT Format DDG'!2:2,0)),"Fonctionnaire CTECH"))+ SUM(SUMIFS( INDEX( 'ETPT Format DDG'!$A:$ZZ,,MATCH("13.2. FORMATIONS SUIVIES",'ETPT Format DDG'!2:2,0)), INDEX( 'ETPT Format DDG'!$A:$ZZ,,MATCH("Fonction recodée",'ETPT Format DDG'!2:2,0)),"Fonctionnaire CTECH"))+ SUM(SUMIFS( INDEX( 'ETPT Format DDG'!$A:$ZZ,,MATCH("13.6. MÉDIATION / CONCILIATION (SUIVI ET LISTES)",'ETPT Format DDG'!2:2,0)), INDEX( 'ETPT Format DDG'!$A:$ZZ,,MATCH("Fonction recodée",'ETPT Format DDG'!2:2,0)),"Fonctionnaire CTECH"))+ SUM(SUMIFS( INDEX( 'ETPT Format DDG'!$A:$ZZ,,MATCH("13.14. POLITIQUE ASSOCIATIVE ET AIDE AUX VICTIMES",'ETPT Format DDG'!2:2,0)), INDEX( 'ETPT Format DDG'!$A:$ZZ,,MATCH("Fonction recodée",'ETPT Format DDG'!2:2,0)),"Fonctionnaire CTECH"))+ SUM(SUMIFS( INDEX( 'ETPT Format DDG'!$A:$ZZ,,MATCH("13.1. SOUTIEN (AUTRES)",'ETPT Format DDG'!2:2,0)), INDEX( 'ETPT Format DDG'!$A:$ZZ,,MATCH("Fonction recodée",'ETPT Format DDG'!2:2,0)),"Fonctionnaire CTECH"))+ SUM(SUMIFS( INDEX( 'ETPT Format DDG'!$A:$ZZ,,MATCH("13.15. AUTRES ACTIVITÉS NON JURIDICTIONNELLES",'ETPT Format DDG'!2:2,0)), INDEX( 'ETPT Format DDG'!$A:$ZZ,,MATCH("Fonction recodée",'ETPT Format DDG'!2:2,0)),"Fonctionnaire CTECH")) -> #N/A | H7: =_xlfn.AGGREGATE(9,6,G7) -> 0 | N7: =SUM(SUMIFS( INDEX( 'ETPT Format DDG'!$A:$ZZ,,MATCH("13.11. ACTIVITÉS EXTÉRIEURES ET PARTENARIATS",'ETPT Format DDG'!2:2,0)), INDEX( 'ETPT Format DDG'!$A:$ZZ,,MATCH("Fonction recodée",'ETPT Format DDG'!2:2,0)),"Fonctionnaire A-B-CBUR"))+ SUM(SUMIFS( INDEX( 'ETPT Format DDG'!$A:$ZZ,,MATCH("13.13. COMMUNICATION",'ETPT Format DDG'!2:2,0)), INDEX( 'ETPT Format DDG'!$A:$ZZ,,MATCH("Fonction recodée",'ETPT Format DDG'!2:2,0)),"Fonctionnaire A-B-CBUR"))+ SUM(SUMIFS( INDEX( 'ETPT Format DDG'!$A:$ZZ,,MATCH("13.12. ÉQUIPEMENT",'ETPT Format DDG'!2:2,0)), INDEX( 'ETPT Format DDG'!$A:$ZZ,,MATCH("Fonction recodée",'ETPT Format DDG'!2:2,0)),"Fonctionnaire A-B-CBUR"))+ SUM(SUMIFS( INDEX( 'ETPT Format DDG'!$A:$ZZ,,MATCH("13.5. EXPERTISES (SUIVI ET LISTES)",'ETPT Format DDG'!2:2,0)), INDEX( 'ETPT Format DDG'!$A:$ZZ,,MATCH("Fonction recodée",'ETPT Format DDG'!2:2,0)),"Fonctionnaire A-B-CBUR"))+ SUM(SUMIFS( INDEX( 'ETPT Format DDG'!$A:$ZZ,,MATCH("13.2. FORMATIONS SUIVIES",'ETPT Format DDG'!2:2,0)), INDEX( 'ETPT Format DDG'!$A:$ZZ,,MATCH("Fonction recodée",'ETPT Format DDG'!2:2,0)),"Fonctionnaire A-B-CBUR"))+ SUM(SUMIFS( INDEX( 'ETPT Format DDG'!$A:$ZZ,,MATCH("13.6. MÉDIATION / CONCILIATION (SUIVI ET LISTES)",'ETPT Format DDG'!2:2,0)), INDEX( 'ETPT Format DDG'!$A:$ZZ,,MATCH("Fonction recodée",'ETPT Format DDG'!2:2,0)),"Fonctionnaire A-B-CBUR"))+ SUM(SUMIFS( INDEX( 'ETPT Format DDG'!$A:$ZZ,,MATCH("13.14. POLITIQUE ASSOCIATIVE ET AIDE AUX VICTIMES",'ETPT Format DDG'!2:2,0)), INDEX( 'ETPT Format DDG'!$A:$ZZ,,MATCH("Fonction recodée",'ETPT Format DDG'!2:2,0)),"Fonctionnaire A-B-CBUR"))+ SUM(SUMIFS( INDEX( 'ETPT Format DDG'!$A:$ZZ,,MATCH("13.1. SOUTIEN (AUTRES)",'ETPT Format DDG'!2:2,0)), INDEX( 'ETPT Format DDG'!$A:$ZZ,,MATCH("Fonction recodée",'ETPT Format DDG'!2:2,0)),"Fonctionnaire A-B-CBUR"))+ SUM(SUMIFS( INDEX( 'ETPT Format DDG'!$A:$ZZ,,MATCH("13.15. AUTRES ACTIVITÉS NON JURIDICTIONNELLES",'ETPT Format DDG'!2:2,0)), INDEX( 'ETPT Format DDG'!$A:$ZZ,,MATCH("Fonction recodée",'ETPT Format DDG'!2:2,0)),"Fonctionnaire A-B-CBUR")) -> #N/A | O7: =_xlfn.AGGREGATE(9,6,I7:N7) -> 0 | T7: =SUM(SUMIFS( INDEX( 'ETPT Format DDG'!$A:$ZZ,,MATCH("13.11. ACTIVITÉS EXTÉRIEURES ET PARTENARIATS",'ETPT Format DDG'!2:2,0)), INDEX( 'ETPT Format DDG'!$A:$ZZ,,MATCH("Fonction recodée",'ETPT Format DDG'!2:2,0)),"Magistrat SIEGE"))+ SUM(SUMIFS( INDEX( 'ETPT Format DDG'!$A:$ZZ,,MATCH("13.13. COMMUNICATION",'ETPT Format DDG'!2:2,0)), INDEX( 'ETPT Format DDG'!$A:$ZZ,,MATCH("Fonction recodée",'ETPT Format DDG'!2:2,0)),"Magistrat SIEGE"))+ SUM(SUMIFS( INDEX( 'ETPT Format DDG'!$A:$ZZ,,MATCH("13.12. ÉQUIPEMENT",'ETPT Format DDG'!2:2,0)), INDEX( 'ETPT Format DDG'!$A:$ZZ,,MATCH("Fonction recodée",'ETPT Format DDG'!2:2,0)),"Magistrat SIEGE"))+ SUM(SUMIFS( INDEX( 'ETPT Format DDG'!$A:$ZZ,,MATCH("13.5. EXPERTISES (SUIVI ET LISTES)",'ETPT Format DDG'!2:2,0)), INDEX( 'ETPT Format DDG'!$A:$ZZ,,MATCH("Fonction recodée",'ETPT Format DDG'!2:2,0)),"Magistrat SIEGE"))+ SUM(SUMIFS( INDEX( 'ETPT Format DDG'!$A:$ZZ,,MATCH("13.2. FORMATIONS SUIVIES",'ETPT Format DDG'!2:2,0)), INDEX( 'ETPT Format DDG'!$A:$ZZ,,MATCH("Fonction recodée",'ETPT Format DDG'!2:2,0)),"Magistrat SIEGE"))+ SUM(SUMIFS( INDEX( 'ETPT Format DDG'!$A:$ZZ,,MATCH("13.6. MÉDIATION / CONCILIATION (SUIVI ET LISTES)",'ETPT Format DDG'!2:2,0)), INDEX( 'ETPT Format DDG'!$A:$ZZ,,MATCH("Fonction recodée",'ETPT Format DDG'!2:2,0)),"Magistrat SIEGE"))+ SUM(SUMIFS( INDEX( 'ETPT Format DDG'!$A:$ZZ,,MATCH("13.14. POLITIQUE ASSOCIATIVE ET AIDE AUX VICTIMES",'ETPT Format DDG'!2:2,0)), INDEX( 'ETPT Format DDG'!$A:$ZZ,,MATCH("Fonction recodée",'ETPT Format DDG'!2:2,0)),"Magistrat SIEGE"))+ SUM(SUMIFS( INDEX( 'ETPT Format DDG'!$A:$ZZ,,MATCH("13.1. SOUTIEN (AUTRES)",'ETPT Format DDG'!2:2,0)), INDEX( 'ETPT Format DDG'!$A:$ZZ,,MATCH("Fonction recodée",'ETPT Format DDG'!2:2,0)),"Magistrat SIEGE"))+ SUM(SUMIFS( INDEX( 'ETPT Format DDG'!$A:$ZZ,,MATCH("13.15. AUTRES ACTIVITÉS NON JURIDICTIONNELLES",'ETPT Format DDG'!2:2,0)), INDEX( 'ETPT Format DDG'!$A:$ZZ,,MATCH("Fonction recodée",'ETPT Format DDG'!2:2,0)),"Magistrat SIEGE")) -> #N/A | U7: =_xlfn.AGGREGATE(9,6,P7:T7) -> 0 | AA7: =_xlfn.AGGREGATE(9,6,V7:Z7) -> 0
D8: =IF(ISBLANK($D$3),"",$D$3) -> =ETPT_CA_JUR_DDG!$D$5 | E8: 166-07-NC | F8: Action 7 - Formation dispensée | G8: =SUM(SUMIFS( INDEX( 'ETPT Format DDG'!$A:$ZZ,,MATCH("13.3. FORMATIONS DISPENSÉES",'ETPT Format DDG'!2:2,0)), INDEX( 'ETPT Format DDG'!$A:$ZZ,,MATCH("Fonction recodée",'ETPT Format DDG'!2:2,0)),"Fonctionnaire CTECH")) -> #N/A | H8: =_xlfn.AGGREGATE(9,6,G8) -> 0 | N8: =SUM(SUMIFS( INDEX( 'ETPT Format DDG'!$A:$ZZ,,MATCH("13.3. FORMATIONS DISPENSÉES",'ETPT Format DDG'!2:2,0)), INDEX( 'ETPT Format DDG'!$A:$ZZ,,MATCH("Fonction recodée",'ETPT Format DDG'!2:2,0)),"Fonctionnaire A-B-CBUR")) -> #N/A | O8: =_xlfn.AGGREGATE(9,6,I8:N8) -> 0 | T8: =SUM(SUMIFS( INDEX( 'ETPT Format DDG'!$A:$ZZ,,MATCH("13.3. FORMATIONS DISPENSÉES",'ETPT Format DDG'!2:2,0)), INDEX( 'ETPT Format DDG'!$A:$ZZ,,MATCH("Fonction recodée",'ETPT Format DDG'!2:2,0)),"Magistrat SIEGE")) -> #N/A | U8: =_xlfn.AGGREGATE(9,6,P8:T8) -> 0 | AA8: =_xlfn.AGGREGATE(9,6,V8:Z8) -> 0
D9: =IF(ISBLANK($D$3),"",$D$3) -> =ETPT_CA_JUR_DDG!$D$5 | E9: 166-08-NC | F9: Action 8 - Support à l'accès au droit et à la justice | G9: =SUM(SUMIFS( INDEX( 'ETPT Format DDG'!$A:$ZZ,,MATCH("13.7. ACCÈS AU DROIT ET À LA JUSTICE",'ETPT Format DDG'!2:2,0)), INDEX( 'ETPT Format DDG'!$A:$ZZ,,MATCH("Fonction recodée",'ETPT Format DDG'!2:2,0)),"Fonctionnaire CTECH")) -> #N/A | H9: =_xlfn.AGGREGATE(9,6,G9) -> 0 | N9: =SUM(SUMIFS( INDEX( 'ETPT Format DDG'!$A:$ZZ,,MATCH("13.7. ACCÈS AU DROIT ET À LA JUSTICE",'ETPT Format DDG'!2:2,0)), INDEX( 'ETPT Format DDG'!$A:$ZZ,,MATCH("Fonction recodée",'ETPT Format DDG'!2:2,0)),"Fonctionnaire A-B-CBUR")) -> #N/A | O9: =_xlfn.AGGREGATE(9,6,I9:N9) -> 0 | T9: =SUM(SUMIFS( INDEX( 'ETPT Format DDG'!$A:$ZZ,,MATCH("13.7. ACCÈS AU DROIT ET À LA JUSTICE",'ETPT Format DDG'!2:2,0)), INDEX( 'ETPT Format DDG'!$A:$ZZ,,MATCH("Fonction recodée",'ETPT Format DDG'!2:2,0)),"Magistrat SIEGE")) -> #N/A | U9: =_xlfn.AGGREGATE(9,6,P9:T9) -> 0 | AA9: =_xlfn.AGGREGATE(9,6,V9:Z9) -> 0
D10: =IF(ISBLANK($D$3),"",$D$3) -> =ETPT_CA_JUR_DDG!$D$5 | E10: 166-99-NC | F10: Action 99 - Personnel concourant au programme - à reventiler | G10: =SUM(SUMIFS( INDEX( 'ETPT Format DDG'!$A:$ZZ,,MATCH("14. TOTAL des INDISPONIBILITÉS relevant de l'action 99",'ETPT Format DDG'!2:2,0)), INDEX( 'ETPT Format DDG'!$A:$ZZ,,MATCH("Fonction recodée",'ETPT Format DDG'!2:2,0)),"Fonctionnaire CTECH"))- SUM(SUMIFS( INDEX( 'ETPT Format DDG'!$A:$ZZ,,MATCH("14.9. MISE À DISPOSITION",'ETPT Format DDG'!2:2,0)), INDEX( 'ETPT Format DDG'!$A:$ZZ,,MATCH("Fonction recodée",'ETPT Format DDG'!2:2,0)),"Fonctionnaire CTECH")) -> #N/A | H10: =_xlfn.AGGREGATE(9,6,G10) -> 0 | N10: =SUM(SUMIFS( INDEX( 'ETPT Format DDG'!$A:$ZZ,,MATCH("14. TOTAL des INDISPONIBILITÉS relevant de l'action 99",'ETPT Format DDG'!2:2,0)), INDEX( 'ETPT Format DDG'!$A:$ZZ,,MATCH("Fonction recodée",'ETPT Format DDG'!2:2,0)),"Fonctionnaire A-B-CBUR"))- SUM(SUMIFS( INDEX( 'ETPT Format DDG'!$A:$ZZ,,MATCH("14.9. MISE À DISPOSITION",'ETPT Format DDG'!2:2,0)), INDEX( 'ETPT Format DDG'!$A:$ZZ,,MATCH("Fonction recodée",'ETPT Format DDG'!2:2,0)),"Fonctionnaire A-B-CBUR")) -> #N/A | O10: =_xlfn.AGGREGATE(9,6,I10:N10) -> 0 | T10: =SUM(SUMIFS( INDEX( 'ETPT Format DDG'!$A:$ZZ,,MATCH("14. TOTAL des INDISPONIBILITÉS relevant de l'action 99",'ETPT Format DDG'!2:2,0)), INDEX( 'ETPT Format DDG'!$A:$ZZ,,MATCH("Fonction recodée",'ETPT Format DDG'!2:2,0)),"Magistrat SIEGE"))- SUM(SUMIFS( INDEX( 'ETPT Format DDG'!$A:$ZZ,,MATCH("14.9. MISE À DISPOSITION",'ETPT Format DDG'!2:2,0)), INDEX( 'ETPT Format DDG'!$A:$ZZ,,MATCH("Fonction recodée",'ETPT Format DDG'!2:2,0)),"Magistrat SIEGE")) -> #N/A | U10: =_xlfn.AGGREGATE(9,6,P10:T10) -> 0 | AA10: =_xlfn.AGGREGATE(9,6,V10:Z10) -> 0
D11: =IF(ISBLANK($D$3),"",$D$3) -> =ETPT_CA_JUR_DDG!$D$5 | E11: 166-NC-NC | F11: Etpt autres personnels à reventiler (dont droit local,commercial- rcs, mise à disposition) | G11: =SUM(SUMIFS( INDEX( 'ETPT Format DDG'!$A:$ZZ,,MATCH("14.9. MISE À DISPOSITION",'ETPT Format DDG'!2:2,0)), INDEX( 'ETPT Format DDG'!$A:$ZZ,,MATCH("Fonction recodée",'ETPT Format DDG'!2:2,0)),"Fonctionnaire CTECH")) -> #N/A | H11: =_xlfn.AGGREGATE(9,6,G11) -> 0 | N11: =SUM(SUMIFS( INDEX( 'ETPT Format DDG'!$A:$ZZ,,MATCH("14.9. MISE À DISPOSITION",'ETPT Format DDG'!2:2,0)), INDEX( 'ETPT Format DDG'!$A:$ZZ,,MATCH("Fonction recodée",'ETPT Format DDG'!2:2,0)),"Fonctionnaire A-B-CBUR")) -> #N/A | O11: =_xlfn.AGGREGATE(9,6,I11:N11) -> 0 | T11: =SUM(SUMIFS( INDEX( 'ETPT Format DDG'!$A:$ZZ,,MATCH("14.9. MISE À DISPOSITION",'ETPT Format DDG'!2:2,0)), INDEX( 'ETPT Format DDG'!$A:$ZZ,,MATCH("Fonction recodée",'ETPT Format DDG'!2:2,0)),"Magistrat SIEGE")) -> #N/A | U11: =_xlfn.AGGREGATE(9,6,P11:T11) -> 0 | AA11: =_xlfn.AGGREGATE(9,6,V11:Z11) -> 0
D12: =IF(ISBLANK($D$3),"",$D$3) -> =ETPT_CA_JUR_DDG!$D$5 | E12: 166-PA-NC | F12: Etpt placés additionnels | G12: =SUM(SUMIFS( INDEX('ETPT A-JUST'!$A:$ZZ,,MATCH("Temps ventilés sur la période (absentéisme et action 99 déduits)",'ETPT A-JUST'!2:2,0)), INDEX('ETPT A-JUST'!$A:$ZZ,,MATCH("Fonction recodée",'ETPT A-JUST'!2:2,0)),"Fonctionnaire CTECH placé ADD")) -> #N/A | H12: =_xlfn.AGGREGATE(9,6,G12) -> 0 | I12: =SUM(SUMIFS( INDEX('ETPT A-JUST'!$A:$ZZ,,MATCH("13.9. FONCTIONNAIRES / AJ AFFECTÉS AUX ACTIVITÉS CIVILES ET COMMERCIALES DU PARQUET GÉNÉRAL",'ETPT A-JUST'!2:2,0)), INDEX('ETPT A-JUST'!$A:$ZZ,,MATCH("Fonction recodée",'ETPT A-JUST'!2:2,0)),"Fonctionnaire A-B-CBUR placé ADD")) -> #N/A | J12: =SUM(SUMIFS( INDEX('ETPT A-JUST'!$A:$ZZ,,MATCH("11.1. ASSISES HORS JIRS",'ETPT A-JUST'!2:2,0)), INDEX('ETPT A-JUST'!$A:$ZZ,,MATCH("Fonction recodée",'ETPT A-JUST'!2:2,0)),"Fonctionnaire A-B-CBUR placé ADD"))+ SUM(SUMIFS( INDEX('ETPT A-JUST'!$A:$ZZ,,MATCH("11.2 ASSISES JIRS",'ETPT A-JUST'!2:2,0)), INDEX('ETPT A-JUST'!$A:$ZZ,,MATCH("Fonction recodée",'ETPT A-JUST'!2:2,0)),"Fonctionnaire A-B-CBUR placé ADD")) -> #N/A | K12: =SUM(SUMIFS( INDEX('ETPT A-JUST'!$A:$ZZ,,MATCH("11.3. COUR CRIMINELLE DÉPARTEMENTALE",'ETPT A-JUST'!2:2,0)), INDEX('ETPT A-JUST'!$A:$ZZ,,MATCH("Fonction recodée",'ETPT A-JUST'!2:2,0)),"Fonctionnaire A-B-CBUR placé ADD")) -> #N/A | L12: =SUM(SUMIFS( INDEX( 'ETPT A-JUST'!$A:$ZZ,,MATCH("8.4. CONTENTIEUX JIRS CRIM-ORG",'ETPT A-JUST'!2:2,0)), INDEX( 'ETPT A-JUST'!$A:$ZZ,,MATCH("Fonction recodée",'ETPT A-JUST'!2:2,0)),"Fonctionnaire A-B-CBUR placé ADD"))+ SUM(SUMIFS( INDEX( 'ETPT A-JUST'!$A:$ZZ,,MATCH("8.7. CONTENTIEUX JIRS ÉCO-FI",'ETPT A-JUST'!2:2,0)), INDEX( 'ETPT A-JUST'!$A:$ZZ,,MATCH("Fonction recodée",'ETPT A-JUST'!2:2,0)),"Fonctionnaire A-B-CBUR placé ADD"))+ SUM(SUMIFS( INDEX( 'ETPT A-JUST'!$A:$ZZ,,MATCH("9.3. CONTENTIEUX DE LA DÉTENTION JIRS",'ETPT A-JUST'!2:2,0)), INDEX( 'ETPT A-JUST'!$A:$ZZ,,MATCH("Fonction recodée",'ETPT A-JUST'!2:2,0)),"Fonctionnaire A-B-CBUR placé ADD"))+ SUM(SUMIFS( INDEX( 'ETPT A-JUST'!$A:$ZZ,,MATCH("9.5. CONTENTIEUX DU CONTRÔLE JUDICIAIRE JIRS",'ETPT A-JUST'!2:2,0)), INDEX( 'ETPT A-JUST'!$A:$ZZ,,MATCH("Fonction recodée",'ETPT A-JUST'!2:2,0)),"Fonctionnaire A-B-CBUR placé ADD"))+ SUM(SUMIFS( INDEX( 'ETPT A-JUST'!$A:$ZZ,,MATCH("9.7. CONTENTIEUX DE FOND JIRS",'ETPT A-JUST'!2:2,0)), INDEX( 'ETPT A-JUST'!$A:$ZZ,,MATCH("Fonction recodée",'ETPT A-JUST'!2:2,0)),"Fonctionnaire A-B-CBUR placé ADD")) -> #N/A | M12: =SUM(SUMIFS( INDEX( 'ETPT A-JUST'!$A:$ZZ,,MATCH("1. TOTAL CONTENTIEUX SOCIAL",'ETPT A-JUST'!2:2,0)), INDEX( 'ETPT A-JUST'!$A:$ZZ,,MATCH("Fonction recodée",'ETPT A-JUST'!2:2,0)),"Fonctionnaire A-B-CBUR placé ADD")) -> #N/A | N12: =SUM(SUMIFS( INDEX('ETPT A-JUST'!$A:$ZZ,,MATCH("Temps ventilés sur la période (absentéisme et action 99 déduits)",'ETPT A-JUST'!2:2,0)), INDEX('ETPT A-JUST'!$A:$ZZ,,MATCH("Fonction recodée",'ETPT A-JUST'!2:2,0)),"Fonctionnaire A-B-CBUR placé ADD"))- SUM(I12:M12) -> #N/A | O12: =_xlfn.AGGREGATE(9,6,I12:N12) -> 0 | P12: =SUM(SUMIFS( INDEX('ETPT A-JUST'!$A:$ZZ,,MATCH("11.1. ASSISES HORS JIRS",'ETPT A-JUST'!2:2,0)), INDEX('ETPT A-JUST'!$A:$ZZ,,MATCH("Fonction recodée",'ETPT A-JUST'!2:2,0)),"Magistrat placé ADD"))+ SUM(SUMIFS( INDEX('ETPT A-JUST'!$A:$ZZ,,MATCH("11.2 ASSISES JIRS",'ETPT A-JUST'!2:2,0)), INDEX('ETPT A-JUST'!$A:$ZZ,,MATCH("Fonction recodée",'ETPT A-JUST'!2:2,0)),"Magistrat placé ADD")) -> #N/A | Q12: =SUM(SUMIFS( INDEX('ETPT A-JUST'!$A:$ZZ,,MATCH("11.3. COUR CRIMINELLE DÉPARTEMENTALE",'ETPT A-JUST'!2:2,0)), INDEX('ETPT A-JUST'!$A:$ZZ,,MATCH("Fonction recodée",'ETPT A-JUST'!2:2,0)),"Magistrat placé ADD")) -> #N/A | R12: =SUM(SUMIFS( INDEX( 'ETPT A-JUST'!$A:$ZZ,,MATCH("8.4. CONTENTIEUX JIRS CRIM-ORG",'ETPT A-JUST'!2:2,0)), INDEX( 'ETPT A-JUST'!$A:$ZZ,,MATCH("Fonction recodée",'ETPT A-JUST'!2:2,0)),"Magistrat placé ADD"))+ SUM(SUMIFS( INDEX( 'ETPT A-JUST'!$A:$ZZ,,MATCH("8.7. CONTENTIEUX JIRS ÉCO-FI",'ETPT A-JUST'!2:2,0)), INDEX( 'ETPT A-JUST'!$A:$ZZ,,MATCH("Fonction recodée",'ETPT A-JUST'!2:2,0)),"Magistrat placé ADD"))+ SUM(SUMIFS( INDEX( 'ETPT A-JUST'!$A:$ZZ,,MATCH("9.3. CONTENTIEUX DE LA DÉTENTION JIRS",'ETPT A-JUST'!2:2,0)), INDEX( 'ETPT A-JUST'!$A:$ZZ,,MATCH("Fonction recodée",'ETPT A-JUST'!2:2,0)),"Magistrat placé ADD"))+ SUM(SUMIFS( INDEX( 'ETPT A-JUST'!$A:$ZZ,,MATCH("9.5. CONTENTIEUX DU CONTRÔLE JUDICIAIRE JIRS",'ETPT A-JUST'!2:2,0)), INDEX( 'ETPT A-JUST'!$A:$ZZ,,MATCH("Fonction recodée",'ETPT A-JUST'!2:2,0)),"Magistrat placé ADD"))+ SUM(SUMIFS( INDEX( 'ETPT A-JUST'!$A:$ZZ,,MATCH("9.7. CONTENTIEUX DE FOND JIRS",'ETPT A-JUST'!2:2,0)), INDEX( 'ETPT A-JUST'!$A:$ZZ,,MATCH("Fonction recodée",'ETPT A-JUST'!2:2,0)),"Magistrat placé ADD")) -> #N/A | S12: =SUM(SUMIFS( INDEX( 'ETPT A-JUST'!$A:$ZZ,,MATCH("1. TOTAL CONTENTIEUX SOCIAL",'ETPT A-JUST'!2:2,0)), INDEX( 'ETPT A-JUST'!$A:$ZZ,,MATCH("Fonction recodée",'ETPT A-JUST'!2:2,0)),"Magistrat placé ADD")) -> #N/A | T12: =SUM(SUMIFS( INDEX('ETPT A-JUST'!$A:$ZZ,,MATCH("Temps ventilés sur la période (absentéisme et action 99 déduits)",'ETPT A-JUST'!2:2,0)), INDEX('ETPT A-JUST'!$A:$ZZ,,MATCH("Fonction recodée",'ETPT A-JUST'!2:2,0)),"Magistrat placé ADD"))- SUM(P12:S12) -> #N/A | U12: =_xlfn.AGGREGATE(9,6,P12:T12) -> 0 | AA12: =_xlfn.AGGREGATE(9,6,V12:Z12) -> 0
D13: =IF(ISBLANK($D$3),"",$D$3) -> =ETPT_CA_JUR_DDG!$D$5 | E13: 166-PN-NC | F13: Etpt placés absents non affectés | H13: =_xlfn.AGGREGATE(9,6,G13) -> 0 | O13: =_xlfn.AGGREGATE(9,6,I13:N13) -> 0 | T13: {=SUM(SUMIFS( INDEX( 'ETPT A-JUST'!$A:$ZZ,,MATCH("14. TOTAL INDISPONIBILITÉ",'ETPT A-JUST'!2:2,0)), INDEX( 'ETPT A-JUST'!$A:$ZZ,,MATCH("Fonction recodée",'ETPT A-JUST'!2:2,0)),{"Magistrat placé ADD";"Magistrat placé SUB"}))} -> #N/A | U13: =_xlfn.AGGREGATE(9,6,P13:T13) -> 0 | AA13: =_xlfn.AGGREGATE(9,6,V13:Z13) -> 0
E14: 166-PS-NC | F14: Etpt placés de substitution | G14: =SUM(SUMIFS( INDEX('ETPT A-JUST'!$A:$ZZ,,MATCH("Temps ventilés sur la période (absentéisme et action 99 déduits)",'ETPT A-JUST'!2:2,0)), INDEX('ETPT A-JUST'!$A:$ZZ,,MATCH("Fonction recodée",'ETPT A-JUST'!2:2,0)),"Fonctionnaire CTECH placé SUB")) -> #N/A | H14: =_xlfn.AGGREGATE(9,6,G14) -> 0 | I14: =SUM(SUMIFS( INDEX('ETPT A-JUST'!$A:$ZZ,,MATCH("13.9. FONCTIONNAIRES / AJ AFFECTÉS AUX ACTIVITÉS CIVILES ET COMMERCIALES DU PARQUET GÉNÉRAL",'ETPT A-JUST'!2:2,0)), INDEX('ETPT A-JUST'!$A:$ZZ,,MATCH("Fonction recodée",'ETPT A-JUST'!2:2,0)),"Fonctionnaire A-B-CBUR placé SUB")) -> #N/A | J14: =SUM(SUMIFS( INDEX('ETPT A-JUST'!$A:$ZZ,,MATCH("11.1. ASSISES HORS JIRS",'ETPT A-JUST'!2:2,0)), INDEX('ETPT A-JUST'!$A:$ZZ,,MATCH("Fonction recodée",'ETPT A-JUST'!2:2,0)),"Fonctionnaire A-B-CBUR placé SUB"))+ SUM(SUMIFS( INDEX('ETPT A-JUST'!$A:$ZZ,,MATCH("11.2 ASSISES JIRS",'ETPT A-JUST'!2:2,0)), INDEX('ETPT A-JUST'!$A:$ZZ,,MATCH("Fonction recodée",'ETPT A-JUST'!2:2,0)),"Fonctionnaire A-B-CBUR placé SUB")) -> #N/A | K14: =SUM(SUMIFS( INDEX('ETPT A-JUST'!$A:$ZZ,,MATCH("11.3. COUR CRIMINELLE DÉPARTEMENTALE",'ETPT A-JUST'!2:2,0)), INDEX('ETPT A-JUST'!$A:$ZZ,,MATCH("Fonction recodée",'ETPT A-JUST'!2:2,0)),"Fonctionnaire A-B-CBUR placé SUB")) -> #N/A | L14: =SUM(SUMIFS( INDEX( 'ETPT A-JUST'!$A:$ZZ,,MATCH("8.4. CONTENTIEUX JIRS CRIM-ORG",'ETPT A-JUST'!2:2,0)), INDEX( 'ETPT A-JUST'!$A:$ZZ,,MATCH("Fonction recodée",'ETPT A-JUST'!2:2,0)),"Fonctionnaire A-B-CBUR placé SUB"))+ SUM(SUMIFS( INDEX( 'ETPT A-JUST'!$A:$ZZ,,MATCH("8.7. CONTENTIEUX JIRS ÉCO-FI",'ETPT A-JUST'!2:2,0)), INDEX( 'ETPT A-JUST'!$A:$ZZ,,MATCH("Fonction recodée",'ETPT A-JUST'!2:2,0)),"Fonctionnaire A-B-CBUR placé SUB"))+ SUM(SUMIFS( INDEX( 'ETPT A-JUST'!$A:$ZZ,,MATCH("9.3. CONTENTIEUX DE LA DÉTENTION JIRS",'ETPT A-JUST'!2:2,0)), INDEX( 'ETPT A-JUST'!$A:$ZZ,,MATCH("Fonction recodée",'ETPT A-JUST'!2:2,0)),"Fonctionnaire A-B-CBUR placé SUB"))+ SUM(SUMIFS( INDEX( 'ETPT A-JUST'!$A:$ZZ,,MATCH("9.5. CONTENTIEUX DU CONTRÔLE JUDICIAIRE JIRS",'ETPT A-JUST'!2:2,0)), INDEX( 'ETPT A-JUST'!$A:$ZZ,,MATCH("Fonction recodée",'ETPT A-JUST'!2:2,0)),"Fonctionnaire A-B-CBUR placé SUB"))+ SUM(SUMIFS( INDEX( 'ETPT A-JUST'!$A:$ZZ,,MATCH("9.7. CONTENTIEUX DE FOND JIRS",'ETPT A-JUST'!2:2,0)), INDEX( 'ETPT A-JUST'!$A:$ZZ,,MATCH("Fonction recodée",'ETPT A-JUST'!2:2,0)),"Fonctionnaire A-B-CBUR placé SUB")) -> #N/A | M14: =SUM(SUMIFS( INDEX( 'ETPT A-JUST'!$A:$ZZ,,MATCH("1. TOTAL CONTENTIEUX SOCIAL",'ETPT A-JUST'!2:2,0)), INDEX( 'ETPT A-JUST'!$A:$ZZ,,MATCH("Fonction recodée",'ETPT A-JUST'!2:2,0)),"Fonctionnaire A-B-CBUR placé SUB")) -> #N/A | N14: =SUM(SUMIFS( INDEX('ETPT A-JUST'!$A:$ZZ,,MATCH("Temps ventilés sur la période (absentéisme et action 99 déduits)",'ETPT A-JUST'!2:2,0)), INDEX('ETPT A-JUST'!$A:$ZZ,,MATCH("Fonction recodée",'ETPT A-JUST'!2:2,0)),"Fonctionnaire A-B-CBUR placé SUB"))- SUM(I14:M14) -> #N/A | O14: =_xlfn.AGGREGATE(9,6,I14:N14) -> 0 | P14: =SUM(SUMIFS( INDEX('ETPT A-JUST'!$A:$ZZ,,MATCH("11.1. ASSISES HORS JIRS",'ETPT A-JUST'!2:2,0)), INDEX('ETPT A-JUST'!$A:$ZZ,,MATCH("Fonction recodée",'ETPT A-JUST'!2:2,0)),"Magistrat placé SUB"))+ SUM(SUMIFS( INDEX('ETPT A-JUST'!$A:$ZZ,,MATCH("11.2 ASSISES JIRS",'ETPT A-JUST'!2:2,0)), INDEX('ETPT A-JUST'!$A:$ZZ,,MATCH("Fonction recodée",'ETPT A-JUST'!2:2,0)),"Magistrat placé SUB")) -> #N/A | Q14: =SUM(SUMIFS( INDEX('ETPT A-JUST'!$A:$ZZ,,MATCH("11.3. COUR CRIMINELLE DÉPARTEMENTALE",'ETPT A-JUST'!2:2,0)), INDEX('ETPT A-JUST'!$A:$ZZ,,MATCH("Fonction recodée",'ETPT A-JUST'!2:2,0)),"Magistrat placé SUB")) -> #N/A | R14: =SUM(SUMIFS( INDEX( 'ETPT A-JUST'!$A:$ZZ,,MATCH("8.4. CONTENTIEUX JIRS CRIM-ORG",'ETPT A-JUST'!2:2,0)), INDEX( 'ETPT A-JUST'!$A:$ZZ,,MATCH("Fonction recodée",'ETPT A-JUST'!2:2,0)),"Magistrat placé SUB"))+ SUM(SUMIFS( INDEX( 'ETPT A-JUST'!$A:$ZZ,,MATCH("8.7. CONTENTIEUX JIRS ÉCO-FI",'ETPT A-JUST'!2:2,0)), INDEX( 'ETPT A-JUST'!$A:$ZZ,,MATCH("Fonction recodée",'ETPT A-JUST'!2:2,0)),"Magistrat placé SUB"))+ SUM(SUMIFS( INDEX( 'ETPT A-JUST'!$A:$ZZ,,MATCH("9.3. CONTENTIEUX DE LA DÉTENTION JIRS",'ETPT A-JUST'!2:2,0)), INDEX( 'ETPT A-JUST'!$A:$ZZ,,MATCH("Fonction recodée",'ETPT A-JUST'!2:2,0)),"Magistrat placé SUB"))+ SUM(SUMIFS( INDEX( 'ETPT A-JUST'!$A:$ZZ,,MATCH("9.5. CONTENTIEUX DU CONTRÔLE JUDICIAIRE JIRS",'ETPT A-JUST'!2:2,0)), INDEX( 'ETPT A-JUST'!$A:$ZZ,,MATCH("Fonction recodée",'ETPT A-JUST'!2:2,0)),"Magistrat placé SUB"))+ SUM(SUMIFS( INDEX( 'ETPT A-JUST'!$A:$ZZ,,MATCH("9.7. CONTENTIEUX DE FOND JIRS",'ETPT A-JUST'!2:2,0)), INDEX( 'ETPT A-JUST'!$A:$ZZ,,MATCH("Fonction recodée",'ETPT A-JUST'!2:2,0)),"Magistrat placé SUB")) -> #N/A | S14: =SUM(SUMIFS( INDEX( 'ETPT A-JUST'!$A:$ZZ,,MATCH("1. TOTAL CONTENTIEUX SOCIAL",'ETPT A-JUST'!2:2,0)), INDEX( 'ETPT A-JUST'!$A:$ZZ,,MATCH("Fonction recodée",'ETPT A-JUST'!2:2,0)),"Magistrat placé SUB")) -> #N/A | T14: =SUM(SUMIFS( INDEX('ETPT A-JUST'!$A:$ZZ,,MATCH("Temps ventilés sur la période (absentéisme et action 99 déduits)",'ETPT A-JUST'!2:2,0)), INDEX('ETPT A-JUST'!$A:$ZZ,,MATCH("Fonction recodée",'ETPT A-JUST'!2:2,0)),"Magistrat placé SUB"))- SUM(P14:S14) -> #N/A | U14: =_xlfn.AGGREGATE(9,6,P14:T14) -> 0 | AA14: =_xlfn.AGGREGATE(9,6,V14:Z14) -> 0
F15: TOTAL ETPT | G15: =_xlfn.AGGREGATE(9,6,G3:G14) -> 0 | H15: =_xlfn.AGGREGATE(9,6,H3:H14) -> 0 | I15: =_xlfn.AGGREGATE(9,6,I3:I14) -> 0 | J15: =_xlfn.AGGREGATE(9,6,J3:J14) -> 0 | K15: =_xlfn.AGGREGATE(9,6,K3:K14) -> 0 | L15: =_xlfn.AGGREGATE(9,6,L3:L14) -> 0 | M15: =_xlfn.AGGREGATE(9,6,M3:M14) -> 0 | N15: =_xlfn.AGGREGATE(9,6,N3:N14) -> 0 | ... AA15: =_xlfn.AGGREGATE(9,6,AA3:AA14) -> 0
F17: Indisponibilité des placés à reporter sur le SAR, ligne "Etpt placés absents non affectés", colonne C-TECH | G17: {=SUM(SUMIFS( INDEX( 'ETPT A-JUST'!$A:$ZZ,,MATCH("14. TOTAL INDISPONIBILITÉ",'ETPT A-JUST'!2:2,0)), INDEX( 'ETPT A-JUST'!$A:$ZZ,,MATCH("Fonction recodée",'ETPT A-JUST'!2:2,0)),{"Fonctionnaire CTECH placé ADD";"Fonctionnaire CTECH placé SUB"}))} -> #N/A | I17: Indisponibilité des placés à reporter sur le SAR, ligne "Etpt placés absents non affectés", colonne ABC-BUR | N17: {=SUM(SUMIFS( INDEX( 'ETPT A-JUST'!$A:$ZZ,,MATCH("14. TOTAL INDISPONIBILITÉ",'ETPT A-JUST'!2:2,0)), INDEX( 'ETPT A-JUST'!$A:$ZZ,,MATCH("Fonction recodée",'ETPT A-JUST'!2:2,0)),{"Fonctionnaire A-B-CBUR placé ADD";"Fonctionnaire A-B-CBUR placé SUB"}))} -> #N/A

Sheet ETPT_CA_JUR_DDG
A1: Déclaration des ETPT CA | D1: Déclaration des ETPT CA
B2: UO | C2: Code de la juridiction | D2: Juridiction | E2: Code sous action | F2: Action | G2: Fonctionnaires Catégorie C Technique spécialisés | H2: Total fonctionnaires techniques | I2: Fonctionnaires activité civile et commerciale du parquet | J2: Fonctionnaires Assises (inclus JIRS) | K2: Fonctionnaires Cour criminelle | L2: Fonctionnaires JIRS (correctionnel) | M2: Fonctionnaires chambres sociales | N2: Fonctionnaires hors fonctions spécifiques | O2: Total fonctionnaires administratifs | P2: Magistrats du Siège assises (inclus JIRS) | Q2: Magistrats du siège Cour criminelle | R2: Autres Magistrats du Siège JIRS (correctionnel) | S2: Magistrats du Siège chambres sociales | T2: Autres Magistrats du Siège non spécialisés | U2: Total magistrats du siège non spécialisés | V2: Magistrats du Parquet - activité civile et commerciale | W2: Magistrats du Parquet JIRS (correctionnel) | X2: Magistrats du Parquet assises (inclus JIRS) | Y2: Magistrats du Parquet Cour criminelle | Z2: Autres Magistrats du Parquet | AA2: Total magistrats du parquet
D3: A | E3: 166-01-NC | F3: Action 1 - Traitement et jugement des contentieux civils | G3: =IF(ISBLANK($D$3),"",IF(ISERROR(ETPT_CA_JUR!G3),"",IF(ETPT_CA_JUR!G3=0,"",ETPT_CA_JUR!G3))) | H3: =ETPT_CA_JUR!H3 -> 0 | I3: =IF(ISBLANK($D$3),"",IF(ISERROR(ETPT_CA_JUR!I3),"",IF(ETPT_CA_JUR!I3=0,"",ETPT_CA_JUR!I3))) | J3: =IF(ISBLANK($D$3),"",IF(ISERROR(ETPT_CA_JUR!J3),"",IF(ETPT_CA_JUR!J3=0,"",ETPT_CA_JUR!J3))) | K3: =IF(ISBLANK($D$3),"",IF(ISERROR(ETPT_CA_JUR!K3),"",IF(ETPT_CA_JUR!K3=0,"",ETPT_CA_JUR!K3))) | L3: =IF(ISBLANK($D$3),"",IF(ISERROR(ETPT_CA_JUR!L3),"",IF(ETPT_CA_JUR!L3=0,"",ETPT_CA_JUR!L3))) | M3: =IF(ISBLANK($D$3),"",IF(ISERROR(ETPT_CA_JUR!M3),"",IF(ETPT_CA_JUR!M3=0,"",ETPT_CA_JUR!M3))) | N3: =IF(ISBLANK($D$3),"",IF(ISERROR(ETPT_CA_JUR!N3),"",IF(ETPT_CA_JUR!N3=0,"",ETPT_CA_JUR!N3))) | O3: =ETPT_CA_JUR!O3 -> 0 | P3: =IF(ISBLANK($D$3),"",IF(ISERROR(ETPT_CA_JUR!P3),"",IF(ETPT_CA_JUR!P3=0,"",ETPT_CA_JUR!P3))) | Q3: =IF(ISBLANK($D$3),"",IF(ISERROR(ETPT_CA_JUR!Q3),"",IF(ETPT_CA_JUR!Q3=0,"",ETPT_CA_JUR!Q3))) | R3: =IF(ISBLANK($D$3),"",IF(ISERROR(ETPT_CA_JUR!R3),"",IF(ETPT_CA_JUR!R3=0,"",ETPT_CA_JUR!R3))) | S3: =IF(ISBLANK($D$3),"",IF(ISERROR(ETPT_CA_JUR!S3),"",IF(ETPT_CA_JUR!S3=0,"",ETPT_CA_JUR!S3))) | T3: =IF(ISBLANK($D$3),"",IF(ISERROR(ETPT_CA_JUR!T3),"",IF(ETPT_CA_JUR!T3=0,"",ETPT_CA_JUR!T3))) | U3: =ETPT_CA_JUR!U3 -> 0 | V3: =IF(ISBLANK($D$3),"",IF(ISERROR(ETPT_CA_JUR!V3),"",IF(ETPT_CA_JUR!V3=0,"",ETPT_CA_JUR!V3))) | W3: =IF(ISBLANK($D$3),"",IF(ISERROR(ETPT_CA_JUR!W3),"",IF(ETPT_CA_JUR!W3=0,"",ETPT_CA_JUR!W3))) | X3: =IF(ISBLANK($D$3),"",IF(ISERROR(ETPT_CA_JUR!X3),"",IF(ETPT_CA_JUR!X3=0,"",ETPT_CA_JUR!X3))) | Y3: =IF(ISBLANK($D$3),"",IF(ISERROR(ETPT_CA_JUR!Y3),"",IF(ETPT_CA_JUR!Y3=0,"",ETPT_CA_JUR!Y3))) | Z3: =IF(ISBLANK($D$3),"",IF(ISERROR(ETPT_CA_JUR!Z3),"",IF(ETPT_CA_JUR!Z3=0,"",ETPT_CA_JUR!Z3))) | AA3: =ETPT_CA_JUR!AA3 -> 0
D4: =IF(ISBLANK($D$3),"",$D$3) -> A | E4: 166-02-NC | F4: Action 2 - Traitement et jugement des affaires pénales | G4: =IF(ISBLANK($D$3),"",IF(ISERROR(ETPT_CA_JUR!G4),"",IF(ETPT_CA_JUR!G4=0,"",ETPT_CA_JUR!G4))) | H4: =ETPT_CA_JUR!H4 -> 0 | I4: =IF(ISBLANK($D$3),"",IF(ISERROR(ETPT_CA_JUR!I4),"",IF(ETPT_CA_JUR!I4=0,"",ETPT_CA_JUR!I4))) | J4: =IF(ISBLANK($D$3),"",IF(ISERROR(ETPT_CA_JUR!J4),"",IF(ETPT_CA_JUR!J4=0,"",ETPT_CA_JUR!J4))) | K4: =IF(ISBLANK($D$3),"",IF(ISERROR(ETPT_CA_JUR!K4),"",IF(ETPT_CA_JUR!K4=0,"",ETPT_CA_JUR!K4))) | L4: =IF(ISBLANK($D$3),"",IF(ISERROR(ETPT_CA_JUR!L4),"",IF(ETPT_CA_JUR!L4=0,"",ETPT_CA_JUR!L4))) | M4: =IF(ISBLANK($D$3),"",IF(ISERROR(ETPT_CA_JUR!M4),"",IF(ETPT_CA_JUR!M4=0,"",ETPT_CA_JUR!M4))) | N4: =IF(ISBLANK($D$3),"",IF(ISERROR(ETPT_CA_JUR!N4),"",IF(ETPT_CA_JUR!N4=0,"",ETPT_CA_JUR!N4))) | O4: =ETPT_CA_JUR!O4 -> 0 | P4: =IF(ISBLANK($D$3),"",IF(ISERROR(ETPT_CA_JUR!P4),"",IF(ETPT_CA_JUR!P4=0,"",ETPT_CA_JUR!P4))) | Q4: =IF(ISBLANK($D$3),"",IF(ISERROR(ETPT_CA_JUR!Q4),"",IF(ETPT_CA_JUR!Q4=0,"",ETPT_CA_JUR!Q4))) | R4: =IF(ISBLANK($D$3),"",IF(ISERROR(ETPT_CA_JUR!R4),"",IF(ETPT_CA_JUR!R4=0,"",ETPT_CA_JUR!R4))) | S4: =IF(ISBLANK($D$3),"",IF(ISERROR(ETPT_CA_JUR!S4),"",IF(ETPT_CA_JUR!S4=0,"",ETPT_CA_JUR!S4))) | T4: =IF(ISBLANK($D$3),"",IF(ISERROR(ETPT_CA_JUR!T4),"",IF(ETPT_CA_JUR!T4=0,"",ETPT_CA_JUR!T4))) | U4: =ETPT_CA_JUR!U4 -> 0 | V4: =IF(ISBLANK($D$3),"",IF(ISERROR(ETPT_CA_JUR!V4),"",IF(ETPT_CA_JUR!V4=0,"",ETPT_CA_JUR!V4))) | W4: =IF(ISBLANK($D$3),"",IF(ISERROR(ETPT_CA_JUR!W4),"",IF(ETPT_CA_JUR!W4=0,"",ETPT_CA_JUR!W4))) | X4: =IF(ISBLANK($D$3),"",IF(ISERROR(ETPT_CA_JUR!X4),"",IF(ETPT_CA_JUR!X4=0,"",ETPT_CA_JUR!X4))) | Y4: =IF(ISBLANK($D$3),"",IF(ISERROR(ETPT_CA_JUR!Y4),"",IF(ETPT_CA_JUR!Y4=0,"",ETPT_CA_JUR!Y4))) | Z4: =IF(ISBLANK($D$3),"",IF(ISERROR(ETPT_CA_JUR!Z4),"",IF(ETPT_CA_JUR!Z4=0,"",ETPT_CA_JUR!Z4))) | AA4: =ETPT_CA_JUR!AA4 -> 0
